<?xml version="1.0"?>
<robot name="template">

    <gazebo reference="base">
        <material>Gazebo/Red</material>
    </gazebo>
    <gazebo reference="link1">
        <material>Gazebo/DarkGrey</material>
    </gazebo>

    <!--World & Base -->	
    <link name="world">
    </link> 
    <joint name="base_joint" type="fixed">
        <origin xyz="0 0 0" rpy="0 1.57 0"/> 
        <parent link="world"/>
        <child link="base"/>
        <axis xyz="0 0 0"/>
    </joint>
    <link name="base">
        <inertial>
            <origin xyz="0 0 0" rpy="0 0 0"/>
            <mass value="1.0"/>
            <inertia ixx="0.1" iyy="0.1" izz="0.1" ixy="0" ixz="0" iyz="0"/>
        </inertial>
        <visual>
            <origin xyz="0 0 0" rpy="0 0 0"/>
            <geometry>
                <cylinder length="0.055" radius="0.03"/>
            </geometry> 
        </visual>
    </link> 

    <!--First Joint & Link  --> 
    <joint name="joint" type="revolute">
        <origin xyz="0 0 0.035" rpy="0 0 0"/> 
        <parent link="base"/>
        <child link="link"/>
        <limit effort="300" velocity="100" lower="-3.14" upper="3.14" />
        <dynamics damping="0.02" friction="0.0"/>
        <axis xyz="0 0 1"/>
    </joint> 
    <link name="link">
        <inertial>
            <origin xyz="0 0.04 0" rpy="0 0 0"/>
            <mass value="0.5"/>
            <inertia ixx="0.001" iyy="0.001" izz="0.002" ixy="0" ixz="0" iyz="0"/>
        </inertial>
		<visual>
            <origin xyz="0 0.04 0" rpy="0 0 0"/>
            <geometry>
				<box size="0.025 0.08 0.01"/>
            </geometry>	
        </visual>
        <visual>
            <origin xyz="0 0 0" rpy="0 0 0"/>
            <geometry>
                <cylinder length="0.01" radius="0.0125"/>
            </geometry> 
        </visual>
    </link>

    <!-- Custom plugin inseriton -->
    <!-- <gazebo>
        <plugin name="compliant_act_j1" filename="libqbmove_plugin.so">
            <joint>joint</joint>
            <operation_mode>4</operation_mode>
            <pub_eltau>true</pub_eltau>
            <pub_state>true</pub_state>
            <namespace>template</namespace>
            <sub_ext_tau>false</sub_ext_tau>
        </plugin>
    </gazebo> -->

      <gazebo>
        <plugin name="qbmove_vsa_j" filename="libqbmove_plugin.so">
            <!-- # REQUIRED tags -->
            <joint>joint</joint>
            <operation_mode>5</operation_mode>     <!--select the operational mode (see above)-->
            <pub_eltau>true</pub_eltau>             <!--enable elastic torques publishing-->
            <pub_state>true</pub_state>            <!--# enable link state publishing-->
            <sub_ext_tau>true</sub_ext_tau>        <!--enable subscription to external torques -->
            <namespace>template</namespace>
            <t_sample>0.01</t_sample>
            <spring_a1>8.9992</spring_a1>
            <spring_k1>0.0019</spring_k1>
            <spring_a2>8.9992</spring_a2>
            <spring_k2>0.0019</spring_k2>
            <max_def>0.8</max_def>
            <!-- motors parameters -->
            <mot_1_J>0.0233</mot_1_J>               <!-- # motor inertia-->    
            <mot_1_D>0.0019</mot_1_D>               <!-- # motor damping-->
            <mot_1_tauMax>6.0</mot_1_tauMax>        <!-- # maximum motor torque-->
            <mot_1_maxVel>6.0</mot_1_maxVel>        <!-- # maximum motor velocity -->
            <mot_1_minPos>-inf</mot_1_minPos>       <!-- # minimum motor position -->
            <mot_1_maxPos>inf</mot_1_maxPos>        <!-- # maximum motor position -->
            <mot_1_tauFric>0.5</mot_1_tauFric>      <!-- # static motor friction-->
            <mot_2_J>0.0233</mot_2_J>
            <mot_2_D>0.0019</mot_2_D>
            <mot_2_tauMax>6.0</mot_2_tauMax>
            <mot_2_maxVel>6.0</mot_2_maxVel>
            <mot_2_minPos>-inf</mot_2_minPos>
            <mot_2_maxPos>inf</mot_2_maxPos>
            <mot_2_tauFric>0.5</mot_2_tauFric>
            <!-- controllers parameters -->
            <ctrl_1_P>125</ctrl_1_P>                <!-- # proportional gain on motor -->
            <ctrl_1_I>0</ctrl_1_I>                 <!--  # integral gain on motor -->
            <ctrl_1_D>4.5</ctrl_1_D>                <!--  # derivative gain on motor -->
            <ctrl_2_P>125</ctrl_2_P>                
            <ctrl_2_I>0</ctrl_2_I>
            <ctrl_2_D>4.5</ctrl_2_D>
        </plugin>
    </gazebo>

<!--     <gazebo>
        <plugin name="compliant_act_j1" filename="libbavs_plugin.so">
            <joint>joint</joint>
            <operation_mode>1</operation_mode>
            <pub_eltau>true</pub_eltau>
            <pub_state>true</pub_state>
            <sub_ext_tau>false</sub_ext_tau>
        </plugin>
    </gazebo> -->

<!--     <gazebo>
        <plugin name="compliant_act_j1" filename="libawas_ii_plugin.so">
            <joint>joint</joint>
            <operation_mode>1</operation_mode>
            <pub_eltau>true</pub_eltau>
            <pub_state>true</pub_state>
            <sub_ext_tau>false</sub_ext_tau>
        </plugin>
    </gazebo> -->
</robot>
