<?xml version="1.0"?>

<sdf version='1.7'>
  <model name='ego_robot'>
    <link name='base_link'>
      <inertial>
        <pose>-0.005978 0.00027 0.332573 0 -0 0</pose>
        <mass>23.9454</mass>
        <inertia>
          <ixx>3.1326</ixx>
          <ixy>-0.00159271</ixy>
          <ixz>-0.0476261</ixz>
          <iyy>2.96456</iyy>
          <iyz>-0.000493292</iyz>
          <izz>0.263953</izz>
        </inertia>
      </inertial>
      <collision name='base_link_collision'>
        <pose>0 0 0 0 -0 0</pose>
        <geometry>
          <mesh>
            <scale>0.001 0.001 0.001</scale>
            <uri>
              /home/cp/iit_ws/src/AlterEGO_v2/alterego_description/meshes/alterego_v3/collision/aego_base.stl</uri>
          </mesh>
        </geometry>
        <surface>
          <contact>
            <ode />
          </contact>
          <friction>
            <ode />
          </friction>
        </surface>
      </collision>
      <collision name='base_link_fixed_joint_lump__imu_collision_1'>
        <pose>0 0.1025 0.02425 0 -0 0</pose>
        <geometry>
          <mesh>
            <scale>0.001 0.001 0.001</scale>
            <uri>
              /home/cp/iit_ws/src/AlterEGO_v2/alterego_description/meshes/common/collision/mc_seg_imu_supp_1_100.stl</uri>
          </mesh>
        </geometry>
        <surface>
          <contact>
            <ode />
          </contact>
          <friction>
            <ode />
          </friction>
        </surface>
      </collision>
      <collision name='base_link_fixed_joint_lump__laser_collision_2'>
        <pose>0 0 0.106 0 0 -1.5708</pose>
        <geometry>
          <mesh>
            <scale>0.001 0.001 0.001</scale>
            <uri>
              /home/cp/iit_ws/src/AlterEGO_v2/alterego_description/meshes/common/collision/rplidar_a2_slamtec.stl</uri>
          </mesh>
        </geometry>
        <surface>
          <contact>
            <ode />
          </contact>
          <friction>
            <ode />
          </friction>
        </surface>
      </collision>
      <visual name='base_link_visual'>
        <pose>0 0 0 0 -0 0</pose>
        <geometry>
          <mesh>
            <scale>0.001 0.001 0.001</scale>
            <uri>
              /home/cp/iit_ws/src/AlterEGO_v2/alterego_description/meshes/alterego_v3/visual/aego_base.dae</uri>
          </mesh>
        </geometry>
        <material>
          <script>
            <name>Gazebo/SkyBlue</name>
            <uri>file://media/materials/scripts/gazebo.material</uri>
          </script>
        </material>
      </visual>
      <visual name='base_link_fixed_joint_lump__imu_visual_1'>
        <pose>0 0.1025 0.02425 0 -0 0</pose>
        <geometry>
          <mesh>
            <scale>0.001 0.001 0.001</scale>
            <uri>
              /home/cp/iit_ws/src/AlterEGO_v2/alterego_description/meshes/common/visual/mc_seg_imu_supp_1_100.dae</uri>
          </mesh>
        </geometry>
      </visual>
      <visual name='base_link_fixed_joint_lump__laser_visual_2'>
        <pose>0 0 0.136 0 0 -1.6008</pose>
        <geometry>
          <mesh>
            <scale>0.001 0.001 0.001</scale>
            <uri>
              /home/cp/iit_ws/src/AlterEGO_v2/alterego_description/meshes/common/visual/rplidar_a2_slamtec.dae</uri>
          </mesh>
        </geometry>
        <material>
          <script>
            <name>Gazebo/Black</name>
            <uri>file://media/materials/scripts/gazebo.material</uri>
          </script>
        </material>
      </visual>
      <self_collide>1</self_collide>
      <gravity>1</gravity>
      <sensor name='imu_sensor' type='imu'>
        <always_on>1</always_on>
        <update_rate>500</update_rate>
        <visualize>1</visualize>
        <topic>__default_topic__</topic>
        <plugin name='imu_plugin' filename='libgazebo_ros_imu_sensor.so'>
          <topicName>imu</topicName>
          <bodyName>imu_1</bodyName>
          <updateRateHZ>10.0</updateRateHZ>
          <gaussianNoise>0.0</gaussianNoise>
          <xyzOffset>0 0 0</xyzOffset>
          <rpyOffset>0 0 0</rpyOffset>
          <frameName>imu_1</frameName>
        </plugin>
        <pose>0 0.1025 0.02425 0 -0 0</pose>
      </sensor>
    </link>
    <joint name='base_link_to_back_kick_stand' type='revolute'>
      <pose relative_to='base_link'>-0.03 0 0.536 0 0 -3.14159</pose>
      <parent>base_link</parent>
      <child>back_kick_stand</child>
      <axis>
        <xyz>0 1 0</xyz>
        <limit>
          <lower>-0.523333</lower>
          <upper>0</upper>
          <effort>1000</effort>
          <velocity>100</velocity>
        </limit>
        <dynamics>
          <spring_reference>0</spring_reference>
          <spring_stiffness>0</spring_stiffness>
        </dynamics>
      </axis>
    </joint>
    <link name='back_kick_stand'>
      <pose relative_to='base_link_to_back_kick_stand'>0 0 0 0 -0 0</pose>
      <inertial>
        <pose>0.080678 -0.000591 -0.306901 0 -0 0</pose>
        <mass>1.12034</mass>
        <inertia>
          <ixx>0.0418087</ixx>
          <ixy>4.03348e-05</ixy>
          <ixz>0.00790331</ixz>
          <iyy>0.043331</iyy>
          <iyz>-0.000179259</iyz>
          <izz>0.00167237</izz>
        </inertia>
      </inertial>
      <collision name='back_kick_stand_collision'>
        <pose>0 0 0 0 -0 0</pose>
        <geometry>
          <mesh>
            <scale>0.001 0.001 0.001</scale>
            <uri>
              /home/cp/iit_ws/src/AlterEGO_v2/alterego_description/meshes/alterego_v3/collision/salv_v04.stl</uri>
          </mesh>
        </geometry>
        <surface>
          <contact>
            <ode />
          </contact>
          <friction>
            <ode />
          </friction>
        </surface>
      </collision>
      <visual name='back_kick_stand_visual'>
        <pose>0 0 0 0 -0 0</pose>
        <geometry>
          <mesh>
            <scale>0.001 0.001 0.001</scale>
            <uri>
              /home/cp/iit_ws/src/AlterEGO_v2/alterego_description/meshes/alterego_v3/visual/salv_v04.dae</uri>
          </mesh>
        </geometry>
        <material>
          <script>
            <name>Gazebo/Grey</name>
            <uri>file://media/materials/scripts/gazebo.material</uri>
          </script>
        </material>
      </visual>
      <self_collide>1</self_collide>
    </link>
    <joint name='back_kick_stand_to_back_wheel' type='revolute'>
      <pose relative_to='back_kick_stand'>0.168487 0 -0.61001 -1.5708 0.174533 -3.14159</pose>
      <parent>back_kick_stand</parent>
      <child>back_wheel</child>
      <axis>
        <xyz>0 0 1</xyz>
        <limit>
          <lower>-1e+16</lower>
          <upper>1e+16</upper>
        </limit>
        <dynamics>
          <spring_reference>0</spring_reference>
          <spring_stiffness>0</spring_stiffness>
        </dynamics>
      </axis>
    </joint>
    <link name='back_wheel'>
      <pose relative_to='back_kick_stand_to_back_wheel'>0 0 0 0 -0 0</pose>
      <inertial>
        <pose>0 0 0 0 -0 0</pose>
        <mass>0.0524507</mass>
        <inertia>
          <ixx>9.6163e-06</ixx>
          <ixy>0</ixy>
          <ixz>0</ixz>
          <iyy>9.61632e-06</iyy>
          <iyz>0</iyz>
          <izz>1.5743e-05</izz>
        </inertia>
      </inertial>
      <collision name='back_wheel_collision'>
        <pose>0 0 0 0 -0 0</pose>
        <geometry>
          <mesh>
            <scale>0.001 0.001 0.001</scale>
            <uri>
              /home/cp/iit_ws/src/AlterEGO_v2/alterego_description/meshes/alterego_v3/collision/gyul50.stl</uri>
          </mesh>
        </geometry>
        <surface>
          <contact>
            <ode />
          </contact>
          <friction>
            <ode />
          </friction>
        </surface>
      </collision>
      <visual name='back_wheel_visual'>
        <pose>0 0 0 0 -0 0</pose>
        <geometry>
          <mesh>
            <scale>0.001 0.001 0.001</scale>
            <uri>
              /home/cp/iit_ws/src/AlterEGO_v2/alterego_description/meshes/alterego_v3/visual/gyul50.dae</uri>
          </mesh>
        </geometry>
        <material>
          <script>
            <name>Gazebo/Grey</name>
            <uri>file://media/materials/scripts/gazebo.material</uri>
          </script>
        </material>
      </visual>
    </link>
    <joint name='base_link_to_front_kick_stand' type='revolute'>
      <pose relative_to='base_link'>0.03 0 0.536 0 -0 0</pose>
      <parent>base_link</parent>
      <child>front_kick_stand</child>
      <axis>
        <xyz>0 1 0</xyz>
        <limit>
          <lower>-0.523333</lower>
          <upper>0</upper>
          <effort>1000</effort>
          <velocity>100</velocity>
        </limit>
        <dynamics>
          <spring_reference>0</spring_reference>
          <spring_stiffness>0</spring_stiffness>
        </dynamics>
      </axis>
    </joint>
    <link name='front_kick_stand'>
      <pose relative_to='base_link_to_front_kick_stand'>0 0 0 0 -0 0</pose>
      <inertial>
        <pose>0.080678 -0.000591 -0.306901 0 -0 0</pose>
        <mass>1.12034</mass>
        <inertia>
          <ixx>0.0418087</ixx>
          <ixy>4.03348e-05</ixy>
          <ixz>0.00790331</ixz>
          <iyy>0.043331</iyy>
          <iyz>-0.000179259</iyz>
          <izz>0.00167237</izz>
        </inertia>
      </inertial>
      <collision name='front_kick_stand_collision'>
        <pose>0 0 0 0 -0 0</pose>
        <geometry>
          <mesh>
            <scale>0.001 0.001 0.001</scale>
            <uri>
              /home/cp/iit_ws/src/AlterEGO_v2/alterego_description/meshes/alterego_v3/collision/salv_v04.stl</uri>
          </mesh>
        </geometry>
        <surface>
          <contact>
            <ode />
          </contact>
          <friction>
            <ode />
          </friction>
        </surface>
      </collision>
      <visual name='front_kick_stand_visual'>
        <pose>0 0 0 0 -0 0</pose>
        <geometry>
          <mesh>
            <scale>0.001 0.001 0.001</scale>
            <uri>
              /home/cp/iit_ws/src/AlterEGO_v2/alterego_description/meshes/alterego_v3/visual/salv_v04.dae</uri>
          </mesh>
        </geometry>
        <material>
          <script>
            <name>Gazebo/Grey</name>
            <uri>file://media/materials/scripts/gazebo.material</uri>
          </script>
        </material>
      </visual>
      <self_collide>1</self_collide>
    </link>
    <joint name='front_kick_stand_to_front_wheel' type='revolute'>
      <pose relative_to='front_kick_stand'>0.168487 0 -0.61001 -1.5708 0.174533 -3.14159</pose>
      <parent>front_kick_stand</parent>
      <child>front_wheel</child>
      <axis>
        <xyz>0 0 1</xyz>
        <limit>
          <lower>-1e+16</lower>
          <upper>1e+16</upper>
        </limit>
        <dynamics>
          <spring_reference>0</spring_reference>
          <spring_stiffness>0</spring_stiffness>
        </dynamics>
      </axis>
    </joint>
    <link name='front_wheel'>
      <pose relative_to='front_kick_stand_to_front_wheel'>0 0 0 0 -0 0</pose>
      <inertial>
        <pose>0 0 0 0 -0 0</pose>
        <mass>0.0524507</mass>
        <inertia>
          <ixx>9.6163e-06</ixx>
          <ixy>0</ixy>
          <ixz>0</ixz>
          <iyy>9.61632e-06</iyy>
          <iyz>0</iyz>
          <izz>1.5743e-05</izz>
        </inertia>
      </inertial>
      <collision name='front_wheel_collision'>
        <pose>0 0 0 0 -0 0</pose>
        <geometry>
          <mesh>
            <scale>0.001 0.001 0.001</scale>
            <uri>
              /home/cp/iit_ws/src/AlterEGO_v2/alterego_description/meshes/alterego_v3/collision/gyul50.stl</uri>
          </mesh>
        </geometry>
        <surface>
          <contact>
            <ode />
          </contact>
          <friction>
            <ode />
          </friction>
        </surface>
      </collision>
      <visual name='front_wheel_visual'>
        <pose>0 0 0 0 -0 0</pose>
        <geometry>
          <mesh>
            <scale>0.001 0.001 0.001</scale>
            <uri>
              /home/cp/iit_ws/src/AlterEGO_v2/alterego_description/meshes/alterego_v3/visual/gyul50.dae</uri>
          </mesh>
        </geometry>
        <material>
          <script>
            <name>Gazebo/Grey</name>
            <uri>file://media/materials/scripts/gazebo.material</uri>
          </script>
        </material>
      </visual>
    </link>
    <joint name='base_link_to_left_shoulder_flange' type='revolute'>
      <pose relative_to='base_link'>0.028648 0.220259 0.901246 -0.174535 -1.39626 -1.57079</pose>
      <parent>base_link</parent>
      <child>left_shoulder_flange</child>
      <axis>
        <xyz>0 0 1</xyz>
        <limit>
          <lower>-3.14</lower>
          <upper>3.14</upper>
          <effort>1000</effort>
          <velocity>0.5</velocity>
        </limit>
        <dynamics>
          <damping>0.065</damping>
          <friction>0.025</friction>
          <spring_reference>0</spring_reference>
          <spring_stiffness>0</spring_stiffness>
        </dynamics>
      </axis>
    </joint>
    <link name='left_shoulder_flange'>
      <pose relative_to='base_link_to_left_shoulder_flange'>0 0 0 0 -0 0</pose>
      <inertial>
        <pose>-6.9e-05 0.002644 0.034842 0 -0 0</pose>
        <mass>0.703175</mass>
        <inertia>
          <ixx>0.000621305</ixx>
          <ixy>-1.51157e-06</ixy>
          <ixz>1.74351e-05</ixz>
          <iyy>0.000359584</iyy>
          <iyz>-4.0314e-06</iyz>
          <izz>0.000587928</izz>
        </inertia>
      </inertial>
      <collision name='left_shoulder_flange_collision'>
        <pose>0 0 0 0 -0 0</pose>
        <geometry>
          <mesh>
            <scale>0.001 0.001 0.001</scale>
            <uri>
              /home/cp/iit_ws/src/AlterEGO_v2/alterego_description/meshes/common/collision/la_flg_asm_flat_blu.stl</uri>
          </mesh>
        </geometry>
        <surface>
          <contact>
            <ode />
          </contact>
          <friction>
            <ode />
          </friction>
        </surface>
      </collision>
      <collision name='left_shoulder_flange_fixed_joint_lump__left_shoulder_cube_collision_1'>
        <pose>0 -0.0005 0.037 -1.5708 0 0</pose>
        <geometry>
          <box>
            <size>0.07 0.07 0.07</size>
          </box>
        </geometry>
        <surface>
          <contact>
            <ode />
          </contact>
          <friction>
            <ode />
          </friction>
        </surface>
      </collision>
      <visual name='left_shoulder_flange_visual'>
        <pose>0 0 0 0 -0 0</pose>
        <geometry>
          <mesh>
            <scale>0.001 0.001 0.001</scale>
            <uri>
              /home/cp/iit_ws/src/AlterEGO_v2/alterego_description/meshes/common/visual/la_flg_asm_flat_blu.dae</uri>
          </mesh>
        </geometry>
        <material>
          <script>
            <name>Gazebo/SkyBlue</name>
            <uri>file://media/materials/scripts/gazebo.material</uri>
          </script>
        </material>
      </visual>
      <visual name='left_shoulder_flange_fixed_joint_lump__left_shoulder_cube_visual_1'>
        <pose>0 -0.0005 0.037 -1.5708 0 0</pose>
        <geometry>
          <mesh>
            <scale>0.001 0.001 0.001</scale>
            <uri>
              /home/cp/iit_ws/src/AlterEGO_v2/alterego_description/meshes/alterego_v3/visual/qb_mate_advanced_plus_add.dae</uri>
          </mesh>
        </geometry>
        <material>
          <script>
            <name>Gazebo/Grey</name>
            <uri>file://media/materials/scripts/gazebo.material</uri>
          </script>
        </material>
      </visual>
      <self_collide>1</self_collide>
    </link>
    <joint name='left_shoulder_cube_to_left_arm_flange' type='revolute'>
      <pose relative_to='left_shoulder_flange'>0 -0 0.037 -1.5708 0 0</pose>
      <parent>left_shoulder_flange</parent>
      <child>left_arm_flange</child>
      <axis>
        <xyz>0 0 1</xyz>
        <limit>
          <lower>-3.14</lower>
          <upper>3.14</upper>
          <effort>1000</effort>
          <velocity>0.5</velocity>
        </limit>
        <dynamics>
          <damping>0.065</damping>
          <friction>0.025</friction>
          <spring_reference>0</spring_reference>
          <spring_stiffness>0</spring_stiffness>
        </dynamics>
      </axis>
    </joint>
    <link name='left_arm_flange'>
      <pose relative_to='left_shoulder_cube_to_left_arm_flange'>0 0 0 0 -0 0</pose>
      <inertial>
        <pose>-0.070251 0.003185 7.5e-05 0 -0 0</pose>
        <mass>0.579431</mass>
        <inertia>
          <ixx>0.00030007</ixx>
          <ixy>-0.000171677</ixy>
          <ixz>9.18388e-07</ixz>
          <iyy>0.00134753</iyy>
          <iyz>1.37664e-07</iyz>
          <izz>0.00141623</izz>
        </inertia>
      </inertial>
      <collision name='left_arm_flange_collision'>
        <pose>0 0 0 0 -0 0</pose>
        <geometry>
          <mesh>
            <scale>0.001 0.001 0.001</scale>
            <uri>
              /home/cp/iit_ws/src/AlterEGO_v2/alterego_description/meshes/alterego_v3/collision/la_flg_c_wb_large.stl</uri>
          </mesh>
        </geometry>
        <surface>
          <contact>
            <ode />
          </contact>
          <friction>
            <ode />
          </friction>
        </surface>
      </collision>
      <collision name='left_arm_flange_fixed_joint_lump__left_arm_cube_collision_1'>
        <pose>-0.09 0 0 3.14159 1.5708 0</pose>
        <geometry>
          <box>
            <size>0.07 0.07 0.07</size>
          </box>
        </geometry>
        <surface>
          <contact>
            <ode />
          </contact>
          <friction>
            <ode />
          </friction>
        </surface>
      </collision>
      <visual name='left_arm_flange_visual'>
        <pose>0 0 0 0 -0 0</pose>
        <geometry>
          <mesh>
            <scale>0.001 0.001 0.001</scale>
            <uri>
              /home/cp/iit_ws/src/AlterEGO_v2/alterego_description/meshes/alterego_v3/visual/la_flg_c_wb_large.dae</uri>
          </mesh>
        </geometry>
        <material>
          <script>
            <name>Gazebo/SkyBlue</name>
            <uri>file://media/materials/scripts/gazebo.material</uri>
          </script>
        </material>
      </visual>
      <visual name='left_arm_flange_fixed_joint_lump__left_arm_cube_visual_1'>
        <pose>-0.09 0 0 3.14159 1.5708 0</pose>
        <geometry>
          <mesh>
            <scale>0.001 0.001 0.001</scale>
            <uri>
              /home/cp/iit_ws/src/AlterEGO_v2/alterego_description/meshes/common/visual/qb_move_advanced_for_mate.dae</uri>
          </mesh>
        </geometry>
        <material>
          <script>
            <name>Gazebo/Grey</name>
            <uri>file://media/materials/scripts/gazebo.material</uri>
          </script>
        </material>
      </visual>
      <self_collide>1</self_collide>
    </link>
    <joint name='left_arm_cube_to_left_elbow_flange_sensor' type='revolute'>
      <pose relative_to='left_arm_flange'>-0.1565 -0 0 1.5708 0 -1.5708</pose>
      <parent>left_arm_flange</parent>
      <child>left_elbow_flange_sensor</child>
      <axis>
        <xyz>0 0 1</xyz>
        <limit>
          <lower>-3.14</lower>
          <upper>3.14</upper>
          <effort>1000</effort>
          <velocity>0.5</velocity>
        </limit>
        <dynamics>
          <damping>0.065</damping>
          <friction>0.025</friction>
          <spring_reference>0</spring_reference>
          <spring_stiffness>0</spring_stiffness>
        </dynamics>
      </axis>
    </joint>
    <link name='left_elbow_flange_sensor'>
      <pose relative_to='left_arm_cube_to_left_elbow_flange_sensor'>0 0 0 0 -0 0</pose>
      <inertial>
        <pose>0.001053 -4.8e-05 0.042674 0 -0 0</pose>
        <mass>0.598471</mass>
        <inertia>
          <ixx>0.000548866</ixx>
          <ixy>-9.03269e-08</ixy>
          <ixz>-7.78145e-06</ixz>
          <iyy>0.000549199</iyy>
          <iyz>-3.83727e-06</iyz>
          <izz>0.000302501</izz>
        </inertia>
      </inertial>
      <collision name='left_elbow_flange_sensor_collision'>
        <pose>0 0 0 0 -0 0</pose>
        <geometry>
          <mesh>
            <scale>0.001 0.001 0.001</scale>
            <uri>
              /home/cp/iit_ws/src/AlterEGO_v2/alterego_description/meshes/alterego_v3/collision/fsens_hinge_001.stl</uri>
          </mesh>
        </geometry>
      </collision>
      <collision name='left_elbow_flange_sensor_fixed_joint_lump__left_elbow_flange_collision_1'>
        <pose>0 0 0.018 0 0 -1.5708</pose>
        <geometry>
          <mesh>
            <scale>0.001 0.001 0.001</scale>
            <uri>
              /home/cp/iit_ws/src/AlterEGO_v2/alterego_description/meshes/common/collision/la_flg_asm_flat_blu.stl</uri>
          </mesh>
        </geometry>
        <surface>
          <contact>
            <ode />
          </contact>
          <friction>
            <ode />
          </friction>
        </surface>
      </collision>
      <collision name='left_elbow_flange_sensor_fixed_joint_lump__left_elbow_cube_collision_2'>
        <pose>0 0 0.055 -1.5708 0 -1.5708</pose>
        <geometry>
          <box>
            <size>0.07 0.07 0.07</size>
          </box>
        </geometry>
        <surface>
          <contact>
            <ode />
          </contact>
          <friction>
            <ode />
          </friction>
        </surface>
      </collision>
      <visual name='left_elbow_flange_sensor_visual'>
        <pose>0 0 0 0 -0 0</pose>
        <geometry>
          <mesh>
            <scale>0.001 0.001 0.001</scale>
            <uri>
              /home/cp/iit_ws/src/AlterEGO_v2/alterego_description/meshes/alterego_v3/visual/fsens_hinge_001.dae</uri>
          </mesh>
        </geometry>
      </visual>
      <visual name='left_elbow_flange_sensor_fixed_joint_lump__left_elbow_flange_visual_1'>
        <pose>0 0 0.018 0 0 -1.5708</pose>
        <geometry>
          <mesh>
            <scale>0.001 0.001 0.001</scale>
            <uri>
              /home/cp/iit_ws/src/AlterEGO_v2/alterego_description/meshes/common/visual/la_flg_asm_flat_blu.dae</uri>
          </mesh>
        </geometry>
        <material>
          <script>
            <name>Gazebo/SkyBlue</name>
            <uri>file://media/materials/scripts/gazebo.material</uri>
          </script>
        </material>
      </visual>
      <visual name='left_elbow_flange_sensor_fixed_joint_lump__left_elbow_cube_visual_2'>
        <pose>0 0 0.055 -1.5708 0 -1.5708</pose>
        <geometry>
          <mesh>
            <scale>0.001 0.001 0.001</scale>
            <uri>
              /home/cp/iit_ws/src/AlterEGO_v2/alterego_description/meshes/common/visual/qb_move_advanced_for_mate.dae</uri>
          </mesh>
        </geometry>
        <material>
          <script>
            <name>Gazebo/Grey</name>
            <uri>file://media/materials/scripts/gazebo.material</uri>
          </script>
        </material>
      </visual>
      <self_collide>1</self_collide>
    </link>
    <joint name='left_elbow_cube_to_left_forearm_flange' type='revolute'>
      <pose relative_to='left_elbow_flange_sensor'>-0.0005 -0 0.055 -0 1.5708 0</pose>
      <parent>left_elbow_flange_sensor</parent>
      <child>left_forearm_flange</child>
      <axis>
        <xyz>0 0 1</xyz>
        <limit>
          <lower>-3.14</lower>
          <upper>3.14</upper>
          <effort>1000</effort>
          <velocity>0.5</velocity>
        </limit>
        <dynamics>
          <damping>0.065</damping>
          <friction>0.025</friction>
          <spring_reference>0</spring_reference>
          <spring_stiffness>0</spring_stiffness>
        </dynamics>
      </axis>
    </joint>
    <link name='left_forearm_flange'>
      <pose relative_to='left_elbow_cube_to_left_forearm_flange'>0 0 0 0 -0 0</pose>
      <inertial>
        <pose>-0.07792 0.003767 -1.4e-05 0 -0 0</pose>
        <mass>0.540829</mass>
        <inertia>
          <ixx>0.000285746</ixx>
          <ixy>-0.00012138</ixy>
          <ixz>-1.02457e-07</ixz>
          <iyy>0.000796731</iyy>
          <iyz>-2.79322e-08</iyz>
          <izz>0.000868681</izz>
        </inertia>
      </inertial>
      <collision name='left_forearm_flange_collision'>
        <pose>0 0 0 0 -0 0</pose>
        <geometry>
          <mesh>
            <scale>0.001 0.001 0.001</scale>
            <uri>
              /home/cp/iit_ws/src/AlterEGO_v2/alterego_description/meshes/common/collision/la_flg_asm_c_wb_blu.stl</uri>
          </mesh>
        </geometry>
        <surface>
          <contact>
            <ode />
          </contact>
          <friction>
            <ode />
          </friction>
        </surface>
      </collision>
      <collision name='left_forearm_flange_fixed_joint_lump__left_forearm_cube_collision_1'>
        <pose>-0.09 0 0 1.5708 -0 -1.5708</pose>
        <geometry>
          <box>
            <size>0.07 0.07 0.07</size>
          </box>
        </geometry>
        <surface>
          <contact>
            <ode />
          </contact>
          <friction>
            <ode />
          </friction>
        </surface>
      </collision>
      <visual name='left_forearm_flange_visual'>
        <pose>0 0 0 0 -0 0</pose>
        <geometry>
          <mesh>
            <scale>0.001 0.001 0.001</scale>
            <uri>
              /home/cp/iit_ws/src/AlterEGO_v2/alterego_description/meshes/common/visual/la_flg_asm_c_wb_blu.dae</uri>
          </mesh>
        </geometry>
        <material>
          <script>
            <name>Gazebo/SkyBlue</name>
            <uri>file://media/materials/scripts/gazebo.material</uri>
          </script>
        </material>
      </visual>
      <visual name='left_forearm_flange_fixed_joint_lump__left_forearm_cube_visual_1'>
        <pose>-0.09 0 0 1.5708 -0 -1.5708</pose>
        <geometry>
          <mesh>
            <scale>0.001 0.001 0.001</scale>
            <uri>
              /home/cp/iit_ws/src/AlterEGO_v2/alterego_description/meshes/common/visual/qb_move_advanced_for_mate.dae</uri>
          </mesh>
        </geometry>
        <material>
          <script>
            <name>Gazebo/Grey</name>
            <uri>file://media/materials/scripts/gazebo.material</uri>
          </script>
        </material>
      </visual>
      <self_collide>1</self_collide>
    </link>
    <joint name='left_forearm_cube_to_left_wrist_flange' type='revolute'>
      <pose relative_to='left_forearm_flange'>-0.1305 -0 0 3.14159 1.5708 0</pose>
      <parent>left_forearm_flange</parent>
      <child>left_wrist_flange</child>
      <axis>
        <xyz>0 0 1</xyz>
        <limit>
          <lower>-3.14</lower>
          <upper>3.14</upper>
          <effort>1000</effort>
          <velocity>0.5</velocity>
        </limit>
        <dynamics>
          <damping>0.065</damping>
          <friction>0.025</friction>
          <spring_reference>0</spring_reference>
          <spring_stiffness>0</spring_stiffness>
        </dynamics>
      </axis>
    </joint>
    <link name='left_wrist_flange'>
      <pose relative_to='left_forearm_cube_to_left_wrist_flange'>0 0 0 0 -0 0</pose>
      <inertial>
        <pose>0.001775 -0.006742 0.049042 0 -0 0</pose>
        <mass>0.755533</mass>
        <inertia>
          <ixx>0.00102134</ixx>
          <ixy>1.02078e-05</ixy>
          <ixz>-6.84955e-05</ixz>
          <iyy>0.000829982</iyy>
          <iyz>5.18939e-05</iyz>
          <izz>0.000536396</izz>
        </inertia>
      </inertial>
      <collision name='left_wrist_flange_collision'>
        <pose>0 0 0 0 -0 0</pose>
        <geometry>
          <mesh>
            <scale>0.001 0.001 0.001</scale>
            <uri>
              /home/cp/iit_ws/src/AlterEGO_v2/alterego_description/meshes/common/collision/la_flg_asm_flat_blu.stl</uri>
          </mesh>
        </geometry>
        <surface>
          <contact>
            <ode />
          </contact>
          <friction>
            <ode />
          </friction>
        </surface>
      </collision>
      <collision name='left_wrist_flange_fixed_joint_lump__left_wrist_collision_1'>
        <pose>0.0119 0 0.099864 1.5708 -0 0</pose>
        <geometry>
          <mesh>
            <scale>0.001 0.001 0.001</scale>
            <uri>
              /home/cp/iit_ws/src/AlterEGO_v2/alterego_description/meshes/alterego_v3/collision/left_wrist_v2_1_urdf.stl</uri>
          </mesh>
        </geometry>
        <surface>
          <contact>
            <ode />
          </contact>
          <friction>
            <ode />
          </friction>
        </surface>
      </collision>
      <visual name='left_wrist_flange_visual'>
        <pose>0 0 0 0 -0 0</pose>
        <geometry>
          <mesh>
            <scale>0.001 0.001 0.001</scale>
            <uri>
              /home/cp/iit_ws/src/AlterEGO_v2/alterego_description/meshes/common/visual/la_flg_asm_flat_blu.dae</uri>
          </mesh>
        </geometry>
        <material>
          <script>
            <name>Gazebo/SkyBlue</name>
            <uri>file://media/materials/scripts/gazebo.material</uri>
          </script>
        </material>
      </visual>
      <visual name='left_wrist_flange_fixed_joint_lump__left_wrist_visual_1'>
        <pose>0.0119 0 0.099864 1.5708 -0 0</pose>
        <geometry>
          <mesh>
            <scale>0.001 0.001 0.001</scale>
            <uri>
              /home/cp/iit_ws/src/AlterEGO_v2/alterego_description/meshes/alterego_v3/visual/left_wrist_v2_1_urdf.dae</uri>
          </mesh>
        </geometry>
        <material>
          <script>
            <name>Gazebo/Grey</name>
            <uri>file://media/materials/scripts/gazebo.material</uri>
          </script>
        </material>
      </visual>
      <self_collide>1</self_collide>
    </link>
    <joint name='left_wrist_to_left_hand' type='revolute'>
      <pose relative_to='left_wrist_flange'>0.0119 0 0.099864 1.5708 -0 0</pose>
      <parent>left_wrist_flange</parent>
      <child>left_hand</child>
      <axis>
        <xyz>0 0 1</xyz>
        <limit>
          <lower>-3.14</lower>
          <upper>3.14</upper>
          <effort>1000</effort>
          <velocity>0.5</velocity>
        </limit>
        <dynamics>
          <spring_reference>0</spring_reference>
          <spring_stiffness>0</spring_stiffness>
        </dynamics>
      </axis>
    </joint>
    <link name='left_hand'>
      <pose relative_to='left_wrist_to_left_hand'>0 0 0 0 -0 0</pose>
      <inertial>
        <pose>0.004173 0.063288 0.006066 0 -0 0</pose>
        <mass>0.290131</mass>
        <inertia>
          <ixx>0.000563778</ixx>
          <ixy>-2.58914e-05</ixy>
          <ixz>-1.01421e-05</ixz>
          <iyy>0.000149898</iyy>
          <iyz>5.93616e-06</iyz>
          <izz>0.000447698</izz>
        </inertia>
      </inertial>
      <collision name='left_hand_collision'>
        <pose>0 0 0 0 -0 0</pose>
        <geometry>
          <mesh>
            <scale>0.001 0.001 0.001</scale>
            <uri>
              /home/cp/iit_ws/src/AlterEGO_v2/alterego_description/meshes/common/collision/softhand_3_sx_urdf.stl</uri>
          </mesh>
        </geometry>
        <surface>
          <contact>
            <ode />
          </contact>
          <friction>
            <ode />
          </friction>
        </surface>
      </collision>
      <visual name='left_hand_visual'>
        <pose>0 0 0 0 -0 0</pose>
        <geometry>
          <mesh>
            <scale>0.001 0.001 0.001</scale>
            <uri>
              /home/cp/iit_ws/src/AlterEGO_v2/alterego_description/meshes/common/visual/softhand_3_sx_urdf.dae</uri>
          </mesh>
        </geometry>
        <material>
          <script>
            <name>Gazebo/Grey</name>
            <uri>file://media/materials/scripts/gazebo.material</uri>
          </script>
        </material>
      </visual>
      <self_collide>1</self_collide>
    </link>
    <joint name='base_link_to_neck' type='revolute'>
      <pose relative_to='base_link'>0 0 0.9215 0 -0 0</pose>
      <parent>base_link</parent>
      <child>neck</child>
      <axis>
        <xyz>0 0 1</xyz>
        <limit>
          <lower>-1.57</lower>
          <upper>1.57</upper>
          <effort>1000</effort>
          <velocity>0.5</velocity>
        </limit>
        <dynamics>
          <damping>0.065</damping>
          <friction>0.025</friction>
          <spring_reference>0</spring_reference>
          <spring_stiffness>0</spring_stiffness>
        </dynamics>
      </axis>
    </joint>
    <link name='neck'>
      <pose relative_to='base_link_to_neck'>0 0 0 0 -0 0</pose>
      <inertial>
        <pose>0.005112 0.006518 0.030662 0 -0 0</pose>
        <mass>0.0962138</mass>
        <inertia>
          <ixx>0.000222415</ixx>
          <ixy>-8.14274e-06</ixy>
          <ixz>-2.78727e-05</ixz>
          <iyy>0.000164528</iyy>
          <iyz>-3.43615e-05</iyz>
          <izz>0.000116712</izz>
        </inertia>
      </inertial>
      <collision name='neck_collision'>
        <pose>0 0 0 0 -0 0</pose>
        <geometry>
          <mesh>
            <scale>0.001 0.001 0.001</scale>
            <uri>
              /home/cp/iit_ws/src/AlterEGO_v2/alterego_description/meshes/alterego_v3/collision/flange_c_long_new.stl</uri>
          </mesh>
        </geometry>
        <surface>
          <contact>
            <ode />
          </contact>
          <friction>
            <ode />
          </friction>
        </surface>
      </collision>
      <visual name='neck_visual'>
        <pose>0 0 0 0 -0 0</pose>
        <geometry>
          <mesh>
            <scale>0.001 0.001 0.001</scale>
            <uri>
              /home/cp/iit_ws/src/AlterEGO_v2/alterego_description/meshes/alterego_v3/visual/flange_c_long_new.dae</uri>
          </mesh>
        </geometry>
        <material>
          <script>
            <name>Gazebo/SkyBlue</name>
            <uri>file://media/materials/scripts/gazebo.material</uri>
          </script>
        </material>
      </visual>
      <self_collide>1</self_collide>
    </link>
    <joint name='neck_to_neck_cube' type='revolute'>
      <pose relative_to='neck'>0.018 -0.0005 0.085 -1.5708 0.785398 3.14159</pose>
      <parent>neck</parent>
      <child>neck_cube</child>
      <axis>
        <xyz>0 0 -1</xyz>
        <limit>
          <lower>-1.57</lower>
          <upper>1.57</upper>
          <effort>1000</effort>
          <velocity>0.5</velocity>
        </limit>
        <dynamics>
          <damping>0.065</damping>
          <friction>0.025</friction>
          <spring_reference>0</spring_reference>
          <spring_stiffness>0</spring_stiffness>
        </dynamics>
      </axis>
    </joint>
    <link name='neck_cube'>
      <pose relative_to='neck_to_neck_cube'>0 0 0 0 -0 0</pose>
      <inertial>
        <pose>-0.00836 0.061811 0.017879 0 -0 0</pose>
        <mass>0.928833</mass>
        <inertia>
          <ixx>0.00614105</ixx>
          <ixy>-0.000296954</ixy>
          <ixz>-0.000178391</ixz>
          <iyy>0.00195214</iyy>
          <iyz>-0.001324</iyz>
          <izz>0.00624196</izz>
        </inertia>
      </inertial>
      <collision name='neck_cube_collision'>
        <pose>0 0 0 0 -0 0</pose>
        <geometry>
          <box>
            <size>0.07 0.07 0.07</size>
          </box>
        </geometry>
        <surface>
          <contact>
            <ode />
          </contact>
          <friction>
            <ode />
          </friction>
        </surface>
      </collision>
      <collision name='neck_cube_fixed_joint_lump__head_collision_1'>
        <pose>0 0 0 0 -0 0</pose>
        <geometry>
          <mesh>
            <scale>0.001 0.001 0.001</scale>
            <uri>
              /home/cp/iit_ws/src/AlterEGO_v2/alterego_description/meshes/alterego_v3/collision/mteg102_head_201.stl</uri>
          </mesh>
        </geometry>
        <surface>
          <contact>
            <ode />
          </contact>
          <friction>
            <ode />
          </friction>
        </surface>
      </collision>
      <collision name='neck_cube_fixed_joint_lump__camera_collision_2'>
        <pose>-0.087907 0.021681 -0.0065 -1.5708 -0 2.35619</pose>
        <geometry>
          <mesh>
            <scale>0.001 0.001 0.001</scale>
            <uri>
              /home/cp/iit_ws/src/AlterEGO_v2/alterego_description/meshes/common/collision/zedm.stl</uri>
          </mesh>
        </geometry>
      </collision>
      <collision name='neck_cube_fixed_joint_lump__realsense_collision_3'>
        <pose>-2.28599 0.038743 0 -1.5708 -0 2.35619</pose>
        <geometry>
          <mesh>
            <scale>0.001 0.001 0.001</scale>
            <uri>
              /home/cp/iit_ws/src/AlterEGO_v2/alterego_description/meshes/common/collision/intel_realsense_d415_old_asm.stl</uri>
          </mesh>
        </geometry>
        <surface>
          <contact>
            <ode />
          </contact>
          <friction>
            <ode />
          </friction>
        </surface>
      </collision>
      <visual name='neck_cube_visual'>
        <pose>0 0 0 0 -0 0</pose>
        <geometry>
          <mesh>
            <scale>0.001 0.001 0.001</scale>
            <uri>
              /home/cp/iit_ws/src/AlterEGO_v2/alterego_description/meshes/common/visual/qb_move_advanced_for_mate.dae</uri>
          </mesh>
        </geometry>
        <material>
          <script>
            <name>Gazebo/Grey</name>
            <uri>file://media/materials/scripts/gazebo.material</uri>
          </script>
        </material>
      </visual>
      <visual name='neck_cube_fixed_joint_lump__head_visual_1'>
        <pose>0 0 0 0 -0 0</pose>
        <geometry>
          <mesh>
            <scale>0.001 0.001 0.001</scale>
            <uri>
              /home/cp/iit_ws/src/AlterEGO_v2/alterego_description/meshes/alterego_v3/visual/mteg102_head_201.dae</uri>
          </mesh>
        </geometry>
        <material>
          <script>
            <name>Gazebo/Grey</name>
            <uri>file://media/materials/scripts/gazebo.material</uri>
          </script>
        </material>
      </visual>
      <visual name='neck_cube_fixed_joint_lump__camera_visual_2'>
        <pose>-0.087907 0.021681 -0.0065 -1.5708 -0 2.35619</pose>
        <geometry>
          <mesh>
            <scale>0.001 0.001 0.001</scale>
            <uri>
              /home/cp/iit_ws/src/AlterEGO_v2/alterego_description/meshes/common/visual/zedm.dae</uri>
          </mesh>
        </geometry>
      </visual>
      <visual name='neck_cube_fixed_joint_lump__realsense_visual_3'>
        <pose>-0.065673 0.038743 0 -2.35699 1.5708 0</pose>
        <geometry>
          <mesh>
            <scale>0.001 0.001 0.001</scale>
            <uri>
              /home/cp/iit_ws/src/AlterEGO_v2/alterego_description/meshes/common/visual/intel_realsense_d415_old_asm.dae</uri>
          </mesh>
        </geometry>
        <material>
          <script>
            <name>Gazebo/Black</name>
            <uri>file://media/materials/scripts/gazebo.material</uri>
          </script>
        </material>
      </visual>
      <self_collide>1</self_collide>
    </link>
    <joint name='base_link_to_right_shoulder_flange' type='revolute'>
      <pose relative_to='base_link'>0.028648 -0.220259 0.901246 0.174535 -1.39626 1.57079</pose>
      <parent>base_link</parent>
      <child>right_shoulder_flange</child>
      <axis>
        <xyz>0 0 1</xyz>
        <limit>
          <lower>-3.14</lower>
          <upper>3.14</upper>
          <effort>1000</effort>
          <velocity>0.5</velocity>
        </limit>
        <dynamics>
          <damping>0.065</damping>
          <friction>0.025</friction>
          <spring_reference>0</spring_reference>
          <spring_stiffness>0</spring_stiffness>
        </dynamics>
      </axis>
    </joint>
    <link name='right_shoulder_flange'>
      <pose relative_to='base_link_to_right_shoulder_flange'>0 0 0 0 -0 0</pose>
      <inertial>
        <pose>5.9e-05 -0.002644 0.034842 0 -0 0</pose>
        <mass>0.703175</mass>
        <inertia>
          <ixx>0.000621305</ixx>
          <ixy>-1.49372e-06</ixy>
          <ixz>-1.7666e-05</ixz>
          <iyy>0.000359585</iyy>
          <iyz>4.0314e-06</iyz>
          <izz>0.000587929</izz>
        </inertia>
      </inertial>
      <collision name='right_shoulder_flange_collision'>
        <pose>0 0 0 0 -0 0</pose>
        <geometry>
          <mesh>
            <scale>0.001 0.001 0.001</scale>
            <uri>
              /home/cp/iit_ws/src/AlterEGO_v2/alterego_description/meshes/common/collision/la_flg_asm_flat_blu.stl</uri>
          </mesh>
        </geometry>
        <surface>
          <contact>
            <ode />
          </contact>
          <friction>
            <ode />
          </friction>
        </surface>
      </collision>
      <collision name='right_shoulder_flange_fixed_joint_lump__right_shoulder_cube_collision_1'>
        <pose>0 0.0005 0.037 -1.5708 -0 -3.14159</pose>
        <geometry>
          <box>
            <size>0.07 0.07 0.07</size>
          </box>
        </geometry>
        <surface>
          <contact>
            <ode />
          </contact>
          <friction>
            <ode />
          </friction>
        </surface>
      </collision>
      <visual name='right_shoulder_flange_visual'>
        <pose>0 0 0 0 -0 0</pose>
        <geometry>
          <mesh>
            <scale>0.001 0.001 0.001</scale>
            <uri>
              /home/cp/iit_ws/src/AlterEGO_v2/alterego_description/meshes/common/visual/la_flg_asm_flat_blu.dae</uri>
          </mesh>
        </geometry>
        <material>
          <script>
            <name>Gazebo/SkyBlue</name>
            <uri>file://media/materials/scripts/gazebo.material</uri>
          </script>
        </material>
      </visual>
      <visual name='right_shoulder_flange_fixed_joint_lump__right_shoulder_cube_visual_1'>
        <pose>0 0.0005 0.037 -1.5708 -0 -3.14159</pose>
        <geometry>
          <mesh>
            <scale>0.001 0.001 0.001</scale>
            <uri>
              /home/cp/iit_ws/src/AlterEGO_v2/alterego_description/meshes/alterego_v3/visual/qb_mate_advanced_plus_add.dae</uri>
          </mesh>
        </geometry>
        <material>
          <script>
            <name>Gazebo/Grey</name>
            <uri>file://media/materials/scripts/gazebo.material</uri>
          </script>
        </material>
      </visual>
      <self_collide>1</self_collide>
    </link>
    <joint name='right_shoulder_cube_to_right_arm_flange' type='revolute'>
      <pose relative_to='right_shoulder_flange'>0 0 0.037 1.5708 -0 0</pose>
      <parent>right_shoulder_flange</parent>
      <child>right_arm_flange</child>
      <axis>
        <xyz>0 0 1</xyz>
        <limit>
          <lower>-3.14</lower>
          <upper>3.14</upper>
          <effort>1000</effort>
          <velocity>0.5</velocity>
        </limit>
        <dynamics>
          <damping>0.065</damping>
          <friction>0.025</friction>
          <spring_reference>0</spring_reference>
          <spring_stiffness>0</spring_stiffness>
        </dynamics>
      </axis>
    </joint>
    <link name='right_arm_flange'>
      <pose relative_to='right_shoulder_cube_to_right_arm_flange'>0 0 0 0 -0 0</pose>
      <inertial>
        <pose>-0.070251 0.003185 7.5e-05 0 -0 0</pose>
        <mass>0.579431</mass>
        <inertia>
          <ixx>0.00030007</ixx>
          <ixy>-0.000171677</ixy>
          <ixz>9.18388e-07</ixz>
          <iyy>0.00134753</iyy>
          <iyz>1.37664e-07</iyz>
          <izz>0.00141623</izz>
        </inertia>
      </inertial>
      <collision name='right_arm_flange_collision'>
        <pose>0 0 0 0 -0 0</pose>
        <geometry>
          <mesh>
            <scale>0.001 0.001 0.001</scale>
            <uri>
              /home/cp/iit_ws/src/AlterEGO_v2/alterego_description/meshes/alterego_v3/collision/la_flg_c_wb_large.stl</uri>
          </mesh>
        </geometry>
        <surface>
          <contact>
            <ode />
          </contact>
          <friction>
            <ode />
          </friction>
        </surface>
      </collision>
      <collision name='right_arm_flange_fixed_joint_lump__right_arm_cube_collision_1'>
        <pose>-0.09 0 0 3.14159 1.5708 0</pose>
        <geometry>
          <box>
            <size>0.07 0.07 0.07</size>
          </box>
        </geometry>
        <surface>
          <contact>
            <ode />
          </contact>
          <friction>
            <ode />
          </friction>
        </surface>
      </collision>
      <visual name='right_arm_flange_visual'>
        <pose>0 0 0 0 -0 0</pose>
        <geometry>
          <mesh>
            <scale>0.001 0.001 0.001</scale>
            <uri>
              /home/cp/iit_ws/src/AlterEGO_v2/alterego_description/meshes/alterego_v3/visual/la_flg_c_wb_large.dae</uri>
          </mesh>
        </geometry>
        <material>
          <script>
            <name>Gazebo/SkyBlue</name>
            <uri>file://media/materials/scripts/gazebo.material</uri>
          </script>
        </material>
      </visual>
      <visual name='right_arm_flange_fixed_joint_lump__right_arm_cube_visual_1'>
        <pose>-0.09 0 0 3.14159 1.5708 0</pose>
        <geometry>
          <mesh>
            <scale>0.001 0.001 0.001</scale>
            <uri>
              /home/cp/iit_ws/src/AlterEGO_v2/alterego_description/meshes/common/visual/qb_move_advanced_for_mate.dae</uri>
          </mesh>
        </geometry>
        <material>
          <script>
            <name>Gazebo/Grey</name>
            <uri>file://media/materials/scripts/gazebo.material</uri>
          </script>
        </material>
      </visual>
      <self_collide>1</self_collide>
    </link>
    <joint name='right_arm_cube_to_right_elbow_flange_sensor' type='revolute'>
      <pose relative_to='right_arm_flange'>-0.1565 -0 0 1.5708 0 -1.5708</pose>
      <parent>right_arm_flange</parent>
      <child>right_elbow_flange_sensor</child>
      <axis>
        <xyz>0 0 1</xyz>
        <limit>
          <lower>-3.14</lower>
          <upper>3.14</upper>
          <effort>1000</effort>
          <velocity>0.5</velocity>
        </limit>
        <dynamics>
          <damping>0.065</damping>
          <friction>0.025</friction>
          <spring_reference>0</spring_reference>
          <spring_stiffness>0</spring_stiffness>
        </dynamics>
      </axis>
    </joint>
    <link name='right_elbow_flange_sensor'>
      <pose relative_to='right_arm_cube_to_right_elbow_flange_sensor'>0 0 0 0 -0 0</pose>
      <inertial>
        <pose>-0.001053 -4.8e-05 0.042649 0 -0 0</pose>
        <mass>0.598471</mass>
        <inertia>
          <ixx>0.00054849</ixx>
          <ixy>9.03266e-08</ixy>
          <ixz>7.77636e-06</ixz>
          <iyy>0.000548824</iyy>
          <iyz>-3.83509e-06</iyz>
          <izz>0.000302501</izz>
        </inertia>
      </inertial>
      <collision name='right_elbow_flange_sensor_collision'>
        <pose>0 0 0 0 -0 0</pose>
        <geometry>
          <mesh>
            <scale>0.001 0.001 0.001</scale>
            <uri>
              /home/cp/iit_ws/src/AlterEGO_v2/alterego_description/meshes/alterego_v3/collision/fsens_hinge_001.stl</uri>
          </mesh>
        </geometry>
      </collision>
      <collision name='right_elbow_flange_sensor_fixed_joint_lump__right_elbow_flange_collision_1'>
        <pose>0 0 0.018 0 0 -1.5708</pose>
        <geometry>
          <mesh>
            <scale>0.001 0.001 0.001</scale>
            <uri>
              /home/cp/iit_ws/src/AlterEGO_v2/alterego_description/meshes/common/collision/la_flg_asm_flat_blu.stl</uri>
          </mesh>
        </geometry>
        <surface>
          <contact>
            <ode />
          </contact>
          <friction>
            <ode />
          </friction>
        </surface>
      </collision>
      <collision name='right_elbow_flange_sensor_fixed_joint_lump__right_elbow_cube_collision_2'>
        <pose>0 0 0.055 1.5708 -0 -1.5708</pose>
        <geometry>
          <box>
            <size>0.07 0.07 0.07</size>
          </box>
        </geometry>
        <surface>
          <contact>
            <ode />
          </contact>
          <friction>
            <ode />
          </friction>
        </surface>
      </collision>
      <visual name='right_elbow_flange_sensor_visual'>
        <pose>0 0 0 0 -0 0</pose>
        <geometry>
          <mesh>
            <scale>0.001 0.001 0.001</scale>
            <uri>
              /home/cp/iit_ws/src/AlterEGO_v2/alterego_description/meshes/alterego_v3/visual/fsens_hinge_001.dae</uri>
          </mesh>
        </geometry>
      </visual>
      <visual name='right_elbow_flange_sensor_fixed_joint_lump__right_elbow_flange_visual_1'>
        <pose>0 0 0.018 0 0 -1.5708</pose>
        <geometry>
          <mesh>
            <scale>0.001 0.001 0.001</scale>
            <uri>
              /home/cp/iit_ws/src/AlterEGO_v2/alterego_description/meshes/common/visual/la_flg_asm_flat_blu.dae</uri>
          </mesh>
        </geometry>
        <material>
          <script>
            <name>Gazebo/SkyBlue</name>
            <uri>file://media/materials/scripts/gazebo.material</uri>
          </script>
        </material>
      </visual>
      <visual name='right_elbow_flange_sensor_fixed_joint_lump__right_elbow_cube_visual_2'>
        <pose>0 0 0.055 1.5708 -0 -1.5708</pose>
        <geometry>
          <mesh>
            <scale>0.001 0.001 0.001</scale>
            <uri>
              /home/cp/iit_ws/src/AlterEGO_v2/alterego_description/meshes/common/visual/qb_move_advanced_for_mate.dae</uri>
          </mesh>
        </geometry>
        <material>
          <script>
            <name>Gazebo/Grey</name>
            <uri>file://media/materials/scripts/gazebo.material</uri>
          </script>
        </material>
      </visual>
      <self_collide>1</self_collide>
    </link>
    <joint name='right_elbow_cube_to_right_forearm_flange' type='revolute'>
      <pose relative_to='right_elbow_flange_sensor'>0.0005 0 0.055 3.14159 1.5708 0</pose>
      <parent>right_elbow_flange_sensor</parent>
      <child>right_forearm_flange</child>
      <axis>
        <xyz>0 0 1</xyz>
        <limit>
          <lower>-3.14</lower>
          <upper>3.14</upper>
          <effort>1000</effort>
          <velocity>0.5</velocity>
        </limit>
        <dynamics>
          <damping>0.065</damping>
          <friction>0.025</friction>
          <spring_reference>0</spring_reference>
          <spring_stiffness>0</spring_stiffness>
        </dynamics>
      </axis>
    </joint>
    <link name='right_forearm_flange'>
      <pose relative_to='right_elbow_cube_to_right_forearm_flange'>0 0 0 0 -0 0</pose>
      <inertial>
        <pose>-0.07792 0.003607 1.4e-05 0 -0 0</pose>
        <mass>0.540829</mass>
        <inertia>
          <ixx>0.000286386</ixx>
          <ixy>-0.00012255</ixy>
          <ixz>1.02458e-07</ixz>
          <iyy>0.000796731</iyy>
          <iyz>2.81655e-08</iyz>
          <izz>0.000869322</izz>
        </inertia>
      </inertial>
      <collision name='right_forearm_flange_collision'>
        <pose>0 0 0 0 -0 0</pose>
        <geometry>
          <mesh>
            <scale>0.001 0.001 0.001</scale>
            <uri>
              /home/cp/iit_ws/src/AlterEGO_v2/alterego_description/meshes/common/collision/la_flg_asm_c_wb_blu.stl</uri>
          </mesh>
        </geometry>
        <surface>
          <contact>
            <ode />
          </contact>
          <friction>
            <ode />
          </friction>
        </surface>
      </collision>
      <collision name='right_forearm_flange_fixed_joint_lump__right_forearm_cube_collision_1'>
        <pose>-0.09 0 0 -1.5708 -0 1.5708</pose>
        <geometry>
          <box>
            <size>0.07 0.07 0.07</size>
          </box>
        </geometry>
        <surface>
          <contact>
            <ode />
          </contact>
          <friction>
            <ode />
          </friction>
        </surface>
      </collision>
      <visual name='right_forearm_flange_visual'>
        <pose>0 0 0 0 -0 0</pose>
        <geometry>
          <mesh>
            <scale>0.001 0.001 0.001</scale>
            <uri>
              /home/cp/iit_ws/src/AlterEGO_v2/alterego_description/meshes/common/visual/la_flg_asm_c_wb_blu.dae</uri>
          </mesh>
        </geometry>
        <material>
          <script>
            <name>Gazebo/SkyBlue</name>
            <uri>file://media/materials/scripts/gazebo.material</uri>
          </script>
        </material>
      </visual>
      <visual name='right_forearm_flange_fixed_joint_lump__right_forearm_cube_visual_1'>
        <pose>-0.09 0 0 -1.5708 -0 1.5708</pose>
        <geometry>
          <mesh>
            <scale>0.001 0.001 0.001</scale>
            <uri>
              /home/cp/iit_ws/src/AlterEGO_v2/alterego_description/meshes/common/visual/qb_move_advanced_for_mate.dae</uri>
          </mesh>
        </geometry>
        <material>
          <script>
            <name>Gazebo/Grey</name>
            <uri>file://media/materials/scripts/gazebo.material</uri>
          </script>
        </material>
      </visual>
      <self_collide>1</self_collide>
    </link>
    <joint name='right_forearm_cube_to_right_wrist_flange' type='revolute'>
      <pose relative_to='right_forearm_flange'>-0.1305 0 0 -0 -1.5708 0</pose>
      <parent>right_forearm_flange</parent>
      <child>right_wrist_flange</child>
      <axis>
        <xyz>0 0 1</xyz>
        <limit>
          <lower>-3.14</lower>
          <upper>3.14</upper>
          <effort>1000</effort>
          <velocity>0.5</velocity>
        </limit>
        <dynamics>
          <damping>0.065</damping>
          <friction>0.025</friction>
          <spring_reference>0</spring_reference>
          <spring_stiffness>0</spring_stiffness>
        </dynamics>
      </axis>
    </joint>
    <link name='right_wrist_flange'>
      <pose relative_to='right_forearm_cube_to_right_wrist_flange'>0 0 0 0 -0 0</pose>
      <inertial>
        <pose>-0.001784 -0.006742 0.139677 0 -0 0</pose>
        <mass>0.755533</mass>
        <inertia>
          <ixx>0.00177513</ixx>
          <ixy>-1.01623e-05</ixy>
          <ixz>-5.40013e-05</ixz>
          <iyy>0.00158375</iyy>
          <iyz>4.17867e-06</iyz>
          <izz>0.000536372</izz>
        </inertia>
      </inertial>
      <collision name='right_wrist_flange_collision'>
        <pose>0 0 0 0 -0 0</pose>
        <geometry>
          <mesh>
            <scale>0.001 0.001 0.001</scale>
            <uri>
              /home/cp/iit_ws/src/AlterEGO_v2/alterego_description/meshes/common/collision/la_flg_asm_flat_blu.stl</uri>
          </mesh>
        </geometry>
        <surface>
          <contact>
            <ode />
          </contact>
          <friction>
            <ode />
          </friction>
        </surface>
      </collision>
      <collision name='right_wrist_flange_fixed_joint_lump__right_wrist_collision_1'>
        <pose>-0.0119 0 0.099864 -1.5708 -0 -3.14159</pose>
        <geometry>
          <mesh>
            <scale>0.001 0.001 0.001</scale>
            <uri>
              /home/cp/iit_ws/src/AlterEGO_v2/alterego_description/meshes/alterego_v3/collision/right_wrist_v2_1_urdf.stl</uri>
          </mesh>
        </geometry>
        <surface>
          <contact>
            <ode />
          </contact>
          <friction>
            <ode />
          </friction>
        </surface>
      </collision>
      <visual name='right_wrist_flange_visual'>
        <pose>0 0 0 0 -0 0</pose>
        <geometry>
          <mesh>
            <scale>0.001 0.001 0.001</scale>
            <uri>
              /home/cp/iit_ws/src/AlterEGO_v2/alterego_description/meshes/common/visual/la_flg_asm_flat_blu.dae</uri>
          </mesh>
        </geometry>
        <material>
          <script>
            <name>Gazebo/SkyBlue</name>
            <uri>file://media/materials/scripts/gazebo.material</uri>
          </script>
        </material>
      </visual>
      <visual name='right_wrist_flange_fixed_joint_lump__right_wrist_visual_1'>
        <pose>-0.0119 0 0.099864 -1.5708 -0 -3.14159</pose>
        <geometry>
          <mesh>
            <scale>0.001 0.001 0.001</scale>
            <uri>
              /home/cp/iit_ws/src/AlterEGO_v2/alterego_description/meshes/alterego_v3/visual/right_wrist_v2_1_urdf.dae</uri>
          </mesh>
        </geometry>
        <material>
          <script>
            <name>Gazebo/Grey</name>
            <uri>file://media/materials/scripts/gazebo.material</uri>
          </script>
        </material>
      </visual>
      <self_collide>1</self_collide>
    </link>
    <joint name='right_wrist_to_right_hand' type='revolute'>
      <pose relative_to='right_wrist_flange'>-0.0119 0 0.099864 -1.5708 -0 -3.14159</pose>
      <parent>right_wrist_flange</parent>
      <child>right_hand</child>
      <axis>
        <xyz>0 0 1</xyz>
        <limit>
          <lower>-1.57</lower>
          <upper>1.57</upper>
          <effort>1000</effort>
          <velocity>0.5</velocity>
        </limit>
        <dynamics>
          <spring_reference>0</spring_reference>
          <spring_stiffness>0</spring_stiffness>
        </dynamics>
      </axis>
    </joint>
    <link name='right_hand'>
      <pose relative_to='right_wrist_to_right_hand'>0 0 0 0 -0 0</pose>
      <inertial>
        <pose>0.004174 -0.063138 0.006101 0 -0 0</pose>
        <mass>0.290131</mass>
        <inertia>
          <ixx>0.000563778</ixx>
          <ixy>-2.58914e-05</ixy>
          <ixz>-1.01421e-05</ixz>
          <iyy>0.000149898</iyy>
          <iyz>5.93616e-06</iyz>
          <izz>0.000447698</izz>
        </inertia>
      </inertial>
      <collision name='right_hand_collision'>
        <pose>0 0 0 0 -0 0</pose>
        <geometry>
          <mesh>
            <scale>0.001 0.001 0.001</scale>
            <uri>
              /home/cp/iit_ws/src/AlterEGO_v2/alterego_description/meshes/common/collision/softhand_3_dx_urdf.stl</uri>
          </mesh>
        </geometry>
        <surface>
          <contact>
            <ode />
          </contact>
          <friction>
            <ode />
          </friction>
        </surface>
      </collision>
      <visual name='right_hand_visual'>
        <pose>0 0 0 0 -0 0</pose>
        <geometry>
          <mesh>
            <scale>0.001 0.001 0.001</scale>
            <uri>
              /home/cp/iit_ws/src/AlterEGO_v2/alterego_description/meshes/common/visual/softhand_3_dx_urdf.dae</uri>
          </mesh>
        </geometry>
        <material>
          <script>
            <name>Gazebo/Grey</name>
            <uri>file://media/materials/scripts/gazebo.material</uri>
          </script>
        </material>
      </visual>
      <self_collide>1</self_collide>
    </link>
    <joint name='base_link_to_wheel_L' type='revolute'>
      <pose relative_to='base_link'>0 0.277 0 -1.5708 -1.5708 0</pose>
      <parent>base_link</parent>
      <child>wheel_L</child>
      <axis>
        <xyz>0 0 1</xyz>
        <limit>
          <effort>22</effort>
          <velocity>1e+16</velocity>
          <lower>-1e+16</lower>
          <upper>1e+16</upper>
        </limit>
        <dynamics>
          <damping>5.2</damping>
          <friction>2.17</friction>
          <spring_reference>0</spring_reference>
          <spring_stiffness>0</spring_stiffness>
        </dynamics>
      </axis>
    </joint>
    <link name='wheel_L'>
      <pose relative_to='base_link_to_wheel_L'>0 0 0 0 -0 0</pose>
      <inertial>
        <pose>-1e-06 -2e-06 0.000726 0 -0 0</pose>
        <mass>1.21753</mass>
        <inertia>
          <ixx>0.00497693</ixx>
          <ixy>0</ixy>
          <ixz>0</ixz>
          <iyy>0.00497687</iyy>
          <iyz>0</iyz>
          <izz>0.00885874</izz>
        </inertia>
      </inertial>
      <collision name='wheel_L_collision'>
        <pose>0 0 0 0 -0 0</pose>
        <geometry>
          <cylinder>
            <length>0.07</length>
            <radius>0.13</radius>
          </cylinder>
        </geometry>
        <surface>
          <contact>
            <ode>
              <kp>1e+06</kp>
              <kd>1</kd>
            </ode>
          </contact>
          <friction>
            <ode>
              <mu>1</mu>
              <mu2>1</mu2>
            </ode>
          </friction>
        </surface>
      </collision>
      <visual name='wheel_L_visual'>
        <pose>0 0 0 0 -0 0</pose>
        <geometry>
          <mesh>
            <scale>0.001 0.001 0.001</scale>
            <uri>
              /home/cp/iit_ws/src/AlterEGO_v2/alterego_description/meshes/common/visual/mteg100_varvel_gearbox.dae</uri>
          </mesh>
        </geometry>
        <material>
          <script>
            <name>Gazebo/Grey</name>
            <uri>file://media/materials/scripts/gazebo.material</uri>
          </script>
        </material>
      </visual>
      <self_collide>1</self_collide>
    </link>
    <joint name='base_link_to_wheel_R' type='revolute'>
      <pose relative_to='base_link'>0 -0.277 0 1.5708 -1.5708 0</pose>
      <parent>base_link</parent>
      <child>wheel_R</child>
      <axis>
        <xyz>0 0 1</xyz>
        <limit>
          <effort>22</effort>
          <velocity>1e+16</velocity>
          <lower>-1e+16</lower>
          <upper>1e+16</upper>
        </limit>
        <dynamics>
          <damping>5.2</damping>
          <friction>2.17</friction>
          <spring_reference>0</spring_reference>
          <spring_stiffness>0</spring_stiffness>
        </dynamics>
      </axis>
    </joint>
    <link name='wheel_R'>
      <pose relative_to='base_link_to_wheel_R'>0 0 0 0 -0 0</pose>
      <inertial>
        <pose>-1e-06 -2e-06 0.000726 0 -0 0</pose>
        <mass>1.21753</mass>
        <inertia>
          <ixx>0.00497693</ixx>
          <ixy>0</ixy>
          <ixz>0</ixz>
          <iyy>0.00497687</iyy>
          <iyz>0</iyz>
          <izz>0.00885874</izz>
        </inertia>
      </inertial>
      <collision name='wheel_R_collision'>
        <pose>0 0 0 0 -0 0</pose>
        <geometry>
          <cylinder>
            <length>0.07</length>
            <radius>0.13</radius>
          </cylinder>
        </geometry>
        <surface>
          <contact>
            <ode>
              <kp>1e+06</kp>
              <kd>1</kd>
            </ode>
          </contact>
          <friction>
            <ode>
              <mu>1</mu>
              <mu2>1</mu2>
            </ode>
          </friction>
        </surface>
      </collision>
      <visual name='wheel_R_visual'>
        <pose>0 0 0 0 -0 0</pose>
        <geometry>
          <mesh>
            <scale>0.001 0.001 0.001</scale>
            <uri>
              /home/cp/iit_ws/src/AlterEGO_v2/alterego_description/meshes/common/visual/mteg100_varvel_gearbox.dae</uri>
          </mesh>
        </geometry>
        <material>
          <script>
            <name>Gazebo/Grey</name>
            <uri>file://media/materials/scripts/gazebo.material</uri>
          </script>
        </material>
      </visual>
      <self_collide>1</self_collide>
    </link>
    <plugin name='gazebo_ros_control' filename='libgazebo_ros_control.so'>
      <robotNamespace>/wheels</robotNamespace>
      <robotSimType>gazebo_ros_control/DefaultRobotHWSim</robotSimType>
      <legacyModeNS>1</legacyModeNS>
    </plugin>
    <plugin name='compliant_act_head0' filename='libqbmove_plugin.so'>
      <joint>base_link_to_neck</joint>
      <operation_mode>5</operation_mode>
      <pub_eltau>0</pub_eltau>
      <pub_state>1</pub_state>
      <sub_ext_tau>0</sub_ext_tau>
      <namespace>left</namespace>
      <t_sample>0.01</t_sample>
      <spring_a1>11.0</spring_a1>
      <spring_k1>0.02</spring_k1>
      <spring_a2>11.0</spring_a2>
      <spring_k2>0.02</spring_k2>
      <mot_1_tauMax>12.0</mot_1_tauMax>
      <mot_2_tauMax>12.0</mot_2_tauMax>
    </plugin>
    <plugin name='compliant_act_left_j1' filename='libqbmove_plugin.so'>
      <joint>base_link_to_left_shoulder_flange</joint>
      <operation_mode>5</operation_mode>
      <pub_eltau>0</pub_eltau>
      <pub_state>1</pub_state>
      <sub_ext_tau>0</sub_ext_tau>
      <namespace>left</namespace>
      <t_sample>0.01</t_sample>
      <spring_a1>11.0</spring_a1>
      <spring_k1>0.02</spring_k1>
      <spring_a2>11.0</spring_a2>
      <spring_k2>0.02</spring_k2>
      <mot_1_tauMax>12.0</mot_1_tauMax>
      <mot_2_tauMax>12.0</mot_2_tauMax>
    </plugin>
    <plugin name='compliant_act_left_j2' filename='libqbmove_plugin.so'>
      <joint>left_shoulder_cube_to_left_arm_flange</joint>
      <operation_mode>5</operation_mode>
      <pub_eltau>0</pub_eltau>
      <pub_state>1</pub_state>
      <sub_ext_tau>0</sub_ext_tau>
      <namespace>left</namespace>
      <t_sample>0.01</t_sample>
      <spring_a1>11.0</spring_a1>
      <spring_k1>0.02</spring_k1>
      <spring_a2>11.0</spring_a2>
      <spring_k2>0.02</spring_k2>
      <mot_1_tauMax>12.0</mot_1_tauMax>
      <mot_2_tauMax>12.0</mot_2_tauMax>
    </plugin>
    <plugin name='compliant_act_left_j3' filename='libqbmove_plugin.so'>
      <joint>left_arm_cube_to_left_elbow_flange_sensor</joint>
      <operation_mode>5</operation_mode>
      <pub_eltau>0</pub_eltau>
      <pub_state>1</pub_state>
      <sub_ext_tau>0</sub_ext_tau>
      <namespace>left</namespace>
      <t_sample>0.01</t_sample>
      <spring_a1>11.0</spring_a1>
      <spring_k1>0.02</spring_k1>
      <spring_a2>11.0</spring_a2>
      <spring_k2>0.02</spring_k2>
      <mot_1_tauMax>12.0</mot_1_tauMax>
      <mot_2_tauMax>12.0</mot_2_tauMax>
    </plugin>
    <plugin name='compliant_act_left_j4' filename='libqbmove_plugin.so'>
      <joint>left_elbow_cube_to_left_forearm_flange</joint>
      <operation_mode>5</operation_mode>
      <pub_eltau>0</pub_eltau>
      <pub_state>1</pub_state>
      <sub_ext_tau>0</sub_ext_tau>
      <namespace>left</namespace>
      <t_sample>0.01</t_sample>
      <spring_a1>11.0</spring_a1>
      <spring_k1>0.02</spring_k1>
      <spring_a2>11.0</spring_a2>
      <spring_k2>0.02</spring_k2>
      <mot_1_tauMax>12.0</mot_1_tauMax>
      <mot_2_tauMax>12.0</mot_2_tauMax>
    </plugin>
    <plugin name='compliant_act_left_j5' filename='libqbmove_plugin.so'>
      <joint>left_forearm_cube_to_left_wrist_flange</joint>
      <operation_mode>5</operation_mode>
      <pub_eltau>0</pub_eltau>
      <pub_state>1</pub_state>
      <sub_ext_tau>0</sub_ext_tau>
      <namespace>left</namespace>
      <t_sample>0.01</t_sample>
      <spring_a1>11.0</spring_a1>
      <spring_k1>0.02</spring_k1>
      <spring_a2>11.0</spring_a2>
      <spring_k2>0.02</spring_k2>
      <mot_1_tauMax>12.0</mot_1_tauMax>
      <mot_2_tauMax>12.0</mot_2_tauMax>
    </plugin>
    <plugin name='compliant_act_left_j6' filename='libqbmove_plugin.so'>
      <joint>left_wrist_to_left_hand</joint>
      <operation_mode>5</operation_mode>
      <pub_eltau>0</pub_eltau>
      <pub_state>1</pub_state>
      <sub_ext_tau>0</sub_ext_tau>
      <namespace>left</namespace>
      <t_sample>0.01</t_sample>
      <spring_a1>11.0</spring_a1>
      <spring_k1>0.02</spring_k1>
      <spring_a2>11.0</spring_a2>
      <spring_k2>0.02</spring_k2>
      <mot_1_tauMax>12.0</mot_1_tauMax>
      <mot_2_tauMax>12.0</mot_2_tauMax>
    </plugin>
    <plugin name='compliant_act_head22' filename='libqbmove_plugin.so'>
      <joint>neck_to_neck_cube</joint>
      <operation_mode>5</operation_mode>
      <pub_eltau>0</pub_eltau>
      <pub_state>1</pub_state>
      <sub_ext_tau>0</sub_ext_tau>
      <namespace>right</namespace>
      <t_sample>0.01</t_sample>
      <spring_a1>11.0</spring_a1>
      <spring_k1>0.02</spring_k1>
      <spring_a2>11.0</spring_a2>
      <spring_k2>0.02</spring_k2>
      <mot_1_tauMax>12.0</mot_1_tauMax>
      <mot_2_tauMax>12.0</mot_2_tauMax>
    </plugin>
    <plugin name='compliant_act_right_11' filename='libqbmove_plugin.so'>
      <joint>base_link_to_right_shoulder_flange</joint>
      <operation_mode>5</operation_mode>
      <pub_eltau>0</pub_eltau>
      <pub_state>1</pub_state>
      <sub_ext_tau>0</sub_ext_tau>
      <namespace>right</namespace>
      <t_sample>0.01</t_sample>
      <spring_a1>11.0</spring_a1>
      <spring_k1>0.02</spring_k1>
      <spring_a2>11.0</spring_a2>
      <spring_k2>0.02</spring_k2>
      <mot_1_tauMax>12.0</mot_1_tauMax>
      <mot_2_tauMax>12.0</mot_2_tauMax>
    </plugin>
    <plugin name='compliant_act_right_j12' filename='libqbmove_plugin.so'>
      <joint>right_shoulder_cube_to_right_arm_flange</joint>
      <operation_mode>5</operation_mode>
      <pub_eltau>0</pub_eltau>
      <pub_state>1</pub_state>
      <sub_ext_tau>0</sub_ext_tau>
      <namespace>right</namespace>
      <t_sample>0.01</t_sample>
      <spring_a1>11.0</spring_a1>
      <spring_k1>0.02</spring_k1>
      <spring_a2>11.0</spring_a2>
      <spring_k2>0.02</spring_k2>
      <mot_1_tauMax>12.0</mot_1_tauMax>
      <mot_2_tauMax>12.0</mot_2_tauMax>
    </plugin>
    <plugin name='compliant_act_right_j13' filename='libqbmove_plugin.so'>
      <joint>right_arm_cube_to_right_elbow_flange_sensor</joint>
      <operation_mode>5</operation_mode>
      <pub_eltau>0</pub_eltau>
      <pub_state>1</pub_state>
      <sub_ext_tau>0</sub_ext_tau>
      <namespace>right</namespace>
      <t_sample>0.01</t_sample>
      <spring_a1>11.0</spring_a1>
      <spring_k1>0.02</spring_k1>
      <spring_a2>11.0</spring_a2>
      <spring_k2>0.02</spring_k2>
      <mot_1_tauMax>12.0</mot_1_tauMax>
      <mot_2_tauMax>12.0</mot_2_tauMax>
    </plugin>
    <plugin name='compliant_act_right_j14' filename='libqbmove_plugin.so'>
      <joint>right_elbow_cube_to_right_forearm_flange</joint>
      <operation_mode>5</operation_mode>
      <pub_eltau>0</pub_eltau>
      <pub_state>1</pub_state>
      <sub_ext_tau>0</sub_ext_tau>
      <namespace>right</namespace>
      <t_sample>0.01</t_sample>
      <spring_a1>11.0</spring_a1>
      <spring_k1>0.02</spring_k1>
      <spring_a2>11.0</spring_a2>
      <spring_k2>0.02</spring_k2>
      <mot_1_tauMax>12.0</mot_1_tauMax>
      <mot_2_tauMax>12.0</mot_2_tauMax>
    </plugin>
    <plugin name='compliant_act_right_j15' filename='libqbmove_plugin.so'>
      <joint>right_forearm_cube_to_right_wrist_flange</joint>
      <operation_mode>5</operation_mode>
      <pub_eltau>0</pub_eltau>
      <pub_state>1</pub_state>
      <sub_ext_tau>0</sub_ext_tau>
      <namespace>right</namespace>
      <t_sample>0.01</t_sample>
      <spring_a1>11.0</spring_a1>
      <spring_k1>0.02</spring_k1>
      <spring_a2>11.0</spring_a2>
      <spring_k2>0.02</spring_k2>
      <mot_1_tauMax>12.0</mot_1_tauMax>
      <mot_2_tauMax>12.0</mot_2_tauMax>
    </plugin>
    <static>0</static>
    <plugin name='compliant_act_right_j16' filename='libqbmove_plugin.so'>
      <joint>right_wrist_to_right_hand</joint>
      <operation_mode>5</operation_mode>
      <pub_eltau>0</pub_eltau>
      <pub_state>1</pub_state>
      <sub_ext_tau>0</sub_ext_tau>
      <namespace>right</namespace>
      <t_sample>0.01</t_sample>
      <spring_a1>11.0</spring_a1>
      <spring_k1>0.02</spring_k1>
      <spring_a2>11.0</spring_a2>
      <spring_k2>0.02</spring_k2>
      <mot_1_tauMax>12.0</mot_1_tauMax>
      <mot_2_tauMax>12.0</mot_2_tauMax>
    </plugin>
  </model>
</sdf>