<?xml version="1.0" ?>
<!-- =================================================================================== -->
<!-- |    This document was autogenerated by xacro from ego_robot.urdf.xacro           | -->
<!-- |    EDITING THIS FILE BY HAND IS NOT RECOMMENDED                                 | -->
<!-- =================================================================================== -->
<robot name="my_robot" xmlns:xacro="http://www.ros.org/wiki/xacro">
  <material name="SoftHand/LightGrey">
    <color rgba="0.7 0.7 0.7 1.0"/>
  </material>
  <material name="SoftHand/DarkGrey">
    <color rgba="0.4 0.4 0.4 1.0"/>
  </material>
  <material name="SoftHand/Black">
    <color rgba="0.0 0.0 0.0 1.0"/>
  </material>
  <material name="SoftHand/DarkGolden">
    <color rgba="0.4 0.4 0.3 1.0"/>
  </material>
  <material name="SoftHand/Blue">
    <color rgba="0.0 0.0 0.8 0.9"/>
  </material>
  <material name="SoftHand/LightBlue">
    <color rgba="0.0 0.4 1.0 0.5"/>
  </material>
  <!-- <xacro:insert_block name="gazebo_friction_properties"/> -->
  <!-- <xacro:insert_block name="gazebo_other_properties"/> -->
  <!-- NOTE: inertia values are approximated using meshlab and only using the significant elements -->
  <!-- from http://answers.ros.org/question/11350/is-there-any-way-to-calculate-inertial-property-of-a-robot-to-simulate-it-in-gazebo/s
    One general rule of thumb I use for checking my inertia tensors is: If total mass of the rigid body is m, and the dimension of the corresponding body is d, then check to see if ixx, iyy, izz are near m*(d/2)^2.

    This is by no means correct, but a sanity check to make sure the moment of inertia are the right order of magnitudes, so the model behaves somewhat physically realistically.
    -->
  <material name="red">
    <color rgba="255 0 0 1"/>
  </material>
  <material name="qbmove/flange">
    <color rgba="0.0 0.5 0.8 1.0"/>
  </material>
  <material name="qbmove/cube">
    <color rgba="0.35 0.35 0.35 1.0"/>
  </material>
  <material name="qbmove/shaft">
    <color rgba="0.8 0.8 0.8 1.0"/>
  </material>
  <material name="qbmove/default">
    <color rgba="0.35 0.35 0.35 1.0"/>
  </material>
  <material name="wheel">
    <color rgba="0.50 0.50 0.50 1.0"/>
  </material>
  
  <link name="world"/>
  
  <joint name="world_to_trans_x" type="prismatic">
	  <parent link="world"/>
	  <child link="trans_x"/>
	  <axis xyz="1 0 0"/>
	  <limit lower="-100000" upper="100000" effort="100000" velocity="100000"/>
  </joint>
  <link name="trans_x"/>

  <joint name="trans_x_to_trans_y" type="prismatic">
	  <parent link="trans_x"/>
	  <child link="trans_y"/>
	  <axis xyz="0 1 0"/>
	  <limit lower="-100000" upper="100000" effort="100000" velocity="100000"/>
  </joint>
  <link name="trans_y"/>
  
    <joint name="trans_y_to_fixed_z" type="fixed">
	  <origin rpy="0.0 0.0 0.0" xyz="0 0 0.13"/> 
	  <parent link="trans_y"/>
	  <child link="trans_z"/>
  </joint>-->
  
  <link name="trans_z"/>
  
  <joint name="trans_z_to_rot_z" type="continuous">
	  <parent link="trans_z"/>
	  <child link="rot_z"/>
	  <axis xyz="0 0 1"/>
  </joint>
  <link name="rot_z"/>

  <joint name="rot_z_to_rot_y" type="continuous">
	  <parent link="rot_z"/>
	  <child link="rot_y"/>
	  <axis xyz="0 1 0"/>
  </joint>
  <link name="rot_y"/>


  <joint name="rot_y_base_link" type="fixed">
	  <origin rpy="0.0 0.0 0.0" xyz="0 0 0"/> 
	  <parent link="rot_y"/>
	  <child link="torso"/>
  </joint>-->
  
  <link name="torso">
    <visual>
      <!--<material name="red"/>-->
      <geometry>
        <!--mesh filename="package://ego_description/meshes/Ego_body.stl" scale="0.001 0.001 0.001"/-->
        <box size="0.1 0.1 0.1"/>
      </geometry>
      <origin rpy="1.57075 -1.57075 0" xyz="0 0 0.1"/>
    </visual>
    <inertial>
      <origin rpy="0 0 0" xyz="-4.9e-3 0 0.2871"/>
      <mass value="13.32"/>
      <inertia ixx="1.41" ixy="3.66e-4" ixz="2.21e-2" iyy="1.29" iyz="-9.05e-4" izz="1.7e-1"/>
    </inertial>
    <collision>
      <geometry>
        <box size="0.1 0.1 0.1"/>
      </geometry>
      <origin rpy="1.57075 -1.57075 0" xyz="0 0 0.1"/>
    </collision>
  </link>
  
  <link name="neck">
    <visual>
      <material name="qbmove/flange"/>
      <geometry>
        <mesh filename="package://ego_description/meshes/qb_c_flange.stl" scale="0.001 0.001 0.001"/>
      </geometry>
      <origin rpy="3.14 0 -1.57075" xyz="0 0 0"/>
    </visual>
    <inertial>
      <origin rpy="0 0 0" xyz="0 0 0"/>
      <mass value="1e-7"/>
      <inertia ixx="1e-8" ixy="0" ixz="0" iyy="1e-8" iyz="0" izz="1e-8"/>
    </inertial>
    <collision>
      <origin rpy="0.0 0.0 0.0" xyz="0.0 0.0 0.0"/>
      <geometry>
        <box size="0.07 0.07 0.07"/>
      </geometry>
    </collision>
  </link>
  
  <joint name="base_to_neck" type="fixed">
    <origin rpy="0.0 0.0 0.0" xyz="0 0 0.74"/>
    <parent link="torso"/>
    <child link="neck"/>
  </joint>
  
  <link name="head">
    <visual>
      <material name="qbmove/cube"/>
      <geometry>
        <mesh filename="package://ego_description/meshes/Ego_head.stl" scale="0.001 0.001 0.001"/>
      </geometry>
      <origin rpy="1.57075 -1.57075 0" xyz="0 0 0"/>
    </visual>
    <inertial>
      <origin rpy="0 0 0" xyz="0 0 0"/>
      <mass value="1e-7"/>
      <inertia ixx="1e-8" ixy="0" ixz="0" iyy="1e-8" iyz="0" izz="1e-8"/>
    </inertial>
    <collision>
      <origin rpy="0.0 0.0 0.0" xyz="0.0 0.0 0.0"/>
      <geometry>
        <box size="0.07 0.07 0.07"/>
      </geometry>
    </collision>
  </link>
  
  <joint name="neck_to_head" type="fixed">
    <origin rpy="0.0 0.0 0.0" xyz="0 0 0.058"/>
    <parent link="neck"/>
    <child link="head"/>
  </joint>
  
  <link name="left_shoulder_flange">
    <visual>
      <material name="qbmove/flange"/>
      <geometry>
        <mesh filename="package://ego_description/meshes/qb_flat_flange.stl" scale="0.001 0.001 0.001"/>
      </geometry>
      <origin rpy="0 0 0" xyz="0 0 -0.033"/>
    </visual>
    <inertial>
      <origin rpy="0 0 0" xyz="0 0 0"/>
      <mass value="1e-7"/>
      <inertia ixx="1e-8" ixy="0" ixz="0" iyy="1e-8" iyz="0" izz="1e-8"/>
    </inertial>
  </link>
  
  <link name="left_shoulder_cube">
    <visual>
      <material name="qbmove/cube"/>
      <geometry>
        <mesh filename="package://ego_description/meshes/qbmove_frame.stl" scale="0.001 0.001 0.001"/>
      </geometry>
      <origin rpy="0 1.57075 0" xyz="-0.033 0 0"/>
    </visual>
    <inertial>
      <origin rpy="0 0 0" xyz="0.001336 0 -3.15e-3"/>
      <mass value="0.601"/>
      <inertia ixx="2.24e-4" ixy="0" ixz="0" iyy="2.43e-4" iyz="0" izz="1.98e-4"/>
    </inertial>
    <collision>
      <origin rpy="0.0 0.0 0.0" xyz="0.0 0.0 0.0"/>
      <geometry>
        <box size="0.07 0.07 0.07"/>
      </geometry>
    </collision>
  </link>
  
  <joint name="base_to_left_shoulder" type="revolute">
    <axis xyz="0 0 1"/>
    <limit effort="1000.0" lower="-1.57" upper="1.884" velocity="0.5"/>
    <origin rpy="-1.3951 0.0 -0.1737" xyz="0.025 0.184 0.721"/>
    <parent link="torso"/>
    <child link="left_shoulder_flange"/>
  </joint>
  
  <joint name="left_shoulder_flange_to_cube" type="fixed">
    <parent link="left_shoulder_flange"/>
    <child link="left_shoulder_cube"/>
  </joint>
  
  <link name="left_arm_flange">
    <visual>
      <material name="qbmove/flange"/>
      <geometry>
        <mesh filename="package://ego_description/meshes/qb_c_flange.stl" scale="0.001 0.001 0.001"/>
      </geometry>
      <origin rpy="-1.57075 0 0" xyz="0 0.057 0"/>
    </visual>
    <inertial>
      <origin rpy="0 0 0" xyz="0 0 0"/>
      <mass value="1e-7"/>
      <inertia ixx="1e-8" ixy="0" ixz="0" iyy="1e-8" iyz="0" izz="1e-8"/>
    </inertial>
  </link>
  
  <link name="left_arm_cube">
    <visual>
      <material name="qbmove/cube"/>
      <geometry>
        <mesh filename="package://ego_description/meshes/qbmove_frame.stl" scale="0.001 0.001 0.001"/>
      </geometry>
      <origin rpy="-1.57075 3.14 0" xyz="0 0.057 0"/>
    </visual>
    <visual>
      <geometry>
        <mesh filename="package://ego_description/meshes/qbmove_pulley.stl" scale="0.001 0.001 0.001"/>
      </geometry>
      <origin rpy="0 0 -1.57075" xyz="0.025 -0.0 0"/>
    </visual>
    <inertial>
      <origin rpy="0 0 0" xyz="9.25e-4  0.08266 0 "/>
      <mass value="0.643"/>
      <inertia ixx="5.44e-4" ixy="0" ixz="0" iyy="2.42e-4" iyz="0" izz="6.04e-4"/>
    </inertial>
    <collision>
      <origin rpy="0.0 0 0.0" xyz="0.0 0.09 0.0"/>
      <geometry>
        <box size="0.07 0.07 0.07"/>
      </geometry>
    </collision>
  </link>
  
  <joint name="shoulder_to_left_arm" type="revolute">
    <axis xyz="1 0 0"/>
    <limit effort="1000.0" lower="-0.174" upper="3.14" velocity="0.5"/>
    <origin rpy="0 0.0 0" xyz="0.0 0 0"/>
    <parent link="left_shoulder_cube"/>
    <child link="left_arm_flange"/>
  </joint>
  <joint name="left_arm_flange_to_cube" type="fixed">
    <parent link="left_arm_flange"/>
    <child link="left_arm_cube"/>
  </joint>
  <link name="left_elbow_flange">
    <visual>
      <material name="qbmove/flange"/>
      <geometry>
        <mesh filename="package://ego_description/meshes/qb_flat_flange.stl" scale="0.001 0.001 0.001"/>
      </geometry>
      <origin rpy="-1.57075 1.57075 0" xyz="0 -0.033 0"/>
    </visual>
    <inertial>
      <origin rpy="0 0 0" xyz="0 0 0"/>
      <mass value="1e-7"/>
      <inertia ixx="1e-8" ixy="0" ixz="0" iyy="1e-8" iyz="0" izz="1e-8"/>
    </inertial>
  </link>
  
  <link name="left_elbow_cube">
    <visual>
      <material name="qbmove/cube"/>
      <geometry>
        <mesh filename="package://ego_description/meshes/qbmove_frame.stl" scale="0.001 0.001 0.001"/>
      </geometry>
      <origin rpy="0 0 3.14" xyz="0 0 -0.033"/>
    </visual>
    <visual>
      <geometry>
        <mesh filename="package://ego_description/meshes/qbmove_pulley.stl" scale="0.001 0.001 0.001"/>
      </geometry>
      <origin rpy="0 0 0.0" xyz="0 -0.053 0"/>
    </visual>
    <inertial>
      <origin rpy="0 0 0" xyz="0  -0.0025 1.36e-3 "/>
      <mass value="0.591"/>
      <inertia ixx="2.25e-4" ixy="0" ixz="0" iyy="1.92e-4" iyz="0" izz="2.00e-4"/>
    </inertial>
    <collision>
      <origin rpy="0.0 0.0 0.0" xyz="0.0 0.0 0.0"/>
      <geometry>
        <box size="0.07 0.07 0.07"/>
      </geometry>
    </collision>
  </link>
  
  <joint name="arm_to_left_elbow" type="revolute">
    <axis xyz="0 1 0"/>
    <limit effort="1000.0" lower="-3.14" upper="3.14" velocity="0.5"/>
    <origin rpy="0.0 0.0 0.0" xyz="0.0 0.168 0.0"/>
    <parent link="left_arm_cube"/>
    <child link="left_elbow_flange"/>
  </joint>
  <joint name="left_elbow_flange_to_cube" type="fixed">
    <parent link="left_elbow_flange"/>
    <child link="left_elbow_cube"/>
  </joint>
  
  <link name="left_forearm_flange">
    <visual>
      <material name="qbmove/flange"/>
      <geometry>
        <mesh filename="package://ego_description/meshes/qb_c_flange.stl" scale="0.001 0.001 0.001"/>
      </geometry>
      <origin rpy="-1.57075 -1.57075 0" xyz="0 0.057 0"/>
    </visual>
    <inertial>
      <origin rpy="0 0 0" xyz="0 0 0"/>
      <mass value="1e-7"/>
      <inertia ixx="1e-8" ixy="0" ixz="0" iyy="1e-8" iyz="0" izz="1e-8"/>
    </inertial>
  </link>
  
  <link name="left_forearm_cube">
    <visual>
      <material name="qbmove/cube"/>
      <geometry>
        <mesh filename="package://ego_description/meshes/qbmove_frame.stl" scale="0.001 0.001 0.001"/>
      </geometry>
      <origin rpy="-1.57075 3.14 0" xyz="0 0.057 0"/>
    </visual>
    <visual>
      <geometry>
        <mesh filename="package://ego_description/meshes/qbmove_pulley.stl" scale="0.001 0.001 0.001"/>
      </geometry>
      <origin rpy="1.57075 0 0" xyz="0 0 0.025"/>
    </visual>
    <inertial>
      <origin rpy="0 0 0" xyz="0  0.07663 -1.78e-3 "/>
      <mass value="0.353"/>
      <inertia ixx="5.4e-4" ixy="0" ixz="0" iyy="2.06e-4" iyz="0" izz="4.82e-4"/>
    </inertial>
    <collision>
      <origin rpy="0.0 0.0 0.0" xyz="0.0 0.09 0.0"/>
      <geometry>
        <box size="0.07 0.07 0.07"/>
      </geometry>
    </collision>
  </link>
  
  <joint name="elbow_to_left_forearm" type="revolute">
    <axis xyz="0 0 1"/>
    <limit effort="1000.0" lower="-1.57" upper="1.57" velocity="0.5"/>
    <origin rpy="0 0.0 0" xyz="0.0 0 0"/>
    <parent link="left_elbow_cube"/>
    <child link="left_forearm_flange"/>
  </joint>
  <joint name="left_forearm_flange_to_cube" type="fixed">
    <parent link="left_forearm_flange"/>
    <child link="left_forearm_cube"/>
  </joint>
  
  <link name="left_EE">
    <visual>
      <material name="qbmove/flange"/>
      <geometry>
        <mesh filename="package://ego_description/meshes/qb_flat_flange.stl" scale="0.001 0.001 0.001"/>
      </geometry>
      <origin rpy="-1.57075 1.57075 0" xyz="0 -0.033 0"/>
    </visual>
    <inertial>
      <origin rpy="0 0 0" xyz="4.62e-3 0.062 -4.88e-3"/>
      <mass value="0.381"/>
      <inertia ixx="1.173e-3" ixy="0" ixz="0" iyy="2.83e-4" iyz="0" izz="1.33e-3"/>
    </inertial>
  </link>
  
  <joint name="forearm_to_left_EE" type="revolute">
    <axis xyz="0 1 0"/>
    <limit effort="1000.0" lower="-3.14" upper="3.14" velocity="0.5"/>
    <origin rpy="0.0 0.0 0.0" xyz="0.0 0.168 0.0"/>
    <parent link="left_forearm_cube"/>
    <child link="left_EE"/>
  </joint>
 
  
  <link name="right_shoulder_flange">
    <visual>
      <material name="qbmove/flange"/>
      <geometry>
        <mesh filename="package://ego_description/meshes/qb_flat_flange.stl" scale="0.001 0.001 0.001"/>
      </geometry>
      <origin rpy="0 0 0" xyz="0 0 -0.033"/>
    </visual>
    <inertial>
      <origin rpy="0 0 0" xyz="0 0 0"/>
      <mass value="1e-7"/>
      <inertia ixx="1e-8" ixy="0" ixz="0" iyy="1e-8" iyz="0" izz="1e-8"/>
    </inertial>
  </link>
  
  <link name="right_shoulder_cube">
    <visual>
      <material name="qbmove/cube"/>
      <geometry>
        <mesh filename="package://ego_description/meshes/qbmove_frame.stl" scale="0.001 0.001 0.001"/>
      </geometry>
      <origin rpy="0 1.57075 0" xyz="-0.033 0 0"/>
    </visual>
    <inertial>
      <origin rpy="0 0 0" xyz="-0.001336 0 -3.15e-3"/>
      <mass value="0.601"/>
      <inertia ixx="2.24e-4" ixy="0" ixz="0" iyy="2.43e-4" iyz="0" izz="1.98e-4"/>
    </inertial>
    <collision>
      <origin rpy="0.0 0.0 0.0" xyz="0.0 0.0 0.0"/>
      <geometry>
        <box size="0.07 0.07 0.07"/>
      </geometry>
    </collision>
  </link>
  
  <joint name="base_to_right_shoulder" type="revolute">
    <axis xyz="0 0 1"/>
    <limit effort="1000.0" lower="-1.57" upper="1.884"  velocity="0.5"/>
    <origin rpy="1.3951 0.0 0.1737" xyz="0.025 -0.184 0.721"/>
    <parent link="torso"/>
    <child link="right_shoulder_flange"/>
  </joint>
  <joint name="right_shoulder_flange_to_cube" type="fixed">
    <parent link="right_shoulder_flange"/>
    <child link="right_shoulder_cube"/>
  </joint>
  
  <link name="right_arm_flange">
    <visual>
      <material name="qbmove/flange"/>
      <geometry>
        <mesh filename="package://ego_description/meshes/qb_c_flange.stl" scale="0.001 0.001 0.001"/>
      </geometry>
      <origin rpy="1.57075 0 0" xyz="0 -0.057 0"/>
    </visual>
    <inertial>
      <origin rpy="0 0 0" xyz="0 0 0"/>
      <mass value="1e-7"/>
      <inertia ixx="1e-8" ixy="0" ixz="0" iyy="1e-8" iyz="0" izz="1e-8"/>
    </inertial>
  </link>
  
  <link name="right_arm_cube">
    <visual>
      <material name="qbmove/cube"/>
      <geometry>
        <mesh filename="package://ego_description/meshes/qbmove_frame.stl" scale="0.001 0.001 0.001"/>
      </geometry>
      <origin rpy="1.57075 3.14 0" xyz="0 -0.057 0"/>
    </visual>
    <visual>
      <geometry>
        <mesh filename="package://ego_description/meshes/qbmove_pulley.stl" scale="0.001 0.001 0.001"/>
      </geometry>
      <origin rpy="0 0 -1.57075" xyz="0.025 0.0 0"/>
    </visual>
    <inertial>
      <origin rpy="0 0 0" xyz="9.25e-4  -0.08266 0 "/>
      <mass value="0.643"/>
      <inertia ixx="5.44e-4" ixy="0" ixz="0" iyy="2.42e-4" iyz="0" izz="6.04e-4"/>
    </inertial>
    <collision>
      <origin rpy="0.0 0 0.0" xyz="0.0 -0.09 0.0"/>
      <geometry>
        <box size="0.07 0.07 0.07"/>
      </geometry>
    </collision>
  </link>
  
  <joint name="shoulder_to_right_arm" type="revolute">
    <axis xyz="1 0 0"/>
    <limit effort="1000.0" lower="-3.14" upper="0.174" velocity="0.5"/>
    <origin rpy="0 0.0 0" xyz="0.0 0 0"/>
    <parent link="right_shoulder_cube"/>
    <child link="right_arm_flange"/>
  </joint>
  <joint name="right_arm_flange_to_cube" type="fixed">
    <parent link="right_arm_flange"/>
    <child link="right_arm_cube"/>
  </joint>
  <link name="right_elbow_flange">
    <visual>
      <material name="qbmove/flange"/>
      <geometry>
        <mesh filename="package://ego_description/meshes/qb_flat_flange.stl" scale="0.001 0.001 0.001"/>
      </geometry>
      <origin rpy="1.57075 1.57075 0" xyz="0 0.033 0"/>
    </visual>
    <inertial>
      <origin rpy="0 0 0" xyz="0 0 0"/>
      <mass value="1e-7"/>
      <inertia ixx="1e-8" ixy="0" ixz="0" iyy="1e-8" iyz="0" izz="1e-8"/>
    </inertial>
  </link>
  
  <link name="right_elbow_cube">
    <visual>
      <material name="qbmove/cube"/>
      <geometry>
        <mesh filename="package://ego_description/meshes/qbmove_frame.stl" scale="0.001 0.001 0.001"/>
      </geometry>
      <origin rpy="0 0 3.14" xyz="0 0 -0.033"/>
    </visual>
    <visual>
      <geometry>
        <mesh filename="package://ego_description/meshes/qbmove_pulley.stl" scale="0.001 0.001 0.001"/>
      </geometry>
      <origin rpy="0 0 3.14" xyz="0 0.053 0"/>
    </visual>
    <inertial>
      <origin rpy="0 0 0" xyz="0  0.0025 1.36e-3 "/>
      <mass value="0.591"/>
      <inertia ixx="2.25e-4" ixy="0" ixz="0" iyy="1.92e-4" iyz="0" izz="2.00e-4"/>
    </inertial>
    <collision>
      <origin rpy="0.0 0.0 0.0" xyz="0.0 0.0 0.0"/>
      <geometry>
        <box size="0.07 0.07 0.07"/>
      </geometry>
    </collision>
  </link>
  
  <joint name="arm_to_right_elbow" type="revolute">
    <axis xyz="0 1 0"/>
    <limit effort="1000.0" lower="-3.14" upper="3.14" velocity="0.5"/>
    <origin rpy="0.0 0.0 0.0" xyz="0.0 -0.168 0.0"/>
    <parent link="right_arm_cube"/>
    <child link="right_elbow_flange"/>
  </joint>
  <joint name="right_elbow_flange_to_cube" type="fixed">
    <parent link="right_elbow_flange"/>
    <child link="right_elbow_cube"/>
  </joint>
  <link name="right_forearm_flange">
    <visual>
      <material name="qbmove/flange"/>
      <geometry>
        <mesh filename="package://ego_description/meshes/qb_c_flange.stl" scale="0.001 0.001 0.001"/>
      </geometry>
      <origin rpy="1.57075 -1.57075 0" xyz="0 -0.057 0"/>
    </visual>
    <inertial>
      <origin rpy="0 0 0" xyz="0 0 0"/>
      <mass value="1e-7"/>
      <inertia ixx="1e-8" ixy="0" ixz="0" iyy="1e-8" iyz="0" izz="1e-8"/>
    </inertial>
  </link>
  
  <link name="right_forearm_cube">
    <visual>
      <material name="qbmove/cube"/>
      <geometry>
        <mesh filename="package://ego_description/meshes/qbmove_frame.stl" scale="0.001 0.001 0.001"/>
      </geometry>
      <origin rpy="1.57075 3.14 0" xyz="0 -0.057 0"/>
    </visual>
    <visual>
      <geometry>
        <mesh filename="package://ego_description/meshes/qbmove_pulley.stl" scale="0.001 0.001 0.001"/>
      </geometry>
      <origin rpy="1.57075 0 0" xyz="0 0 0.025"/>
    </visual>
    <inertial>
      <origin rpy="0 0 0" xyz="0  -0.07663 -1.78e-3 "/>
      <mass value="0.353"/>
      <inertia ixx="5.4e-4" ixy="0" ixz="0" iyy="2.06e-4" iyz="0" izz="4.82e-4"/>
    </inertial>
    <collision>
      <origin rpy="0.0 0.0 0.0" xyz="0.0 -0.09 0.0"/>
      <geometry>
        <box size="0.07 0.07 0.07"/>
      </geometry>
    </collision>
  </link>
  
  <joint name="elbow_to_right_forearm" type="revolute">
    <axis xyz="0 0 1"/>
    <limit effort="1000.0" lower="-1.57" upper="1.57" velocity="0.5"/>
    <origin rpy="0 0.0 0" xyz="0.0 0 0"/>
    <parent link="right_elbow_cube"/>
    <child link="right_forearm_flange"/>
  </joint>
  <joint name="right_forearm_flange_to_cube" type="fixed">
    <parent link="right_forearm_flange"/>
    <child link="right_forearm_cube"/>
  </joint>
  <link name="right_EE">
    <visual>
      <material name="qbmove/flange"/>
      <geometry>
        <mesh filename="package://ego_description/meshes/qb_flat_flange.stl" scale="0.001 0.001 0.001"/>
      </geometry>
      <origin rpy="1.57075 1.57075 0" xyz="0 0.033 0"/>
    </visual>
    <inertial>
      <origin rpy="0 0 0" xyz="4.62e-3 -0.062 -4.88e-3"/>
      <mass value="0.381"/>
      <inertia ixx="1.173e-3" ixy="0" ixz="0" iyy="2.83e-4" iyz="0" izz="1.33e-3"/>
    </inertial>
  </link>
  
  <joint name="forearm_to_right_EE" type="revolute">
    <axis xyz="0 1 0"/>
    <limit effort="1000.0" lower="-3.14" upper="3.14" velocity="0.5"/>
    <origin rpy="0.0 0.0 0.0" xyz="0.0 -0.168 0.0"/>
    <parent link="right_forearm_cube"/>
    <child link="right_EE"/>
  </joint>
  
 
  <!-- Ego Left Wheel-->
  <link name="wheel_L">
    <visual>
      <material name="wheel"/>
      <geometry>
        <!--<cylinder  length="0.1" radius="0.13"/>-->
        <mesh filename="package://ego_description/meshes/Ego_wheel.stl" scale="0.001 0.001 0.001"/>
      </geometry>
      <origin rpy="1.57075 0 0" xyz="0 0 0"/>
    </visual>
    <inertial>
      <origin rpy="0 0 0" xyz="0 0 0"/>
      <mass value="1.22"/>
      <inertia ixx="3.21e-3" ixy="0" ixz="0" iyy="5.31e-3" iyz="0" izz="3.21e-3"/>
    </inertial>
    <collision>
      <geometry>
        <cylinder length="0.1" radius="0.13"/>
      </geometry>
      <origin rpy="1.57075 0 0" xyz="0 0 0"/>
    </collision>
  </link>
  <joint name="L_joint_baseW" type="continuous">
    <axis xyz="0 1 0"/>
    <origin rpy="0.0 0.0 0.0" xyz="0.0 0.248 0"/>
    <parent link="torso"/>
    <child link="wheel_L"/>
  </joint>
  <!-- Ego Right Wheel-->
  <link name="wheel_R">
    <visual>
      <material name="wheel"/>
      <geometry>
        <!--<cylinder  length="0.1" radius="0.13"/>-->
        <mesh filename="package://ego_description/meshes/Ego_wheel.stl" scale="0.001 0.001 0.001"/>
      </geometry>
      <origin rpy="1.57075 0 0" xyz="0 0 0"/>
    </visual>
    <inertial>
      <origin rpy="0 0 0" xyz="0 0 0"/>
      <mass value="1.22"/>
      <inertia ixx="3.21e-3" ixy="0" ixz="0" iyy="5.31e-3" iyz="0" izz="3.21e-3"/>
    </inertial>
    <collision>
      <geometry>
        <cylinder length="0.1" radius="0.13"/>
      </geometry>
      <origin rpy="1.57075 0 0" xyz="0 0 0"/>
    </collision>
  </link>
  <joint name="R_joint_baseW" type="continuous">
    <axis xyz="0 1 0"/>
    <origin rpy="0.0 0.0 0.0" xyz="0.0 -0.248 0"/>
    <parent link="torso"/>
    <child link="wheel_R"/>
  </joint>
</robot>
