<?xml version="1.0" ?>
<!-- =================================================================================== -->
<!-- |    This document was autogenerated by xacro from ego_robot_gazebo_v3.urdf.xacro | -->
<!-- |    EDITING THIS FILE BY HAND IS NOT RECOMMENDED                                 | -->
<!-- =================================================================================== -->
<robot name="ego_robot">
  <material name="qbmove/flange">
    <color rgba="0.0 0.5 0.8 1.0"/>
  </material>
  <material name="qbmove/cube">
    <color rgba="0.35 0.35 0.35 1.0"/>
  </material>
  <material name="qbmove/shaft">
    <color rgba="0.8 0.8 0.8 1.0"/>
  </material>
  <material name="qbmove/default">
    <color rgba="0.35 0.35 0.35 1.0"/>
  </material>
  <material name="SoftBlue">
    <color rgba="0.0 0.0 0.8 0.9"/>
  </material>
  <material name="SoftLightBlue">
    <color rgba="0.0 0.4 1.0 1.0"/>
  </material>
  <material name="wheel">
    <color rgba="0.50 0.50 0.50 1.0"/>
  </material>
  <!-- IMU : -->
  <joint name="base_to_imu" type="fixed">
    <origin rpy="0 0 0" xyz="0 102.5e-3 24.25e-3"/>
    <parent link="base"/>
    <child link="imu"/>
  </joint>
  <link name="imu">
    <visual>
      <material name="qbmove/cube"/>
      <geometry>
        <mesh filename="package://alterego_robot/alterego_description/meshes/common/visual/mc_seg_imu_supp_1_100.dae" scale="0.001 0.001 0.001"/>
      </geometry>
      <origin rpy="0 0 0" xyz="0 0 0"/>
    </visual>
    <inertial>
      <origin rpy="0 0 0" xyz="7.5000002e-3 -2.4329396e-4  5.0246414e-4"/>
      <mass value="2.3770213e-3"/>
      <inertia ixx="0" ixy="0" ixz="0" iyy="0" iyz="0" izz="0"/>
    </inertial>
    <collision>
      <origin rpy="0 0 0" xyz="0 0 0"/>
      <geometry>
        <mesh filename="package://alterego_robot/alterego_description/meshes/common/collision/mc_seg_imu_supp_1_100.stl" scale="0.001 0.001 0.001"/>
      </geometry>
    </collision>
  </link>
  <!-- LASER : -->
  <joint name="base_to_laser" type="fixed">
    <origin rpy="0 0 -1.5707963" xyz="0 0 116e-3 "/>
    <parent link="base"/>
    <child link="laser"/>
  </joint>
  <link name="laser">
    <visual>
      <material name="qbmove/cube"/>
      <geometry>
        <mesh filename="package://alterego_robot/alterego_description/meshes/common/visual/rplidar_a2_slamtec.dae" scale="0.001 0.001 0.001"/>
      </geometry>
      <origin rpy="0 0 0" xyz="0 0 0"/>
    </visual>
    <inertial>
      <origin rpy="0 0 0" xyz=" -4.3709710e-4 0   1.8991442e-2"/>
      <mass value="2.0002622e-1"/>
      <inertia ixx=" 9.1569570e-5" ixy="0" ixz="0" iyy="9.0192290e-5" iyz="0" izz="1.2956170e-4"/>
    </inertial>
    <collision>
      <origin rpy="0 0 0" xyz="0 0 0"/>
      <geometry>
        <mesh filename="package://alterego_robot/alterego_description/meshes/common/collision/rplidar_a2_slamtec.stl" scale="0.001 0.001 0.001"/>
      </geometry>
    </collision>
  </link>
  <gazebo reference="laser">
    <material>Gazebo/Black</material>
  </gazebo>
  <!-- ZED : -->
  <joint name="head_to_camera" type="fixed">
    <origin rpy="-1.5707963 0 2.3561944" xyz="-87.9065e-3 21.6811e-3 -6.5e-3"/>
    <parent link="head"/>
    <child link="camera"/>
  </joint>
  <link name="camera">
    <visual>
      <material name="qbmove/cube"/>
      <geometry>
        <mesh filename="package://alterego_robot/alterego_description/meshes/common/visual/zedm.dae" scale="0.001 0.001 0.001"/>
      </geometry>
      <origin rpy="0 0 0" xyz="0 0 0"/>
    </visual>
    <inertial>
      <origin rpy="0 0 0" xyz=" -1.7967264e-2  8.9226986e-4  7.6630930e-6"/>
      <mass value="5.8888131e-2"/>
      <inertia ixx=" 0" ixy="0" ixz="0" iyy="0" iyz="0" izz="0"/>
    </inertial>
    <collision>
      <origin rpy="0 0 0" xyz="0 0 0"/>
      <geometry>
        <mesh filename="package://alterego_robot/alterego_description/meshes/common/collision/zedm.stl" scale="0.001 0.001 0.001"/>
      </geometry>
    </collision>
  </link>
  <!-- FRAME FOR PLUGIN  -->
  <!-- LEFT  -->
  <joint name="camera_to_left" type="fixed">
    <origin rpy="0 0 0" xyz="0 0.025 0"/>
    <parent link="camera"/>
    <child link="camera_left"/>
  </joint>
  <link name="camera_left"/>
  <!-- FRAME FOR PLUGIN  -->
  <!-- RIGHT  -->
  <joint name="camera_to_right" type="fixed">
    <origin rpy="0 0 0" xyz="0 -0.036 0"/>
    <parent link="camera"/>
    <child link="camera_right"/>
  </joint>
  <link name="camera_right"/>
  <!-- IMU : -->
  <joint name="head_to_realsense" type="fixed">
    <origin rpy="-1.5707963 0 2.3561944" xyz="-65.6725e-3 38.7425e-3 0"/>
    <parent link="head"/>
    <child link="realsense"/>
  </joint>
  <link name="realsense">
    <visual>
      <material name="qbmove/cube"/>
      <geometry>
        <mesh filename="package://alterego_robot/alterego_description/meshes/common/visual/intel_realsense_d415_old_asm.dae" scale="0.001 0.001 0.001"/>
      </geometry>
      <origin rpy="1.57 0 1.57" xyz="0 0 0"/>
    </visual>
    <inertial>
      <origin rpy="0 0 0" xyz=" 2.8406417e-3  -1.0608066e-4  -1.1037173e-2"/>
      <mass value="5.6999990e-2"/>
      <inertia ixx=" 0" ixy="0" ixz="0" iyy="0" iyz="0" izz="0"/>
    </inertial>
    <collision>
      <origin rpy="1.57 0 1.57" xyz="0 0 0"/>
      <geometry>
        <mesh filename="package://alterego_robot/alterego_description/meshes/common/collision/intel_realsense_d415_old_asm.stl" scale="0.001 0.001 0.001"/>
      </geometry>
    </collision>
  </link>
  <gazebo reference="realsense">
    <material>Gazebo/Black</material>
  </gazebo>
  <link name="fake_realsense">
    <inertial>
      <origin rpy="0 0 0" xyz=" 2.8406417e-5  -1.0608066e-7  -1.1037173e-5"/>
      <mass value="5.6999990e-4"/>
      <inertia ixx=" 0" ixy="0" ixz="0" iyy="0" iyz="0" izz="0"/>
    </inertial>
  </link>
  <joint name="depth_to_fakelink" type="fixed">
    <!-- <origin xyz="83e-3 -0.5e-3  1006.5e-3" rpy="-1.57 0 -1.57" /> -->
    <origin rpy="-1.57 0 -1.57" xyz="0 0 0"/>
    <parent link="realsense"/>
    <child link="fake_realsense"/>
  </joint>
  <!-- <xacro:include filename="$(find realsense2_description)/urdf/_d435.urdf.xacro" />
  <xacro:sensor_d435 name="d435" topics_ns="realsense" parent="realsense_link"
    publish_pointcloud="true">
    <origin xyz="0 0 0" rpy="1.57 -1.57 0" />
  </xacro:sensor_d435> -->
  <!-- JOINT -->
  <joint name="base_to_wheel_L" type="continuous">
    <axis xyz="0 0 1"/>
    <limit effort="22" velocity="1e16"/>
    <dynamics damping="5.2" friction="2.17"/>
    <origin rpy="0 -1.5707963 -1.5707963" xyz="0 277e-3 0"/>
    <parent link="base"/>
    <child link="wheel_L"/>
  </joint>
  <!-- LINK -->
  <link name="wheel_L">
    <visual>
      <material name="wheel"/>
      <geometry>
        <mesh filename="package://alterego_robot/alterego_description/meshes/common/visual/mteg100_varvel_gearbox.dae" scale="0.001 0.001 0.001"/>
      </geometry>
      <origin rpy="0 0 0" xyz="0 0 0"/>
    </visual>
    <inertial>
      <origin rpy="0 0 0" xyz="-9.3352926e-7 -1.6320810e-6 7.2612692e-4"/>
      <mass value="1.2175322"/>
      <inertia ixx="4.9769349e-3" ixy="0" ixz="0" iyy="4.9768680e-3" iyz="0" izz="8.8587376e-3"/>
    </inertial>
    <collision>
      <geometry>
        <cylinder length="0.07" radius="0.13"/>
      </geometry>
      <origin rpy="0 0 0" xyz="0 0 0"/>
    </collision>
  </link>
  <!-- GAZEBO REFERENCE -->
  <gazebo reference="wheel_L">
    <material>Gazebo/Grey</material>
    <selfCollide>false</selfCollide>
    <mu1 value="1.0"/>
    <mu2 value="1.0"/>
    <kp value="1e6"/>
    <kd value="1.0"/>
  </gazebo>
  <!-- JOINT -->
  <joint name="base_to_wheel_R" type="continuous">
    <axis xyz="0 0 1"/>
    <limit effort="22" velocity="1e16"/>
    <dynamics damping="5.2" friction="2.17"/>
    <origin rpy="0 -1.5707963 1.5707963" xyz="0 -277e-3 0"/>
    <parent link="base"/>
    <child link="wheel_R"/>
  </joint>
  <!-- LINK -->
  <link name="wheel_R">
    <visual>
      <material name="wheel"/>
      <geometry>
        <mesh filename="package://alterego_robot/alterego_description/meshes/common/visual/mteg100_varvel_gearbox.dae" scale="0.001 0.001 0.001"/>
      </geometry>
      <origin rpy="0 0 0" xyz="0 0 0"/>
    </visual>
    <inertial>
      <origin rpy="0 0 0" xyz="-9.3352926e-7 -1.6320810e-6 7.2612692e-4"/>
      <mass value="1.2175322"/>
      <inertia ixx="4.9769349e-3" ixy="0" ixz="0" iyy="4.9768680e-3" iyz="0" izz="8.8587376e-3"/>
    </inertial>
    <collision>
      <geometry>
        <cylinder length="0.07" radius="0.13"/>
      </geometry>
      <origin rpy="0 0 0" xyz="0 0 0"/>
    </collision>
  </link>
  <!-- GAZEBO REFERENCE -->
  <gazebo reference="wheel_R">
    <material>Gazebo/Grey</material>
    <selfCollide>false</selfCollide>
    <mu1 value="1.0"/>
    <mu2 value="1.0"/>
    <kp value="1e6"/>
    <kd value="1.0"/>
  </gazebo>
  <!-- Plugins  -->
  <gazebo>
    <plugin filename="libgazebo_ros_control.so" name="gazebo_ros_control">
      <robotNamespace>/wheels</robotNamespace>
      <robotSimType>gazebo_ros_control/DefaultRobotHWSim</robotSimType>
      <legacyModeNS>true</legacyModeNS>
    </plugin>
  </gazebo>
  <!--Trasmission-->
  <transmission name="tran1">
    <type>transmission_interface/SimpleTransmission</type>
    <joint name="base_to_wheel_L">
      <hardwareInterface>hardware_interface/EffortJointInterface</hardwareInterface>
    </joint>
    <actuator name="L_wheel_motor">
      <hardwareInterface>EffortJointInterface</hardwareInterface>
      <mechanicalReduction>1</mechanicalReduction>
    </actuator>
  </transmission>
  <transmission name="tran2">
    <type>transmission_interface/SimpleTransmission</type>
    <joint name="base_to_wheel_R">
      <hardwareInterface>hardware_interface/EffortJointInterface</hardwareInterface>
    </joint>
    <actuator name="R_wheel_motor">
      <hardwareInterface>EffortJointInterface</hardwareInterface>
      <mechanicalReduction>1</mechanicalReduction>
    </actuator>
  </transmission>
  <!-- Left Arm Actuator-->
  <!-- CUBE 21 -->
  <gazebo>
    <plugin filename="libqbmove_plugin.so" name="compliant_act_head0">
      <joint>base_to_neck</joint>
      <operation_mode>5</operation_mode>
      <pub_eltau>false</pub_eltau>
      <pub_state>true</pub_state>
      <sub_ext_tau>false</sub_ext_tau>
      <namespace>left</namespace>
      <t_sample>0.01</t_sample>
      <spring_a1>11.0 </spring_a1>
      <spring_k1>0.02</spring_k1>
      <spring_a2>11.0</spring_a2>
      <spring_k2>0.02</spring_k2>
      <mot_1_tauMax>12.0</mot_1_tauMax>
      <mot_2_tauMax>12.0</mot_2_tauMax>
    </plugin>
  </gazebo>
  <!-- CUBE 1 -->
  <gazebo>
    <plugin filename="libqbmove_plugin.so" name="compliant_act_left_j1">
      <joint>base_to_left_shoulder_flange</joint>
      <operation_mode>1</operation_mode>
      <pub_eltau>false</pub_eltau>
      <pub_state>true</pub_state>
      <sub_ext_tau>false</sub_ext_tau>
      <namespace>left</namespace>
      <t_sample>0.01</t_sample>
      <spring_a1>11.0 </spring_a1>
      <spring_k1>0.02</spring_k1>
      <spring_a2>11.0</spring_a2>
      <spring_k2>0.02</spring_k2>
      <mot_1_tauMax>12.0</mot_1_tauMax>
      <mot_2_tauMax>12.0</mot_2_tauMax>
    </plugin>
  </gazebo>
  <!-- CUBE 2 -->
  <gazebo>
    <plugin filename="libqbmove_plugin.so" name="compliant_act_left_j2">
      <joint>left_shoulder_cube_to_left_arm_flange</joint>
      <operation_mode>5</operation_mode>
      <pub_eltau>false</pub_eltau>
      <pub_state>true</pub_state>
      <sub_ext_tau>false</sub_ext_tau>
      <namespace>left</namespace>
      <t_sample>0.01</t_sample>
      <spring_a1>11.0 </spring_a1>
      <spring_k1>0.02</spring_k1>
      <spring_a2>11.0</spring_a2>
      <spring_k2>0.02</spring_k2>
      <mot_1_tauMax>12.0</mot_1_tauMax>
      <mot_2_tauMax>12.0</mot_2_tauMax>
    </plugin>
  </gazebo>
  <!-- CUBE 3 -->
  <gazebo>
    <plugin filename="libqbmove_plugin.so" name="compliant_act_left_j3">
      <joint>left_arm_cube_to_left_elbow_flange_sensor</joint>
      <operation_mode>5</operation_mode>
      <pub_eltau>false</pub_eltau>
      <pub_state>true</pub_state>
      <sub_ext_tau>false</sub_ext_tau>
      <namespace>left</namespace>
      <t_sample>0.01</t_sample>
      <spring_a1>11.0 </spring_a1>
      <spring_k1>0.02</spring_k1>
      <spring_a2>11.0</spring_a2>
      <spring_k2>0.02</spring_k2>
      <mot_1_tauMax>12.0</mot_1_tauMax>
      <mot_2_tauMax>12.0</mot_2_tauMax>
    </plugin>
  </gazebo>
  <!-- CUBE 4 -->
  <gazebo>
    <plugin filename="libqbmove_plugin.so" name="compliant_act_left_j4">
      <joint>left_elbow_cube_to_left_forearm_flange</joint>
      <operation_mode>5</operation_mode>
      <pub_eltau>false</pub_eltau>
      <pub_state>true</pub_state>
      <sub_ext_tau>false</sub_ext_tau>
      <namespace>left</namespace>
      <t_sample>0.01</t_sample>
      <spring_a1>11.0 </spring_a1>
      <spring_k1>0.02</spring_k1>
      <spring_a2>11.0</spring_a2>
      <spring_k2>0.02</spring_k2>
      <mot_1_tauMax>12.0</mot_1_tauMax>
      <mot_2_tauMax>12.0</mot_2_tauMax>
    </plugin>
  </gazebo>
  <!-- CUBE 5 -->
  <gazebo>
    <plugin filename="libqbmove_plugin.so" name="compliant_act_left_j5">
      <joint>left_forearm_cube_to_left_wrist_flange</joint>
      <operation_mode>5</operation_mode>
      <pub_eltau>false</pub_eltau>
      <pub_state>true</pub_state>
      <sub_ext_tau>false</sub_ext_tau>
      <namespace>left</namespace>
      <t_sample>0.01</t_sample>
      <spring_a1>11.0 </spring_a1>
      <spring_k1>0.02</spring_k1>
      <spring_a2>11.0</spring_a2>
      <spring_k2>0.02</spring_k2>
      <mot_1_tauMax>12.0</mot_1_tauMax>
      <mot_2_tauMax>12.0</mot_2_tauMax>
    </plugin>
  </gazebo>
  <!-- CUBE 6 -->
  <gazebo>
    <plugin filename="libqbmove_plugin.so" name="compliant_act_left_j6">
      <joint>left_wrist_to_left_hand</joint>
      <operation_mode>5</operation_mode>
      <pub_eltau>false</pub_eltau>
      <pub_state>true</pub_state>
      <sub_ext_tau>false</sub_ext_tau>
      <namespace>left</namespace>
      <t_sample>0.01</t_sample>
      <spring_a1>11.0 </spring_a1>
      <spring_k1>0.02</spring_k1>
      <spring_a2>11.0</spring_a2>
      <spring_k2>0.02</spring_k2>
      <mot_1_tauMax>12.0</mot_1_tauMax>
      <mot_2_tauMax>12.0</mot_2_tauMax>
    </plugin>
  </gazebo>
  <!-- Right Arm Actuator-->
  <!-- CUBE 22 -->
  <gazebo>
    <plugin filename="libqbmove_plugin.so" name="compliant_act_head22">
      <joint>neck_to_neck_cube</joint>
      <operation_mode>5</operation_mode>
      <pub_eltau>false</pub_eltau>
      <pub_state>true</pub_state>
      <sub_ext_tau>false</sub_ext_tau>
      <namespace>right</namespace>
      <t_sample>0.01</t_sample>
      <spring_a1>11.0 </spring_a1>
      <spring_k1>0.02</spring_k1>
      <spring_a2>11.0</spring_a2>
      <spring_k2>0.02</spring_k2>
      <mot_1_tauMax>12.0</mot_1_tauMax>
      <mot_2_tauMax>12.0</mot_2_tauMax>
    </plugin>
  </gazebo>
  <!-- CUBE 11 -->
  <gazebo>
    <plugin filename="libqbmove_plugin.so" name="compliant_act_right_11">
      <joint>base_to_right_shoulder_flange</joint>
      <operation_mode>1</operation_mode>
      <pub_eltau>false</pub_eltau>
      <pub_state>true</pub_state>
      <sub_ext_tau>false</sub_ext_tau>
      <namespace>right</namespace>
      <t_sample>0.01</t_sample>
      <spring_a1>11.0 </spring_a1>
      <spring_k1>0.02</spring_k1>
      <spring_a2>11.0</spring_a2>
      <spring_k2>0.02</spring_k2>
      <mot_1_tauMax>12.0</mot_1_tauMax>
      <mot_2_tauMax>12.0</mot_2_tauMax>
    </plugin>
  </gazebo>
  <!-- CUBE 12 -->
  <gazebo>
    <plugin filename="libqbmove_plugin.so" name="compliant_act_right_j12">
      <joint>right_shoulder_cube_to_right_arm_flange</joint>
      <operation_mode>5</operation_mode>
      <pub_eltau>false</pub_eltau>
      <pub_state>true</pub_state>
      <sub_ext_tau>false</sub_ext_tau>
      <namespace>right</namespace>
      <t_sample>0.01</t_sample>
      <spring_a1>11.0 </spring_a1>
      <spring_k1>0.02</spring_k1>
      <spring_a2>11.0</spring_a2>
      <spring_k2>0.02</spring_k2>
      <mot_1_tauMax>12.0</mot_1_tauMax>
      <mot_2_tauMax>12.0</mot_2_tauMax>
    </plugin>
  </gazebo>
  <!-- CUBE 13 -->
  <gazebo>
    <plugin filename="libqbmove_plugin.so" name="compliant_act_right_j13">
      <joint>right_arm_cube_to_right_elbow_flange_sensor</joint>
      <operation_mode>5</operation_mode>
      <pub_eltau>false</pub_eltau>
      <pub_state>true</pub_state>
      <sub_ext_tau>false</sub_ext_tau>
      <namespace>right</namespace>
      <t_sample>0.01</t_sample>
      <spring_a1>11.0 </spring_a1>
      <spring_k1>0.02</spring_k1>
      <spring_a2>11.0</spring_a2>
      <spring_k2>0.02</spring_k2>
      <mot_1_tauMax>12.0</mot_1_tauMax>
      <mot_2_tauMax>12.0</mot_2_tauMax>
    </plugin>
  </gazebo>
  <!-- CUBE 14 -->
  <gazebo>
    <plugin filename="libqbmove_plugin.so" name="compliant_act_right_j14">
      <joint>right_elbow_cube_to_right_forearm_flange</joint>
      <operation_mode>5</operation_mode>
      <pub_eltau>false</pub_eltau>
      <pub_state>true</pub_state>
      <sub_ext_tau>false</sub_ext_tau>
      <namespace>right</namespace>
      <t_sample>0.01</t_sample>
      <spring_a1>11.0 </spring_a1>
      <spring_k1>0.02</spring_k1>
      <spring_a2>11.0</spring_a2>
      <spring_k2>0.02</spring_k2>
      <mot_1_tauMax>12.0</mot_1_tauMax>
      <mot_2_tauMax>12.0</mot_2_tauMax>
    </plugin>
  </gazebo>
  <!-- CUBE 15 -->
  <gazebo>
    <plugin filename="libqbmove_plugin.so" name="compliant_act_right_j15">
      <joint>right_forearm_cube_to_right_wrist_flange</joint>
      <operation_mode>5</operation_mode>
      <pub_eltau>false</pub_eltau>
      <pub_state>true</pub_state>
      <sub_ext_tau>false</sub_ext_tau>
      <namespace>right</namespace>
      <t_sample>0.01</t_sample>
      <spring_a1>11.0 </spring_a1>
      <spring_k1>0.02</spring_k1>
      <spring_a2>11.0</spring_a2>
      <spring_k2>0.02</spring_k2>
      <mot_1_tauMax>12.0</mot_1_tauMax>
      <mot_2_tauMax>12.0</mot_2_tauMax>
    </plugin>
  </gazebo>
  <!-- CUBE 16 -->
  <gazebo>
    <plugin filename="libqbmove_plugin.so" name="compliant_act_right_j16">
      <joint>right_wrist_to_right_hand</joint>
      <operation_mode>5</operation_mode>
      <pub_eltau>false</pub_eltau>
      <pub_state>true</pub_state>
      <sub_ext_tau>false</sub_ext_tau>
      <namespace>right</namespace>
      <t_sample>0.01</t_sample>
      <spring_a1>11.0 </spring_a1>
      <spring_k1>0.02</spring_k1>
      <spring_a2>11.0</spring_a2>
      <spring_k2>0.02</spring_k2>
      <mot_1_tauMax>12.0</mot_1_tauMax>
      <mot_2_tauMax>12.0</mot_2_tauMax>
    </plugin>
  </gazebo>
  <gazebo reference="base_to_front_kick_stand">
    <implicitSpringDamper>true</implicitSpringDamper>
    <springStiffness>200</springStiffness>
    <springReference>-0.2616665</springReference>
  </gazebo>
  <gazebo reference="base_to_back_kick_stand">
    <implicitSpringDamper>true</implicitSpringDamper>
    <springStiffness>200</springStiffness>
    <springReference>-0.2616665</springReference>
  </gazebo>
  <gazebo reference="imu">
    <gravity>true</gravity>
    <sensor name="imu_sensor" type="imu">
      <always_on>true</always_on>
      <update_rate>500</update_rate>
      <visualize>true</visualize>
      <topic>__default_topic__</topic>
      <plugin filename="libgazebo_ros_imu_sensor.so" name="imu_plugin">
        <topicName>imu</topicName>
        <bodyName>imu_1</bodyName>
        <updateRateHZ>10.0</updateRateHZ>
        <gaussianNoise>0.0</gaussianNoise>
        <xyzOffset>0 0 0</xyzOffset>
        <rpyOffset>0 0 0</rpyOffset>
        <frameName>imu_1</frameName>
      </plugin>
      <pose>0 0 0 0 0 0</pose>
    </sensor>
  </gazebo>
  <link name="world"/>
  <joint name="world_to_trans_x" type="prismatic">
    <parent link="world"/>
    <child link="trans_x"/>
    <axis xyz="1 0 0"/>
    <limit effort="100000" lower="-100000" upper="100000" velocity="100000"/>
  </joint>
  <link name="trans_x"/>
  <joint name="trans_x_to_trans_y" type="prismatic">
    <parent link="trans_x"/>
    <child link="trans_y"/>
    <axis xyz="0 1 0"/>
    <limit effort="100000" lower="-100000" upper="100000" velocity="100000"/>
  </joint>
  <link name="trans_y"/>
  <joint name="trans_y_to_fixed_z" type="fixed">
    <origin rpy="0.0 0.0 0.0" xyz="0 0 0.13"/>
    <parent link="trans_y"/>
    <child link="trans_z"/>
  </joint>
  <link name="trans_z"/>
  <joint name="trans_z_to_rot_z" type="continuous">
    <parent link="trans_z"/>
    <child link="rot_z"/>
    <axis xyz="0 0 1"/>
  </joint>
  <link name="rot_z"/>
  <joint name="rot_z_to_rot_y" type="continuous">
    <parent link="rot_z"/>
    <child link="rot_y"/>
    <axis xyz="0 1 0"/>
  </joint>
  <link name="rot_y"/>
  <joint name="rot_y_base" type="fixed">
    <origin rpy="0.0 0.0 0.0" xyz="0 0 0"/>
    <parent link="rot_y"/>
    <child link="base"/>
  </joint>
  <!-- <link name="world">
	</link>

	<joint name="world_to_base" type="fixed">
		<origin xyz="0 0 0" rpy="0 0 0" />
		<parent link="world" />
		<child link="base" />
	</joint>
	 -->
  <link name="base">
    <visual>
      <material name="SoftLightBlue"/>
      <geometry>
        <mesh filename="package://alterego_robot/alterego_description/meshes/alterego_v3/visual/aego_base.dae" scale="0.001 0.001 0.001"/>
      </geometry>
      <origin rpy="0 0 0" xyz="0 0 0"/>
    </visual>
    <inertial>
      <origin rpy="0 0 0" xyz="-6.0298829e-3 2.5874338e-4 3.3410009e-1"/>
      <mass value="2.3743e+1"/>
      <inertia ixx=" 3.1258968" ixy="-1.5892316e-3" ixz="-4.7850173e-2" iyy="2.9578724" iyz="-5.7425852e-4" izz="2.6379126e-1"/>
    </inertial>
    <collision>
      <geometry>
        <mesh filename="package://alterego_robot/alterego_description/meshes/alterego_v3/collision/aego_base.stl" scale="0.001 0.001 0.001"/>
      </geometry>
      <origin rpy="0 0 0" xyz="0 0 0"/>
    </collision>
  </link>
  <link name="torso">
	</link>
  <joint name="base_to_torso" type="fixed">
    <origin rpy="0 0 0" xyz="-0.0 0 0.874939"/>
    <parent link="base"/>
    <child link="torso"/>
  </joint>
  <gazebo reference="base">
    <material>Gazebo/SkyBlue</material>
    <selfCollide>false</selfCollide>
  </gazebo>
  <!-- JOINT -->
  <joint name="base_to_left_shoulder_flange" type="revolute">
    <axis xyz="0 0 1"/>
    <limit effort="1000.0" lower="-3.14" upper="3.14" velocity="0.5"/>
    <origin rpy="-0.1745345 -1.3962633 -1.5707948" xyz="28.6482e-3 220.259e-3 901.246e-3"/>
    <dynamics damping="0.065" friction="0.025"/>
    <parent link="base"/>
    <child link="left_shoulder_flange"/>
  </joint>
  <!-- LINK -->
  <link name="left_shoulder_flange">
    <visual>
      <material name="qbmove/flange"/>
      <geometry>
        <mesh filename="package://alterego_robot/alterego_description/meshes/common/visual/la_flg_asm_flat_blu.dae" scale="0.001 0.001 0.001"/>
      </geometry>
      <origin rpy="0 0 0" xyz="0 0 0"/>
    </visual>
    <inertial>
      <origin rpy="0 0 0" xyz="-8.0511890e-5 0 6.1371397e-4"/>
      <mass value="4.1898263e-02"/>
      <inertia ixx="1.5773084e-5" ixy="0" ixz="0" iyy="2.1042697e-5" iyz="0" izz="3.6312308e-5"/>
    </inertial>
    <collision>
      <material name="qbmove/cube"/>
      <origin rpy="0 0 0" xyz="0 0 0"/>
      <geometry>
        <mesh filename="package://alterego_robot/alterego_description/meshes/common/collision/la_flg_asm_flat_blu.stl" scale="0.001 0.001 0.001"/>
      </geometry>
    </collision>
  </link>
  <!-- GAZEBO REFERENCE -->
  <gazebo reference="left_shoulder_flange">
    <material>Gazebo/SkyBlue</material>
    <selfCollide>false</selfCollide>
  </gazebo>
  <!-- JOINT -->
  <joint name="left_shoulder_flange_to_left_shoulder_cube" type="fixed">
    <origin rpy="-1.5707963 0 0" xyz="0 -0.5e-3 37e-3"/>
    <parent link="left_shoulder_flange"/>
    <child link="left_shoulder_cube"/>
  </joint>
  <!-- LINK -->
  <link name="left_shoulder_cube">
    <visual>
      <material name="qbmove/cube"/>
      <geometry>
        <mesh filename="package://alterego_robot/alterego_description/meshes/alterego_v3/visual/qb_mate_advanced_plus_add.dae" scale="0.001 0.001 0.001"/>
      </geometry>
      <origin rpy="0 0 0" xyz="0 0 0"/>
    </visual>
    <inertial>
      <origin rpy="0 0 0" xyz="-6.7920088e-5 -1.0259859e-5  3.3111200e-3"/>
      <mass value="6.6127705e-1"/>
      <inertia ixx="5.5302425e-4" ixy="-1.7453168e-5" ixz="-1.5101777e-6" iyy="5.5130433e-4" iyz="0" izz="2.8634544e-4"/>
    </inertial>
    <collision>
      <origin rpy="0.0 0.0 0.0" xyz="0.0 0.0 0.0"/>
      <geometry>
        <box size="0.07 0.07 0.07"/>
      </geometry>
    </collision>
  </link>
  <!-- GAZEBO REFERENCE -->
  <gazebo reference="left_shoulder_cube">
    <material>Gazebo/Grey</material>
    <selfCollide>false</selfCollide>
  </gazebo>
  <!-- JOINT -->
  <joint name="left_shoulder_cube_to_left_arm_flange" type="revolute">
    <axis xyz="0 0 1"/>
    <limit effort="1000.0" lower="-3.14" upper="3.14" velocity="0.5"/>
    <origin rpy="0 0 0" xyz="0 0 0.5e-3"/>
    <dynamics damping="0.065" friction="0.025"/>
    <parent link="left_shoulder_cube"/>
    <child link="left_arm_flange"/>
  </joint>
  <!-- LINK -->
  <link name="left_arm_flange">
    <visual>
      <material name="qbmove/flange"/>
      <geometry>
        <mesh filename="package://alterego_robot/alterego_description/meshes/alterego_v3/visual/la_flg_c_wb_large.dae" scale="0.001 0.001 0.001"/>
      </geometry>
      <origin rpy="0 0 0" xyz="0 0 0"/>
    </visual>
    <inertial>
      <origin rpy="0 0 0" xyz="6.4001753e-3 1.4674945e-2 0"/>
      <mass value="1.2524265e-01"/>
      <inertia ixx="1.1014959e-4" ixy="-3.0957793e-5" ixz="0" iyy="2.3068924e-4" iyz="0" izz="2.7657409e-4"/>
    </inertial>
    <collision>
      <origin rpy="0 0 0" xyz="0 0 0"/>
      <geometry>
        <mesh filename="package://alterego_robot/alterego_description/meshes/alterego_v3/collision/la_flg_c_wb_large.stl" scale="0.001 0.001 0.001"/>
      </geometry>
    </collision>
  </link>
  <!-- GAZEBO REFERENCE -->
  <gazebo reference="left_arm_flange">
    <material>Gazebo/SkyBlue</material>
    <selfCollide>false</selfCollide>
  </gazebo>
  <!-- JOINT -->
  <joint name="left_arm_flange_to_left_arm_cube" type="fixed">
    <origin rpy="0 1.5707963 3.1415927" xyz="-90e-3 0 0"/>
    <parent link="left_arm_flange"/>
    <child link="left_arm_cube"/>
  </joint>
  <!-- LINK -->
  <link name="left_arm_cube">
    <visual>
      <material name="qbmove/cube"/>
      <geometry>
        <mesh filename="package://alterego_robot/alterego_description/meshes/common/visual/qb_move_advanced_for_mate.dae" scale="0.001 0.001 0.001"/>
      </geometry>
      <origin rpy="0 0 0" xyz="0 0 0"/>
    </visual>
    <inertial>
      <origin rpy="0 0 0" xyz="-9.5664949e-5 -1.6749134e-5  1.3880927e-3"/>
      <mass value="4.5418805e-1"/>
      <inertia ixx="1.7978900e-4" ixy="0" ixz="0" iyy="1.7806823e-4" iyz="0" izz="1.6882624e-4"/>
    </inertial>
    <collision>
      <origin rpy="0.0 0.0 0.0" xyz="0.0 0.0 0.0"/>
      <geometry>
        <box size="0.07 0.07 0.07"/>
      </geometry>
    </collision>
  </link>
  <!-- GAZEBO REFERENCE -->
  <gazebo reference="left_arm_cube">
    <material>Gazebo/Grey</material>
    <selfCollide>false</selfCollide>
  </gazebo>
  <!-- IMU : -->
  <joint name="left_arm_cube_to_left_elbow_flange_sensor" type="revolute">
    <axis xyz="0 0 1"/>
    <limit effort="1000.0" lower="-3.14" upper="3.14" velocity="0.5"/>
    <dynamics damping="0.065" friction="0.025"/>
    <origin rpy="0 0 1.5707963" xyz="0 0 66.5e-3"/>
    <parent link="left_arm_cube"/>
    <child link="left_elbow_flange_sensor"/>
  </joint>
  <link name="left_elbow_flange_sensor">
    <visual>
      <material name="qbmove/cube"/>
      <geometry>
        <mesh filename="package://alterego_robot/alterego_description/meshes/alterego_v3/visual/fsens_hinge_001.dae" scale="0.001 0.001 0.001"/>
      </geometry>
      <origin rpy="0 0 0" xyz="0 0 0"/>
    </visual>
    <inertial>
      <origin rpy="0 0 0" xyz="0 -7.3560725e-4 -2.2326727e-3"/>
      <mass value="1.0238457e-01"/>
      <inertia ixx="5.9037323e-5" ixy="0" ixz="0" iyy="5.3509057e-5" iyz="0" izz="8.7851500e-5"/>
    </inertial>
    <collision>
      <origin rpy="0 0 0" xyz="0 0 0"/>
      <geometry>
        <mesh filename="package://alterego_robot/alterego_description/meshes/alterego_v3/collision/fsens_hinge_001.stl" scale="0.001 0.001 0.001"/>
      </geometry>
    </collision>
  </link>
  <!-- JOINT -->
  <joint name="left_elbow_flange_sensor_to_left_elbow_flange" type="fixed">
    <axis xyz="0 0 1"/>
    <limit effort="1000.0" lower="-3.14" upper="3.14" velocity="0.5"/>
    <origin rpy="0 0 -1.5707963" xyz="0 0 18e-3"/>
    <dynamics damping="0.065" friction="0.025"/>
    <parent link="left_elbow_flange_sensor"/>
    <child link="left_elbow_flange"/>
  </joint>
  <!-- LINK -->
  <link name="left_elbow_flange">
    <visual>
      <material name="qbmove/flange"/>
      <geometry>
        <mesh filename="package://alterego_robot/alterego_description/meshes/common/visual/la_flg_asm_flat_blu.dae" scale="0.001 0.001 0.001"/>
      </geometry>
      <origin rpy="0 0 0" xyz="0 0 0"/>
    </visual>
    <inertial>
      <origin rpy="0 0 0" xyz="-8.0511890e-5 0 6.1371397e-4"/>
      <mass value="4.1898263e-02"/>
      <inertia ixx="1.5773084e-5" ixy="0" ixz="0" iyy="2.1026644e-5" iyz="0" izz="3.6312308e-5"/>
    </inertial>
    <collision>
      <origin rpy="0 0 0" xyz="0 0 0"/>
      <geometry>
        <mesh filename="package://alterego_robot/alterego_description/meshes/common/collision/la_flg_asm_flat_blu.stl" scale="0.001 0.001 0.001"/>
      </geometry>
    </collision>
  </link>
  <!-- GAZEBO REFERENCE -->
  <gazebo reference="left_elbow_flange">
    <material>Gazebo/SkyBlue</material>
    <selfCollide>false</selfCollide>
  </gazebo>
  <!-- JOINT -->
  <joint name="left_elbow_flange_to_left_elbow_cube" type="fixed">
    <origin rpy="-1.5707963 0 0" xyz="0 0 37e-3"/>
    <parent link="left_elbow_flange"/>
    <child link="left_elbow_cube"/>
  </joint>
  <!-- LINK -->
  <link name="left_elbow_cube">
    <visual>
      <material name="qbmove/cube"/>
      <geometry>
        <mesh filename="package://alterego_robot/alterego_description/meshes/common/visual/qb_move_advanced_for_mate.dae" scale="0.001 0.001 0.001"/>
      </geometry>
      <origin rpy="0 0 0" xyz="0 0 0"/>
    </visual>
    <inertial>
      <origin rpy="0 0 0" xyz="-9.5664949e-5 -1.6749134e-5  1.3880927e-3"/>
      <mass value="4.5418805e-1"/>
      <inertia ixx="1.7978900e-4" ixy="0" ixz="0" iyy="1.7806823e-4" iyz="0" izz="1.6882624e-4"/>
    </inertial>
    <collision>
      <origin rpy="0.0 0.0 0.0" xyz="0.0 0.0 0.0"/>
      <geometry>
        <box size="0.07 0.07 0.07"/>
      </geometry>
    </collision>
  </link>
  <!-- GAZEBO REFERENCE -->
  <gazebo reference="left_elbow_cube">
    <material>Gazebo/Grey</material>
    <selfCollide>false</selfCollide>
  </gazebo>
  <!-- JOINT -->
  <joint name="left_elbow_cube_to_left_forearm_flange" type="revolute">
    <axis xyz="0 0 1"/>
    <limit effort="1000.0" lower="-3.14" upper="3.14" velocity="0.5"/>
    <origin rpy="0 0 1.5707963" xyz="0 0 -0.5e-3"/>
    <dynamics damping="0.065" friction="0.025"/>
    <parent link="left_elbow_cube"/>
    <child link="left_forearm_flange"/>
  </joint>
  <!-- LINK -->
  <link name="left_forearm_flange">
    <visual>
      <material name="qbmove/flange"/>
      <geometry>
        <mesh filename="package://alterego_robot/alterego_description/meshes/common/visual/la_flg_asm_c_wb_blu.dae" scale="0.001 0.001 0.001"/>
      </geometry>
      <origin rpy="0 0 0" xyz="0 0 0"/>
    </visual>
    <inertial>
      <origin rpy="0 0 0" xyz="-7.3157519e-3 2.3015782e-2 0"/>
      <mass value="8.6640591e-2"/>
      <inertia ixx="7.8695858e-5" ixy="1.8826444e-5" ixz="0" iyy="1.0265668e-4" iyz="0" izz="1.3810438e-4"/>
    </inertial>
    <collision>
      <origin rpy="0 0 0" xyz="0 0 0"/>
      <geometry>
        <mesh filename="package://alterego_robot/alterego_description/meshes/common/collision/la_flg_asm_c_wb_blu.stl" scale="0.001 0.001 0.001"/>
      </geometry>
    </collision>
  </link>
  <!-- GAZEBO REFERENCE -->
  <gazebo reference="left_forearm_flange">
    <material>Gazebo/SkyBlue</material>
    <selfCollide>false</selfCollide>
  </gazebo>
  <!-- JOINT -->
  <joint name="left_forearm_flange_to_left_forearm_cube" type="fixed">
    <origin rpy="1.5707963 0 -1.5707963" xyz="-90e-3 0 0"/>
    <parent link="left_forearm_flange"/>
    <child link="left_forearm_cube"/>
  </joint>
  <!-- LINK -->
  <link name="left_forearm_cube">
    <visual>
      <material name="qbmove/cube"/>
      <geometry>
        <mesh filename="package://alterego_robot/alterego_description/meshes/common/visual/qb_move_advanced_for_mate.dae" scale="0.001 0.001 0.001"/>
      </geometry>
      <origin rpy="0 0 0" xyz="0 0 0"/>
    </visual>
    <inertial>
      <origin rpy="0 0 0" xyz="-9.5664949e-5 -1.6749134e-5  1.3880927e-3"/>
      <mass value="4.5418805e-1"/>
      <inertia ixx="1.7978900e-4" ixy="0" ixz="0" iyy="1.7806823e-4" iyz="0" izz="1.6882624e-4"/>
    </inertial>
    <collision>
      <origin rpy="0.0 0.0 0.0" xyz="0.0 0.0 0.0"/>
      <geometry>
        <box size="0.07 0.07 0.07"/>
      </geometry>
    </collision>
  </link>
  <!-- GAZEBO REFERENCE -->
  <gazebo reference="left_forearm_cube">
    <material>Gazebo/Grey</material>
    <selfCollide>false</selfCollide>
  </gazebo>
  <!-- JOINT -->
  <joint name="left_forearm_cube_to_left_wrist_flange" type="revolute">
    <axis xyz="0 0 1"/>
    <limit effort="1000.0" lower="-3.14" upper="3.14" velocity="0.5"/>
    <origin rpy="0 0 -1.5707963" xyz="0.0 0.0 40.5e-3"/>
    <dynamics damping="0.065" friction="0.025"/>
    <parent link="left_forearm_cube"/>
    <child link="left_wrist_flange"/>
  </joint>
  <!-- LINK -->
  <link name="left_wrist_flange">
    <visual>
      <material name="qbmove/flange"/>
      <geometry>
        <mesh filename="package://alterego_robot/alterego_description/meshes/common/visual/la_flg_asm_flat_blu.dae" scale="0.001 0.001 0.001"/>
      </geometry>
      <origin rpy="0 0 0" xyz="0 0 0"/>
    </visual>
    <inertial>
      <origin rpy="0 0 0" xyz="-8.0511890e-5 0 6.1371397e-4"/>
      <mass value="4.1898263e-02"/>
      <inertia ixx="1.5773084e-5" ixy="0" ixz="0" iyy="2.1026644e-5" iyz="0" izz="3.6312308e-5"/>
    </inertial>
    <collision>
      <origin rpy="0 0 0" xyz="0 0 0"/>
      <geometry>
        <mesh filename="package://alterego_robot/alterego_description/meshes/common/collision/la_flg_asm_flat_blu.stl" scale="0.001 0.001 0.001"/>
      </geometry>
    </collision>
  </link>
  <!-- GAZEBO REFERENCE -->
  <gazebo reference="left_wrist_flange">
    <material>Gazebo/SkyBlue</material>
    <selfCollide>false</selfCollide>
  </gazebo>
  <!-- JOINT -->
  <joint name="left_wrist_flange_to_left_wrist" type="fixed">
    <origin rpy="1.5707963 0 0" xyz="11.9e-3 0 99.8636e-3"/>
    <parent link="left_wrist_flange"/>
    <child link="left_wrist"/>
  </joint>
  <!-- LINK -->
  <link name="left_wrist">
    <visual>
      <material name="qbmove/cube"/>
      <geometry>
        <mesh filename="package://alterego_robot/alterego_description/meshes/alterego_v3/visual/left_wrist_v2_1_urdf.dae" scale="0.001 0.001 0.001"/>
      </geometry>
      <origin rpy="0 0 0" xyz="0 0 0"/>
    </visual>
    <inertial>
      <origin rpy="0 0 0" xyz="-1.0015996e-2 -4.7977946e-2  7.1379217e-3"/>
      <mass value="7.1363493e-01"/>
      <inertia ixx=" 8.9951899e-4" ixy="-6.4509373e-5" ixz="-9.6528261e-6" iyy=" 4.9791497e-4" iyz="-3.7410480e-5" izz="7.0476751e-4"/>
    </inertial>
    <collision>
      <material name="qbmove/cube"/>
      <geometry>
        <mesh filename="package://alterego_robot/alterego_description/meshes/alterego_v3/collision/left_wrist_v2_1_urdf.stl" scale="0.001 0.001 0.001"/>
      </geometry>
      <origin rpy="0 0 0" xyz="0 0 0"/>
    </collision>
  </link>
  <!-- GAZEBO REFERENCE -->
  <gazebo reference="left_wrist">
    <material>Gazebo/Grey</material>
    <selfCollide>false</selfCollide>
  </gazebo>
  <!-- JOINT -->
  <joint name="left_wrist_to_left_hand" type="revolute">
    <axis xyz="0 0 1"/>
    <limit effort="1000.0" lower="-3.14" upper="3.14" velocity="0.5"/>
    <origin rpy="0.0 0.0 0.0" xyz="0.0 0.0 0.0"/>
    <parent link="left_wrist"/>
    <child link="left_hand"/>
  </joint>
  <!-- LINK -->
  <link name="left_hand">
    <visual>
      <material name="qbmove/cube"/>
      <geometry>
        <mesh filename="package://alterego_robot/alterego_description/meshes/common/visual/softhand_3_sx_urdf.dae" scale="0.001 0.001 0.001"/>
      </geometry>
      <origin rpy="0 0 0" xyz="0 0 0"/>
    </visual>
    <inertial>
      <origin rpy="0 0 0" xyz="4.1728393e-3  6.3287667e-2 6.0659797e-3"/>
      <mass value="2.9013125e-1"/>
      <inertia ixx="5.6377846e-4" ixy="-2.5891425e-5" ixz="-1.0142109e-5" iyy="1.4989796e-4" iyz="5.9361645e-6" izz="4.4769789e-4"/>
    </inertial>
    <collision>
      <material name="qbmove/cube"/>
      <geometry>
        <mesh filename="package://alterego_robot/alterego_description/meshes/common/collision/softhand_3_sx_urdf.stl" scale="0.001 0.001 0.001"/>
      </geometry>
      <origin rpy="0 0 0" xyz="0 0 0"/>
    </collision>
  </link>
  m
		
  <joint name="left_hand_to_left_hand__ik" type="fixed">
    <origin rpy="0 0 -1.57" xyz="0 0.088 0.032"/>
    <parent link="left_hand"/>
    <child link="left_hand_ik"/>
  </joint>
  <link name="left_hand_ik">
		</link>
  <!-- GAZEBO REFERENCE -->
  <gazebo reference="left_hand">
    <material>Gazebo/Grey</material>
    <selfCollide>false</selfCollide>
  </gazebo>
  <!-- JOINT -->
  <joint name="base_to_right_shoulder_flange" type="revolute">
    <axis xyz="0 0 1"/>
    <limit effort="1000.0" lower="-3.14" upper="3.14" velocity="0.5"/>
    <origin rpy="0.1745345 -1.3962633 1.5707948" xyz="28.6482e-3 -220.259e-3 901.246e-3"/>
    <dynamics damping="0.065" friction="0.025"/>
    <parent link="base"/>
    <child link="right_shoulder_flange"/>
  </joint>
  <!-- LINK -->
  <link name="right_shoulder_flange">
    <visual>
      <material name="qbmove/flange"/>
      <geometry>
        <mesh filename="package://alterego_robot/alterego_description/meshes/common/visual/la_flg_asm_flat_blu.dae" scale="0.001 0.001 0.001"/>
      </geometry>
      <origin rpy="0 0 0" xyz="0 0 0"/>
    </visual>
    <inertial>
      <origin rpy="0 0 0" xyz="-8.0511890e-5 0 6.1371397e-4"/>
      <mass value="4.1898263e-02"/>
      <inertia ixx="1.5773084e-5" ixy="0" ixz="0" iyy="2.1042697e-5" iyz="0" izz="3.6312308e-5"/>
    </inertial>
    <collision>
      <material name="qbmove/cube"/>
      <origin rpy="0 0 0" xyz="0 0 0"/>
      <geometry>
        <mesh filename="package://alterego_robot/alterego_description/meshes/common/collision/la_flg_asm_flat_blu.stl" scale="0.001 0.001 0.001"/>
      </geometry>
    </collision>
  </link>
  <!-- GAZEBO REFERENCE -->
  <gazebo reference="right_shoulder_flange">
    <material>Gazebo/SkyBlue</material>
    <selfCollide>false</selfCollide>
  </gazebo>
  <!-- JOINT -->
  <joint name="right_shoulder_flange_to_right_shoulder_cube" type="fixed">
    <origin rpy="-1.5707963 0 3.1415927" xyz="0 0.5e-3 37e-3"/>
    <parent link="right_shoulder_flange"/>
    <child link="right_shoulder_cube"/>
  </joint>
  <!-- LINK -->
  <link name="right_shoulder_cube">
    <visual>
      <material name="qbmove/cube"/>
      <geometry>
        <mesh filename="package://alterego_robot/alterego_description/meshes/alterego_v3/visual/qb_mate_advanced_plus_add.dae" scale="0.001 0.001 0.001"/>
      </geometry>
      <origin rpy="0 0 0" xyz="0 0 0"/>
    </visual>
    <inertial>
      <origin rpy="0 0 0" xyz="-6.7920088e-5 -1.0259859e-5  3.3111200e-3"/>
      <mass value="6.6127705e-1"/>
      <inertia ixx="5.5302425e-4" ixy="-1.7453168e-5" ixz="-1.5101777e-6" iyy="5.5130433e-4" iyz="0" izz="2.8634544e-4"/>
    </inertial>
    <collision>
      <origin rpy="0.0 0.0 0.0" xyz="0.0 0.0 0.0"/>
      <geometry>
        <box size="0.07 0.07 0.07"/>
      </geometry>
    </collision>
  </link>
  <!-- GAZEBO REFERENCE -->
  <gazebo reference="right_shoulder_cube">
    <material>Gazebo/Grey</material>
    <selfCollide>false</selfCollide>
  </gazebo>
  <!-- JOINT -->
  <joint name="right_shoulder_cube_to_right_arm_flange" type="revolute">
    <axis xyz="0 0 1"/>
    <limit effort="1000.0" lower="-3.14" upper="3.14" velocity="0.5"/>
    <origin rpy="0 0 3.1415927" xyz="0 0 0.5e-3"/>
    <dynamics damping="0.065" friction="0.025"/>
    <parent link="right_shoulder_cube"/>
    <child link="right_arm_flange"/>
  </joint>
  <!-- LINK -->
  <link name="right_arm_flange">
    <visual>
      <material name="qbmove/flange"/>
      <geometry>
        <mesh filename="package://alterego_robot/alterego_description/meshes/alterego_v3/visual/la_flg_c_wb_large.dae" scale="0.001 0.001 0.001"/>
      </geometry>
      <origin rpy="0 0 0" xyz="0 0 0"/>
    </visual>
    <inertial>
      <origin rpy="0 0 0" xyz="6.4001753e-3 1.4674945e-2 0"/>
      <mass value="1.2524265e-01"/>
      <inertia ixx="1.1014959e-4" ixy="-3.0957793e-5" ixz="0" iyy="2.3068924e-4" iyz="0" izz="2.7657409e-4"/>
    </inertial>
    <collision>
      <origin rpy="0 0 0" xyz="0 0 0"/>
      <geometry>
        <mesh filename="package://alterego_robot/alterego_description/meshes/alterego_v3/collision/la_flg_c_wb_large.stl" scale="0.001 0.001 0.001"/>
      </geometry>
    </collision>
  </link>
  <!-- GAZEBO REFERENCE -->
  <gazebo reference="right_arm_flange">
    <material>Gazebo/SkyBlue</material>
    <selfCollide>false</selfCollide>
  </gazebo>
  <!-- JOINT -->
  <joint name="right_arm_flange_to_right_arm_cube" type="fixed">
    <origin rpy="0 1.5707963 3.1415927" xyz="-90e-3 0 0"/>
    <parent link="right_arm_flange"/>
    <child link="right_arm_cube"/>
  </joint>
  <!-- LINK -->
  <link name="right_arm_cube">
    <visual>
      <material name="qbmove/cube"/>
      <geometry>
        <mesh filename="package://alterego_robot/alterego_description/meshes/common/visual/qb_move_advanced_for_mate.dae" scale="0.001 0.001 0.001"/>
      </geometry>
      <origin rpy="0 0 0" xyz="0 0 0"/>
    </visual>
    <inertial>
      <origin rpy="0 0 0" xyz="-9.5664949e-5 -1.6749134e-5  1.3880927e-3"/>
      <mass value="4.5418805e-1"/>
      <inertia ixx="1.7978900e-4" ixy="0" ixz="0" iyy="1.7806823e-4" iyz="0" izz="1.6882624e-4"/>
    </inertial>
    <collision>
      <origin rpy="0.0 0.0 0.0" xyz="0.0 0.0 0.0"/>
      <geometry>
        <box size="0.07 0.07 0.07"/>
      </geometry>
    </collision>
  </link>
  <!-- GAZEBO REFERENCE -->
  <gazebo reference="right_arm_cube">
    <material>Gazebo/Grey</material>
    <selfCollide>false</selfCollide>
  </gazebo>
  <!-- IMU : -->
  <joint name="right_arm_cube_to_right_elbow_flange_sensor" type="revolute">
    <axis xyz="0 0 1"/>
    <limit effort="1000.0" lower="-3.14" upper="3.14" velocity="0.5"/>
    <dynamics damping="0.065" friction="0.025"/>
    <origin rpy="0 0 1.5707963" xyz="0.0 0.0 66.5e-3"/>
    <parent link="right_arm_cube"/>
    <child link="right_elbow_flange_sensor"/>
  </joint>
  <link name="right_elbow_flange_sensor">
    <visual>
      <material name="qbmove/cube"/>
      <geometry>
        <mesh filename="package://alterego_robot/alterego_description/meshes/alterego_v3/visual/fsens_hinge_001.dae" scale="0.001 0.001 0.001"/>
      </geometry>
      <origin rpy="0 0 0" xyz="0 0 0"/>
    </visual>
    <inertial>
      <origin rpy="0 0 0" xyz="0 -7.3560725e-4 -2.2326727e-3"/>
      <mass value="1.0238457e-01"/>
      <inertia ixx="5.9037323e-5" ixy="0" ixz="0" iyy="5.3509057e-5" iyz="0" izz="8.7851500e-5"/>
    </inertial>
    <collision>
      <origin rpy="0 0 0" xyz="0 0 0"/>
      <geometry>
        <mesh filename="package://alterego_robot/alterego_description/meshes/alterego_v3/collision/fsens_hinge_001.stl" scale="0.001 0.001 0.001"/>
      </geometry>
    </collision>
  </link>
  <!-- JOINT -->
  <joint name="right_elbow_flange_sensor_to_right_elbow_flange" type="fixed">
    <axis xyz="0 0 1"/>
    <limit effort="1000.0" lower="-3.14" upper="3.14" velocity="0.5"/>
    <origin rpy="0 0 -1.5707963" xyz="0 0 18e-3"/>
    <dynamics damping="0.065" friction="0.025"/>
    <parent link="right_elbow_flange_sensor"/>
    <child link="right_elbow_flange"/>
  </joint>
  <!-- LINK -->
  <link name="right_elbow_flange">
    <visual>
      <material name="qbmove/flange"/>
      <geometry>
        <mesh filename="package://alterego_robot/alterego_description/meshes/common/visual/la_flg_asm_flat_blu.dae" scale="0.001 0.001 0.001"/>
      </geometry>
      <origin rpy="0 0 0" xyz="0 0 0"/>
    </visual>
    <inertial>
      <origin rpy="0 0 0" xyz="-8.0511890e-5 0 6.1371397e-4"/>
      <mass value="4.1898263e-02"/>
      <inertia ixx="1.5773084e-5" ixy="0" ixz="0" iyy="2.1026644e-5" iyz="0" izz="3.6312308e-5"/>
    </inertial>
    <collision>
      <origin rpy="0 0 0" xyz="0 0 0"/>
      <geometry>
        <mesh filename="package://alterego_robot/alterego_description/meshes/common/collision/la_flg_asm_flat_blu.stl" scale="0.001 0.001 0.001"/>
      </geometry>
    </collision>
  </link>
  <!-- GAZEBO REFERENCE -->
  <gazebo reference="right_elbow_flange">
    <material>Gazebo/SkyBlue</material>
    <selfCollide>false</selfCollide>
  </gazebo>
  <!-- JOINT -->
  <joint name="right_elbow_flange_to_right_elbow_cube" type="fixed">
    <origin rpy="1.5707963 0 0" xyz="0 0 37e-3"/>
    <parent link="right_elbow_flange"/>
    <child link="right_elbow_cube"/>
  </joint>
  <!-- LINK -->
  <link name="right_elbow_cube">
    <visual>
      <material name="qbmove/cube"/>
      <geometry>
        <mesh filename="package://alterego_robot/alterego_description/meshes/common/visual/qb_move_advanced_for_mate.dae" scale="0.001 0.001 0.001"/>
      </geometry>
      <origin rpy="0 0 0" xyz="0 0 0"/>
    </visual>
    <inertial>
      <origin rpy="0 0 0" xyz="-9.5664949e-5 -1.6749134e-5  1.3880927e-3"/>
      <mass value="4.5418805e-1"/>
      <inertia ixx="1.7978900e-4" ixy="0" ixz="0" iyy="1.7806823e-4" iyz="0" izz="1.6882624e-4"/>
    </inertial>
    <collision>
      <origin rpy="0.0 0.0 0.0" xyz="0.0 0.0 0.0"/>
      <geometry>
        <box size="0.07 0.07 0.07"/>
      </geometry>
    </collision>
  </link>
  <!-- GAZEBO REFERENCE -->
  <gazebo reference="right_elbow_cube">
    <material>Gazebo/Grey</material>
    <selfCollide>false</selfCollide>
  </gazebo>
  <!-- JOINT -->
  <joint name="right_elbow_cube_to_right_forearm_flange" type="revolute">
    <axis xyz="0 0 1"/>
    <limit effort="1000.0" lower="-3.14" upper="3.14" velocity="0.5"/>
    <origin rpy="0 0 -1.5707963" xyz="0 0 -0.5e-3"/>
    <dynamics damping="0.065" friction="0.025"/>
    <parent link="right_elbow_cube"/>
    <child link="right_forearm_flange"/>
  </joint>
  <!-- LINK -->
  <link name="right_forearm_flange">
    <visual>
      <material name="qbmove/flange"/>
      <geometry>
        <mesh filename="package://alterego_robot/alterego_description/meshes/common/visual/la_flg_asm_c_wb_blu.dae" scale="0.001 0.001 0.001"/>
      </geometry>
      <origin rpy="0 0 0" xyz="0 0 0"/>
    </visual>
    <inertial>
      <origin rpy="0 0 0" xyz="-7.3157519e-3 2.3015782e-2 0"/>
      <mass value="8.6640591e-2"/>
      <inertia ixx="7.8695858e-5" ixy="1.8826444e-5" ixz="0" iyy="1.0265668e-4" iyz="0" izz="1.3810438e-4"/>
    </inertial>
    <collision>
      <origin rpy="0 0 0" xyz="0 0 0"/>
      <geometry>
        <mesh filename="package://alterego_robot/alterego_description/meshes/common/collision/la_flg_asm_c_wb_blu.stl" scale="0.001 0.001 0.001"/>
      </geometry>
    </collision>
  </link>
  <!-- GAZEBO REFERENCE -->
  <gazebo reference="right_forearm_flange">
    <material>Gazebo/SkyBlue</material>
    <selfCollide>false</selfCollide>
  </gazebo>
  <!-- JOINT -->
  <joint name="right_forearm_flange_to_right_forearm_cube" type="fixed">
    <origin rpy="-1.5707963 0 1.5707963" xyz="-90e-3 0 0"/>
    <parent link="right_forearm_flange"/>
    <child link="right_forearm_cube"/>
  </joint>
  <!-- LINK -->
  <link name="right_forearm_cube">
    <visual>
      <material name="qbmove/cube"/>
      <geometry>
        <mesh filename="package://alterego_robot/alterego_description/meshes/common/visual/qb_move_advanced_for_mate.dae" scale="0.001 0.001 0.001"/>
      </geometry>
      <origin rpy="0 0 0" xyz="0 0 0"/>
    </visual>
    <inertial>
      <origin rpy="0 0 0" xyz="-9.5664949e-5 -1.6749134e-5  1.3880927e-3"/>
      <mass value="4.5418805e-1"/>
      <inertia ixx="1.7978900e-4" ixy="0" ixz="0" iyy="1.7806823e-4" iyz="0" izz="1.6882624e-4"/>
    </inertial>
    <collision>
      <origin rpy="0.0 0.0 0.0" xyz="0.0 0.0 0.0"/>
      <geometry>
        <box size="0.07 0.07 0.07"/>
      </geometry>
    </collision>
  </link>
  <!-- GAZEBO REFERENCE -->
  <gazebo reference="right_forearm_cube">
    <material>Gazebo/Grey</material>
    <selfCollide>false</selfCollide>
  </gazebo>
  <!-- JOINT -->
  <joint name="right_forearm_cube_to_right_wrist_flange" type="revolute">
    <axis xyz="0 0 1"/>
    <limit effort="1000.0" lower="-3.14" upper="3.14" velocity="0.5"/>
    <origin rpy="0 0 -1.5707963" xyz="0.0 0.0 40.5e-3"/>
    <dynamics damping="0.065" friction="0.025"/>
    <parent link="right_forearm_cube"/>
    <child link="right_wrist_flange"/>
  </joint>
  <!-- LINK -->
  <link name="right_wrist_flange">
    <visual>
      <material name="qbmove/flange"/>
      <geometry>
        <mesh filename="package://alterego_robot/alterego_description/meshes/common/visual/la_flg_asm_flat_blu.dae" scale="0.001 0.001 0.001"/>
      </geometry>
      <origin rpy="0 0 0" xyz="0 0 0"/>
    </visual>
    <inertial>
      <origin rpy="0 0 0" xyz="-8.0511890e-5 0 6.1371397e-4"/>
      <mass value="4.1898263e-02"/>
      <inertia ixx="1.5773084e-5" ixy="0" ixz="0" iyy="2.1026644e-5" iyz="0" izz="3.6312308e-5"/>
    </inertial>
    <collision>
      <origin rpy="0 0 0" xyz="0 0 0"/>
      <geometry>
        <mesh filename="package://alterego_robot/alterego_description/meshes/common/collision/la_flg_asm_flat_blu.stl" scale="0.001 0.001 0.001"/>
      </geometry>
    </collision>
  </link>
  <!-- GAZEBO REFERENCE -->
  <gazebo reference="right_wrist_flange">
    <material>Gazebo/SkyBlue</material>
    <selfCollide>false</selfCollide>
  </gazebo>
  <!-- JOINT -->
  <joint name="right_wrist_flange_to_right_wrist" type="fixed">
    <origin rpy="-1.5707963 0 3.1415927" xyz="-11.9e-3 0 99.8636e-3"/>
    <parent link="right_wrist_flange"/>
    <child link="right_wrist"/>
  </joint>
  <!-- LINK -->
  <link name="right_wrist">
    <visual>
      <material name="qbmove/cube"/>
      <geometry>
        <mesh filename="package://alterego_robot/alterego_description/meshes/alterego_v3/visual/right_wrist_v2_1_urdf.dae" scale="0.001 0.001 0.001"/>
      </geometry>
      <origin rpy="0 0 0" xyz="0 0 0"/>
    </visual>
    <inertial>
      <origin rpy="0 0 0" xyz="-1.0015996e-2 -4.7977946e-2  7.1379217e-3"/>
      <mass value="7.1363493e-01"/>
      <inertia ixx=" 8.9951899e-4" ixy="-6.4509373e-5" ixz="-9.6528261e-6" iyy=" 4.9791497e-4" iyz="-3.7410480e-5" izz="7.0476751e-4"/>
    </inertial>
    <collision>
      <material name="qbmove/cube"/>
      <geometry>
        <mesh filename="package://alterego_robot/alterego_description/meshes/alterego_v3/collision/right_wrist_v2_1_urdf.stl" scale="0.001 0.001 0.001"/>
      </geometry>
      <origin rpy="0 0 0" xyz="0 0 0"/>
    </collision>
  </link>
  <!-- GAZEBO REFERENCE -->
  <gazebo reference="right_wrist">
    <material>Gazebo/Grey</material>
    <selfCollide>false</selfCollide>
  </gazebo>
  <!-- JOINT -->
  <joint name="right_wrist_to_right_hand" type="revolute">
    <axis xyz="0 0 1"/>
    <limit effort="1000.0" lower="-1.57" upper="1.57" velocity="0.5"/>
    <origin rpy="0 0 0" xyz="0 0 0.0"/>
    <parent link="right_wrist"/>
    <child link="right_hand"/>
  </joint>
  <!-- LINK -->
  <link name="right_hand">
    <visual>
      <material name="qbmove/cube"/>
      <geometry>
        <mesh filename="package://alterego_robot/alterego_description/meshes/common/visual/softhand_3_dx_urdf.dae" scale="0.001 0.001 0.001"/>
      </geometry>
      <origin rpy="0 0 0" xyz="0 0 0"/>
    </visual>
    <inertial>
      <origin rpy="0 0 0" xyz="4.1739778e-3  -6.3138073e-2 6.1007501e-3"/>
      <mass value="2.9013125e-1"/>
      <inertia ixx="5.6377846e-4" ixy="-2.5891425e-5" ixz="-1.0142109e-5" iyy="1.4989796e-4" iyz="5.9361645e-6" izz="4.4769789e-4"/>
    </inertial>
    <collision>
      <material name="qbmove/cube"/>
      <geometry>
        <mesh filename="package://alterego_robot/alterego_description/meshes/common/collision/softhand_3_dx_urdf.stl" scale="0.001 0.001 0.001"/>
      </geometry>
      <origin rpy="0 0 0" xyz="0 0 0"/>
    </collision>
  </link>
  <joint name="right_hand_to_right_hand__ik" type="fixed">
    <origin rpy="0 0 -1.57" xyz="0 -0.088 0.032"/>
    <parent link="right_hand"/>
    <child link="right_hand_ik"/>
  </joint>
  <link name="right_hand_ik">
		</link>
  <!-- GAZEBO REFERENCE -->
  <gazebo reference="right_hand">
    <material>Gazebo/Grey</material>
    <selfCollide>false</selfCollide>
  </gazebo>
  <!-- JOINT -->
  <joint name="base_to_neck" type="revolute">
    <axis xyz="0 0 1"/>
    <limit effort="1000.0" lower="-1.57" upper="1.57" velocity="0.5"/>
    <origin rpy="0 0 0" xyz="0 0 921.5e-3"/>
    <dynamics damping="0.065" friction="0.025"/>
    <parent link="base"/>
    <child link="neck"/>
  </joint>
  <!-- LINK -->
  <link name="neck">
    <visual>
      <material name="qbmove/flange"/>
      <geometry>
        <mesh filename="package://alterego_robot/alterego_description/meshes/alterego_v3/visual/flange_c_long_new.dae" scale="0.001 0.001 0.001"/>
      </geometry>
      <origin rpy="0 0 0" xyz="0 0 0"/>
    </visual>
    <inertial>
      <origin rpy="0 0 0" xyz="5.1118673e-3 6.5177180e-3 3.0662492e-2"/>
      <mass value="9.6213806e-2"/>
      <inertia ixx="2.2241540e-4" ixy="-8.1427421e-6" ixz="-2.7872669e-5" iyy="1.6452796e-4" iyz="-3.4361481e-5" izz="1.1671216e-4"/>
    </inertial>
    <collision>
      <origin rpy="0 0 0" xyz="0 0 0"/>
      <geometry>
        <mesh filename="package://alterego_robot/alterego_description/meshes/alterego_v3/collision/flange_c_long_new.stl" scale="0.001 0.001 0.001"/>
      </geometry>
    </collision>
  </link>
  <!-- GAZEBO REFERENCE -->
  <gazebo reference="neck">
    <material>Gazebo/SkyBlue</material>
    <selfCollide>false</selfCollide>
  </gazebo>
  <!-- JOINT -->
  <joint name="neck_to_neck_cube" type="revolute">
    <axis xyz="0 0 -1"/>
    <limit effort="1000.0" lower="-3.14" upper="3.14" velocity="0.5"/>
    <dynamics damping="0.065" friction="0.025"/>
    <origin rpy="-1.5707963 0.7853983 -3.1415927" xyz="18e-3 -0.5e-3 85e-3"/>
    <parent link="neck"/>
    <child link="neck_cube"/>
  </joint>
  <!-- LINK -->
  <link name="neck_cube">
    <visual>
      <material name="qbmove/cube"/>
      <geometry>
        <mesh filename="package://alterego_robot/alterego_description/meshes/common/visual/qb_move_advanced_for_mate.dae" scale="0.001 0.001 0.001"/>
      </geometry>
      <origin rpy="0 0 0" xyz="0 0 0"/>
    </visual>
    <inertial>
      <origin rpy="0 0 0" xyz="-9.5664949e-5 -1.6749134e-5  1.3880927e-3"/>
      <mass value="4.5418805e-1"/>
      <inertia ixx="1.7978900e-4" ixy="0" ixz="0" iyy="1.7806823e-4" iyz="0" izz="1.6882624e-4"/>
    </inertial>
    <collision>
      <origin rpy="0.0 0.0 0.0" xyz="0.0 0.0 0.0"/>
      <geometry>
        <box size="0.07 0.07 0.07"/>
      </geometry>
    </collision>
  </link>
  <!-- GAZEBO REFERENCE -->
  <gazebo reference="neck_cube">
    <material>Gazebo/Grey</material>
    <selfCollide>false</selfCollide>
  </gazebo>
  <joint name="neck_cube_to_head" type="fixed">
    <origin rpy="0.0 0.0 0.0" xyz="0 0 0.0"/>
    <parent link="neck_cube"/>
    <child link="head"/>
  </joint>
  <link name="head">
    <visual>
      <material name="qbmove/cube"/>
      <geometry>
        <mesh filename="package://alterego_robot/alterego_description/meshes/alterego_v3/visual/mteg102_head_201.dae" scale="0.001 0.001 0.001"/>
      </geometry>
      <origin rpy="0 0 0" xyz="0 0 0"/>
    </visual>
    <inertial>
      <origin rpy="0 0 0" xyz="4.4194013e-4 1.5128502e-1  4.5874751e-2"/>
      <mass value="3.5761726e-1"/>
      <inertia ixx="7.2541496e-4" ixy="0" ixz="0" iyy="8.3922834e-4" iyz="1.2781136e-4" izz="8.2201132e-4"/>
    </inertial>
    <collision>
      <origin rpy="0.0 0.0 0.0" xyz="0.0 0.0 0.0"/>
      <geometry>
        <mesh filename="package://alterego_robot/alterego_description/meshes/alterego_v3/collision/mteg102_head_201.stl" scale="0.001 0.001 0.001"/>
      </geometry>
    </collision>
  </link>
  <gazebo reference="head">
    <material>Gazebo/Grey</material>
    <selfCollide>false</selfCollide>
  </gazebo>
  <link name="head_curr">
    <inertial>
      <origin rpy="0 0 0" xyz=" 2.8406417e-5  -1.0608066e-7  -1.1037173e-5"/>
      <mass value="5.6999990e-4"/>
      <inertia ixx=" 0" ixy="0" ixz="0" iyy="0" iyz="0" izz="0"/>
    </inertial>
  </link>
  <joint name="head_to_head_curr" type="fixed">
    <!-- <origin xyz="83e-3 -0.5e-3  1006.5e-3" rpy="-1.57 0 -1.57" /> -->
    <origin rpy="-1.5707963 0 2.3561944" xyz="0 0 0"/>
    <parent link="head"/>
    <child link="head_curr"/>
  </joint>
  <joint name="base_to_front_kick_stand" type="revolute">
    <axis xyz="0 1 0"/>
    <limit effort="1000.0" lower="-0.523333333" upper="0" velocity="100.0"/>
    <origin rpy="0 0 0" xyz="30e-3 0 536e-3"/>
    <parent link="base"/>
    <child link="front_kick_stand"/>
  </joint>
  <link name="front_kick_stand">
    <visual>
      <material name="SoftLightBlue"/>
      <geometry>
        <mesh filename="package://alterego_robot/alterego_description/meshes/alterego_v3/visual/salv_v04.dae" scale="0.001 0.001 0.001"/>
      </geometry>
      <origin rpy="0 0 0" xyz="0 0 0"/>
    </visual>
    <inertial>
      <origin rpy="0 0 0" xyz="8.0677828e-2 -5.9076422e-4 -3.0690115e-1"/>
      <mass value="1.1203426"/>
      <inertia ixx="4.1808700e-2" ixy="4.0334806e-5" ixz="7.9033069e-3" iyy="4.3331012e-2" iyz="-1.7925920e-4" izz="1.6723708e-3"/>
    </inertial>
    <collision>
      <origin rpy="0 0 0" xyz="0 0 0"/>
      <geometry>
        <mesh filename="package://alterego_robot/alterego_description/meshes/alterego_v3/collision/salv_v04.stl" scale="0.001 0.001 0.001"/>
      </geometry>
    </collision>
  </link>
  <gazebo reference="front_kick_stand">
    <material>Gazebo/Grey</material>
    <selfCollide>false</selfCollide>
  </gazebo>
  <joint name="front_kick_stand_to_front_wheel" type="continuous">
    <axis xyz="0 0 1"/>
    <origin rpy="-1.5707963 0.1745327 3.1415927" xyz=" 168.487e-3 0 -610.010e-3"/>
    <parent link="front_kick_stand"/>
    <child link="front_wheel"/>
  </joint>
  <link name="front_wheel">
    <visual>
      <material name="wheel"/>
      <geometry>
        <mesh filename="package://alterego_robot/alterego_description/meshes/alterego_v3/visual/gyul50.dae" scale="0.001 0.001 0.001"/>
      </geometry>
      <origin rpy="0 0 0" xyz="0 0 0"/>
    </visual>
    <inertial>
      <origin rpy="0 0 0" xyz="0 0 0"/>
      <mass value="5.2450716e-2"/>
      <inertia ixx="9.6163023e-6" ixy="0" ixz="0" iyy="9.6163185e-6" iyz="0" izz="1.5742967e-5"/>
    </inertial>
    <collision>
      <origin rpy="0 0 0" xyz="0 0 0"/>
      <geometry>
        <mesh filename="package://alterego_robot/alterego_description/meshes/alterego_v3/collision/gyul50.stl" scale="0.001 0.001 0.001"/>
      </geometry>
    </collision>
  </link>
  <gazebo reference="front_wheel">
    <material>Gazebo/Grey</material>
  </gazebo>
  <joint name="base_to_back_kick_stand" type="revolute">
    <axis xyz="0 1 0"/>
    <limit effort="1000.0" lower="-0.523333333" upper="0" velocity="100.0"/>
    <origin rpy="0 0 3.1415927" xyz="-30e-3 0 536e-3"/>
    <parent link="base"/>
    <child link="back_kick_stand"/>
  </joint>
  <link name="back_kick_stand">
    <visual>
      <material name="SoftLightBlue"/>
      <geometry>
        <mesh filename="package://alterego_robot/alterego_description/meshes/alterego_v3/visual/salv_v04.dae" scale="0.001 0.001 0.001"/>
      </geometry>
      <origin rpy="0 0 0" xyz="0 0 0"/>
    </visual>
    <inertial>
      <origin rpy="0 0 0" xyz="8.0677828e-2 -5.9076422e-4 -3.0690115e-1"/>
      <mass value="1.1203426"/>
      <inertia ixx="4.1808700e-2" ixy="4.0334806e-5" ixz="7.9033069e-3" iyy="4.3331012e-2" iyz="-1.7925920e-4" izz="1.6723708e-3"/>
    </inertial>
    <collision>
      <origin rpy="0 0 0" xyz="0 0 0"/>
      <geometry>
        <mesh filename="package://alterego_robot/alterego_description/meshes/alterego_v3/collision/salv_v04.stl" scale="0.001 0.001 0.001"/>
      </geometry>
    </collision>
  </link>
  <gazebo reference="back_kick_stand">
    <material>Gazebo/Grey</material>
    <selfCollide>false</selfCollide>
  </gazebo>
  <joint name="back_kick_stand_to_back_wheel" type="continuous">
    <axis xyz="0 0 1"/>
    <origin rpy="-1.5707963 0.1745327 3.1415927" xyz=" 168.487e-3 0 -610.010e-3"/>
    <parent link="back_kick_stand"/>
    <child link="back_wheel"/>
  </joint>
  <link name="back_wheel">
    <visual>
      <material name="wheel"/>
      <geometry>
        <mesh filename="package://alterego_robot/alterego_description/meshes/alterego_v3/visual/gyul50.dae" scale="0.001 0.001 0.001"/>
      </geometry>
      <origin rpy="0 0 0" xyz="0 0 0"/>
    </visual>
    <inertial>
      <origin rpy="0 0 0" xyz="0 0 0"/>
      <mass value="5.2450716e-2"/>
      <inertia ixx="9.6163023e-6" ixy="0" ixz="0" iyy="9.6163185e-6" iyz="0" izz="1.5742967e-5"/>
    </inertial>
    <collision>
      <origin rpy="0 0 0" xyz="0 0 0"/>
      <geometry>
        <mesh filename="package://alterego_robot/alterego_description/meshes/alterego_v3/collision/gyul50.stl" scale="0.001 0.001 0.001"/>
      </geometry>
    </collision>
  </link>
  <gazebo reference="back_wheel">
    <material>Gazebo/Grey</material>
  </gazebo>
</robot>
