<?xml version="1.0" ?>
<!-- =================================================================================== -->
<!-- |    This document was autogenerated by xacro from ego_robot_gazebo_v2.urdf.xacro | -->
<!-- |    EDITING THIS FILE BY HAND IS NOT RECOMMENDED                                 | -->
<!-- =================================================================================== -->
<robot name="alterego">
  <material name="qbmove/flange">
    <color rgba="0.0 0.5 0.8 1.0"/>
  </material>
  <material name="qbmove/cube">
    <color rgba="0.35 0.35 0.35 1.0"/>
  </material>
  <material name="qbmove/shaft">
    <color rgba="0.8 0.8 0.8 1.0"/>
  </material>
  <material name="qbmove/default">
    <color rgba="0.35 0.35 0.35 1.0"/>
  </material>
  <material name="SoftBlue">
    <color rgba="0.0 0.0 0.8 0.9"/>
  </material>
  <material name="SoftLightBlue">
    <color rgba="0.0 0.4 1.0 1.0"/>
  </material>
  <material name="wheel">
    <color rgba="0.50 0.50 0.50 1.0"/>
  </material>
  <!-- IMU : -->
  <joint name="base_to_imu" type="fixed">
    <origin rpy="0 0 0" xyz="0 102.5e-3 24.25e-3"/>
    <parent link="base"/>
    <child link="imu"/>
  </joint>
  <link name="imu">
    <visual>
      <material name="qbmove/cube"/>
      <geometry>
        <mesh filename="package://alterego_robot/alterego_description/meshes/common/visual/mc_seg_imu_supp_1_100.dae" scale="0.001 0.001 0.001"/>
      </geometry>
      <origin rpy="0 0 0" xyz="0 0 0"/>
    </visual>
    <inertial>
      <origin rpy="0 0 0" xyz="7.5000002e-3 -2.4329396e-4  5.0246414e-4"/>
      <mass value="2.3770213e-3"/>
      <inertia ixx="0" ixy="0" ixz="0" iyy="0" iyz="0" izz="0"/>
    </inertial>
    <collision>
      <origin rpy="0 0 0" xyz="0 0 0"/>
      <geometry>
        <mesh filename="package://alterego_robot/alterego_description/meshes/common/collision/mc_seg_imu_supp_1_100.stl" scale="0.001 0.001 0.001"/>
      </geometry>
    </collision>
  </link>
  <!-- LASER : -->
  <joint name="base_to_laser" type="fixed">
    <origin rpy="0 0 -1.5707963" xyz="0 0 116e-3 "/>
    <parent link="base"/>
    <child link="laser"/>
  </joint>
  <link name="laser">
    <visual>
      <material name="qbmove/cube"/>
      <geometry>
        <mesh filename="package://alterego_robot/alterego_description/meshes/common/visual/rplidar_a2_slamtec.dae" scale="0.001 0.001 0.001"/>
      </geometry>
      <origin rpy="0 0 0" xyz="0 0 0"/>
    </visual>
    <inertial>
      <origin rpy="0 0 0" xyz=" -4.3709710e-4 0   1.8991442e-2"/>
      <mass value="2.0002622e-1"/>
      <inertia ixx=" 9.1569570e-5" ixy="0" ixz="0" iyy="9.0192290e-5" iyz="0" izz="1.2956170e-4"/>
    </inertial>
    <collision>
      <origin rpy="0 0 0" xyz="0 0 0"/>
      <geometry>
        <mesh filename="package://alterego_robot/alterego_description/meshes/common/collision/rplidar_a2_slamtec.stl" scale="0.001 0.001 0.001"/>
      </geometry>
    </collision>
  </link>
  <gazebo reference="laser">
    <material>Gazebo/Black</material>
  </gazebo>
  <!-- ZED : -->
  <joint name="head_to_camera" type="fixed">
    <origin rpy="-1.5707963 0 2.3561944" xyz="-87.9065e-3 21.6811e-3 -6.5e-3"/>
    <parent link="head"/>
    <child link="camera"/>
  </joint>
  <link name="camera">
    <visual>
      <material name="qbmove/cube"/>
      <geometry>
        <mesh filename="package://alterego_robot/alterego_description/meshes/common/visual/zedm.dae" scale="0.001 0.001 0.001"/>
      </geometry>
      <origin rpy="0 0 0" xyz="0 0 0"/>
    </visual>
    <inertial>
      <origin rpy="0 0 0" xyz=" -1.7967264e-2  8.9226986e-4  7.6630930e-6"/>
      <mass value="5.8888131e-2"/>
      <inertia ixx=" 0" ixy="0" ixz="0" iyy="0" iyz="0" izz="0"/>
    </inertial>
    <collision>
      <origin rpy="0 0 0" xyz="0 0 0"/>
      <geometry>
        <mesh filename="package://alterego_robot/alterego_description/meshes/common/collision/zedm.stl" scale="0.001 0.001 0.001"/>
      </geometry>
    </collision>
  </link>
  <!-- FRAME FOR PLUGIN  -->
  <!-- LEFT  -->
  <joint name="camera_to_left" type="fixed">
    <origin rpy="0 0 0" xyz="0 0.025 0"/>
    <parent link="camera"/>
    <child link="camera_left"/>
  </joint>
  <link name="camera_left"/>
  <!-- FRAME FOR PLUGIN  -->
  <!-- RIGHT  -->
  <joint name="camera_to_right" type="fixed">
    <origin rpy="0 0 0" xyz="0 -0.036 0"/>
    <parent link="camera"/>
    <child link="camera_right"/>
  </joint>
  <link name="camera_right"/>
  <!-- IMU : -->
  <joint name="head_to_realsense" type="fixed">
    <origin rpy="-1.5707963 0 2.3561944" xyz="-65.6725e-3 38.7425e-3 0"/>
    <parent link="head"/>
    <child link="realsense"/>
  </joint>
  <link name="realsense">
    <visual>
      <material name="qbmove/cube"/>
      <geometry>
        <mesh filename="package://alterego_robot/alterego_description/meshes/common/visual/intel_realsense_d415_old_asm.dae" scale="0.001 0.001 0.001"/>
      </geometry>
      <origin rpy="1.57 0 1.57" xyz="0 0 0"/>
    </visual>
    <inertial>
      <origin rpy="0 0 0" xyz=" 2.8406417e-3  -1.0608066e-4  -1.1037173e-2"/>
      <mass value="5.6999990e-2"/>
      <inertia ixx=" 0" ixy="0" ixz="0" iyy="0" iyz="0" izz="0"/>
    </inertial>
    <collision>
      <origin rpy="1.57 0 1.57" xyz="0 0 0"/>
      <geometry>
        <mesh filename="package://alterego_robot/alterego_description/meshes/common/collision/intel_realsense_d415_old_asm.stl" scale="0.001 0.001 0.001"/>
      </geometry>
    </collision>
  </link>
  <gazebo reference="realsense">
    <material>Gazebo/Black</material>
  </gazebo>
  <link name="fake_realsense">
    <inertial>
      <origin rpy="0 0 0" xyz=" 2.8406417e-5  -1.0608066e-7  -1.1037173e-5"/>
      <mass value="5.6999990e-4"/>
      <inertia ixx=" 0" ixy="0" ixz="0" iyy="0" iyz="0" izz="0"/>
    </inertial>
  </link>
  <joint name="depth_to_fakelink" type="fixed">
    <!-- <origin xyz="83e-3 -0.5e-3  1006.5e-3" rpy="-1.57 0 -1.57" /> -->
    <origin rpy="-1.57 0 -1.57" xyz="0 0 0"/>
    <parent link="realsense"/>
    <child link="fake_realsense"/>
  </joint>
  <!-- <xacro:include filename="$(find realsense2_description)/urdf/_d435.urdf.xacro" />
  <xacro:sensor_d435 name="d435" topics_ns="realsense" parent="realsense_link"
    publish_pointcloud="true">
    <origin xyz="0 0 0" rpy="1.57 -1.57 0" />
  </xacro:sensor_d435> -->
  <!-- JOINT -->
  <joint name="base_to_wheel_L" type="continuous">
    <axis xyz="0 0 1"/>
    <limit effort="22" velocity="1e16"/>
    <dynamics damping="5.2" friction="2.17"/>
    <origin rpy="0 -1.5707963 -1.5707963" xyz="0 277e-3 0"/>
    <parent link="base"/>
    <child link="wheel_L"/>
  </joint>
  <!-- LINK -->
  <link name="wheel_L">
    <visual>
      <material name="wheel"/>
      <geometry>
        <mesh filename="package://alterego_robot/alterego_description/meshes/common/visual/mteg100_varvel_gearbox.dae" scale="0.001 0.001 0.001"/>
      </geometry>
      <origin rpy="0 0 0" xyz="0 0 0"/>
    </visual>
    <inertial>
      <origin rpy="0 0 0" xyz="-9.3352926e-7 -1.6320810e-6 7.2612692e-4"/>
      <mass value="1.2175322"/>
      <inertia ixx="4.9769349e-3" ixy="0" ixz="0" iyy="4.9768680e-3" iyz="0" izz="8.8587376e-3"/>
    </inertial>
    <collision>
      <geometry>
        <cylinder length="0.07" radius="0.13"/>
      </geometry>
      <origin rpy="0 0 0" xyz="0 0 0"/>
    </collision>
  </link>
  <!-- GAZEBO REFERENCE -->
  <gazebo reference="wheel_L">
    <material>Gazebo/Grey</material>
    <selfCollide>false</selfCollide>
    <mu1 value="1.0"/>
    <mu2 value="1.0"/>
    <kp value="1e6"/>
    <kd value="1.0"/>
  </gazebo>
  <!-- JOINT -->
  <joint name="base_to_wheel_R" type="continuous">
    <axis xyz="0 0 1"/>
    <limit effort="22" velocity="1e16"/>
    <dynamics damping="5.2" friction="2.17"/>
    <origin rpy="0 -1.5707963 1.5707963" xyz="0 -277e-3 0"/>
    <parent link="base"/>
    <child link="wheel_R"/>
  </joint>
  <!-- LINK -->
  <link name="wheel_R">
    <visual>
      <material name="wheel"/>
      <geometry>
        <mesh filename="package://alterego_robot/alterego_description/meshes/common/visual/mteg100_varvel_gearbox.dae" scale="0.001 0.001 0.001"/>
      </geometry>
      <origin rpy="0 0 0" xyz="0 0 0"/>
    </visual>
    <inertial>
      <origin rpy="0 0 0" xyz="-9.3352926e-7 -1.6320810e-6 7.2612692e-4"/>
      <mass value="1.2175322"/>
      <inertia ixx="4.9769349e-3" ixy="0" ixz="0" iyy="4.9768680e-3" iyz="0" izz="8.8587376e-3"/>
    </inertial>
    <collision>
      <geometry>
        <cylinder length="0.07" radius="0.13"/>
      </geometry>
      <origin rpy="0 0 0" xyz="0 0 0"/>
    </collision>
  </link>
  <!-- GAZEBO REFERENCE -->
  <gazebo reference="wheel_R">
    <material>Gazebo/Grey</material>
    <selfCollide>false</selfCollide>
    <mu1 value="1.0"/>
    <mu2 value="1.0"/>
    <kp value="1e6"/>
    <kd value="1.0"/>
  </gazebo>
  <!-- Plugins  -->
  <gazebo>
    <plugin filename="libgazebo_ros_control.so" name="gazebo_ros_control">
      <robotNamespace>/wheels</robotNamespace>
      <robotSimType>gazebo_ros_control/DefaultRobotHWSim</robotSimType>
      <legacyModeNS>true</legacyModeNS>
    </plugin>
  </gazebo>
  <!--Trasmission-->
  <transmission name="tran1">
    <type>transmission_interface/SimpleTransmission</type>
    <joint name="base_to_wheel_L">
      <hardwareInterface>hardware_interface/EffortJointInterface</hardwareInterface>
    </joint>
    <actuator name="L_wheel_motor">
      <hardwareInterface>EffortJointInterface</hardwareInterface>
      <mechanicalReduction>1</mechanicalReduction>
    </actuator>
  </transmission>
  <transmission name="tran2">
    <type>transmission_interface/SimpleTransmission</type>
    <joint name="base_to_wheel_R">
      <hardwareInterface>hardware_interface/EffortJointInterface</hardwareInterface>
    </joint>
    <actuator name="R_wheel_motor">
      <hardwareInterface>EffortJointInterface</hardwareInterface>
      <mechanicalReduction>1</mechanicalReduction>
    </actuator>
  </transmission>
  <!-- Left Arm Actuator-->
  <gazebo>
    <plugin filename="libqbmove_plugin.so" name="compliant_act_head0">
      <joint>base_to_neck</joint>
      <operation_mode>5</operation_mode>
      <pub_eltau>false</pub_eltau>
      <pub_state>true</pub_state>
      <sub_ext_tau>false</sub_ext_tau>
      <namespace>left</namespace>
      <t_sample>0.01</t_sample>
      <spring_a1>11.0 </spring_a1>
      <spring_k1>0.02</spring_k1>
      <spring_a2>11.0</spring_a2>
      <spring_k2>0.02</spring_k2>
      <mot_1_tauMax>12.0</mot_1_tauMax>
      <mot_2_tauMax>12.0</mot_2_tauMax>
    </plugin>
  </gazebo>
  <gazebo>
    <plugin filename="libqbmove_plugin.so" name="compliant_act_left_j1">
      <joint>base_to_left_shoulder_flange</joint>
      <operation_mode>5</operation_mode>
      <pub_eltau>false</pub_eltau>
      <pub_state>true</pub_state>
      <sub_ext_tau>false</sub_ext_tau>
      <namespace>left</namespace>
      <t_sample>0.01</t_sample>
      <spring_a1>11.0 </spring_a1>
      <spring_k1>0.02</spring_k1>
      <spring_a2>11.0</spring_a2>
      <spring_k2>0.02</spring_k2>
      <mot_1_tauMax>12.0</mot_1_tauMax>
      <mot_2_tauMax>12.0</mot_2_tauMax>
    </plugin>
  </gazebo>
  <gazebo>
    <plugin filename="libqbmove_plugin.so" name="compliant_act_left_j2">
      <joint>left_shoulder_cube_to_left_arm_flange</joint>
      <operation_mode>5</operation_mode>
      <pub_eltau>false</pub_eltau>
      <pub_state>true</pub_state>
      <sub_ext_tau>false</sub_ext_tau>
      <namespace>left</namespace>
      <t_sample>0.01</t_sample>
      <spring_a1>11.0 </spring_a1>
      <spring_k1>0.02</spring_k1>
      <spring_a2>11.0</spring_a2>
      <spring_k2>0.02</spring_k2>
      <mot_1_tauMax>12.0</mot_1_tauMax>
      <mot_2_tauMax>12.0</mot_2_tauMax>
    </plugin>
  </gazebo>
  <gazebo>
    <plugin filename="libqbmove_plugin.so" name="compliant_act_left_j3">
      <joint>left_arm_cube_to_left_elbow_flange</joint>
      <operation_mode>5</operation_mode>
      <pub_eltau>false</pub_eltau>
      <pub_state>true</pub_state>
      <sub_ext_tau>false</sub_ext_tau>
      <namespace>left</namespace>
      <t_sample>0.01</t_sample>
      <spring_a1>11.0 </spring_a1>
      <spring_k1>0.02</spring_k1>
      <spring_a2>11.0</spring_a2>
      <spring_k2>0.02</spring_k2>
      <mot_1_tauMax>12.0</mot_1_tauMax>
      <mot_2_tauMax>12.0</mot_2_tauMax>
    </plugin>
  </gazebo>
  <gazebo>
    <plugin filename="libqbmove_plugin.so" name="compliant_act_left_j4">
      <joint>left_elbow_cube_to_left_forearm_flange</joint>
      <operation_mode>5</operation_mode>
      <pub_eltau>false</pub_eltau>
      <pub_state>true</pub_state>
      <sub_ext_tau>false</sub_ext_tau>
      <namespace>left</namespace>
      <t_sample>0.01</t_sample>
      <spring_a1>11.0 </spring_a1>
      <spring_k1>0.02</spring_k1>
      <spring_a2>11.0</spring_a2>
      <spring_k2>0.02</spring_k2>
      <mot_1_tauMax>12.0</mot_1_tauMax>
      <mot_2_tauMax>12.0</mot_2_tauMax>
    </plugin>
  </gazebo>
  <gazebo>
    <plugin filename="libqbmove_plugin.so" name="compliant_act_left_j5">
      <joint>left_forearm_cube_to_left_wrist_flange</joint>
      <operation_mode>5</operation_mode>
      <pub_eltau>false</pub_eltau>
      <pub_state>true</pub_state>
      <sub_ext_tau>false</sub_ext_tau>
      <namespace>left</namespace>
      <t_sample>0.01</t_sample>
      <spring_a1>11.0 </spring_a1>
      <spring_k1>0.02</spring_k1>
      <spring_a2>11.0</spring_a2>
      <spring_k2>0.02</spring_k2>
      <mot_1_tauMax>12.0</mot_1_tauMax>
      <mot_2_tauMax>12.0</mot_2_tauMax>
    </plugin>
  </gazebo>
  <!-- Right Arm Actuator-->
  <gazebo>
    <plugin filename="libqbmove_plugin.so" name="compliant_act_head1">
      <joint>neck_to_neck_cube</joint>
      <operation_mode>5</operation_mode>
      <pub_eltau>false</pub_eltau>
      <pub_state>true</pub_state>
      <sub_ext_tau>false</sub_ext_tau>
      <namespace>right</namespace>
      <t_sample>0.01</t_sample>
      <spring_a1>11.0 </spring_a1>
      <spring_k1>0.02</spring_k1>
      <spring_a2>11.0</spring_a2>
      <spring_k2>0.02</spring_k2>
      <mot_1_tauMax>12.0</mot_1_tauMax>
      <mot_2_tauMax>12.0</mot_2_tauMax>
    </plugin>
  </gazebo>
  <gazebo>
    <plugin filename="libqbmove_plugin.so" name="compliant_act_right_j7">
      <joint>base_to_right_shoulder_flange</joint>
      <operation_mode>5</operation_mode>
      <pub_eltau>false</pub_eltau>
      <pub_state>true</pub_state>
      <sub_ext_tau>false</sub_ext_tau>
      <namespace>right</namespace>
      <t_sample>0.01</t_sample>
      <spring_a1>11.0 </spring_a1>
      <spring_k1>0.02</spring_k1>
      <spring_a2>11.0</spring_a2>
      <spring_k2>0.02</spring_k2>
      <mot_1_tauMax>12.0</mot_1_tauMax>
      <mot_2_tauMax>12.0</mot_2_tauMax>
    </plugin>
  </gazebo>
  <gazebo>
    <plugin filename="libqbmove_plugin.so" name="compliant_act_right_j8">
      <joint>right_shoulder_cube_to_right_arm_flange</joint>
      <operation_mode>5</operation_mode>
      <pub_eltau>false</pub_eltau>
      <pub_state>true</pub_state>
      <sub_ext_tau>false</sub_ext_tau>
      <namespace>right</namespace>
      <t_sample>0.01</t_sample>
      <spring_a1>11.0 </spring_a1>
      <spring_k1>0.02</spring_k1>
      <spring_a2>11.0</spring_a2>
      <spring_k2>0.02</spring_k2>
      <mot_1_tauMax>12.0</mot_1_tauMax>
      <mot_2_tauMax>12.0</mot_2_tauMax>
    </plugin>
  </gazebo>
  <gazebo>
    <plugin filename="libqbmove_plugin.so" name="compliant_act_right_j9">
      <joint>right_arm_cube_to_right_elbow_flange</joint>
      <operation_mode>5</operation_mode>
      <pub_eltau>false</pub_eltau>
      <pub_state>true</pub_state>
      <sub_ext_tau>false</sub_ext_tau>
      <namespace>right</namespace>
      <t_sample>0.01</t_sample>
      <spring_a1>11.0 </spring_a1>
      <spring_k1>0.02</spring_k1>
      <spring_a2>11.0</spring_a2>
      <spring_k2>0.02</spring_k2>
      <mot_1_tauMax>12.0</mot_1_tauMax>
      <mot_2_tauMax>12.0</mot_2_tauMax>
    </plugin>
  </gazebo>
  <gazebo>
    <plugin filename="libqbmove_plugin.so" name="compliant_act_right_j10">
      <joint>right_elbow_cube_to_right_forearm_flange</joint>
      <operation_mode>5</operation_mode>
      <pub_eltau>false</pub_eltau>
      <pub_state>true</pub_state>
      <sub_ext_tau>false</sub_ext_tau>
      <namespace>right</namespace>
      <t_sample>0.01</t_sample>
      <spring_a1>11.0 </spring_a1>
      <spring_k1>0.02</spring_k1>
      <spring_a2>11.0</spring_a2>
      <spring_k2>0.02</spring_k2>
      <mot_1_tauMax>12.0</mot_1_tauMax>
      <mot_2_tauMax>12.0</mot_2_tauMax>
    </plugin>
  </gazebo>
  <gazebo>
    <plugin filename="libqbmove_plugin.so" name="compliant_act_right_j11">
      <joint>right_forearm_cube_to_right_wrist_flange</joint>
      <operation_mode>5</operation_mode>
      <pub_eltau>false</pub_eltau>
      <pub_state>true</pub_state>
      <sub_ext_tau>false</sub_ext_tau>
      <namespace>right</namespace>
      <t_sample>0.01</t_sample>
      <spring_a1>11.0 </spring_a1>
      <spring_k1>0.02</spring_k1>
      <spring_a2>11.0</spring_a2>
      <spring_k2>0.02</spring_k2>
      <mot_1_tauMax>12.0</mot_1_tauMax>
      <mot_2_tauMax>12.0</mot_2_tauMax>
    </plugin>
  </gazebo>
  <gazebo reference="imu">
    <gravity>true</gravity>
    <sensor name="imu_sensor" type="imu">
      <always_on>true</always_on>
      <update_rate>500</update_rate>
      <visualize>true</visualize>
      <topic>__default_topic__</topic>
      <plugin filename="libgazebo_ros_imu_sensor.so" name="imu_plugin">
        <topicName>imu</topicName>
        <bodyName>imu_1</bodyName>
        <updateRateHZ>10.0</updateRateHZ>
        <gaussianNoise>0.0</gaussianNoise>
        <xyzOffset>0 0 0</xyzOffset>
        <rpyOffset>0 0 0</rpyOffset>
        <frameName>imu_1</frameName>
      </plugin>
      <pose>0 0 0 0 0 0</pose>
    </sensor>
  </gazebo>
  <link name="world"/>
  <joint name="world_to_trans_x" type="prismatic">
    <parent link="world"/>
    <child link="trans_x"/>
    <axis xyz="1 0 0"/>
    <limit effort="100000" lower="-100000" upper="100000" velocity="100000"/>
  </joint>
  <link name="trans_x"/>
  <joint name="trans_x_to_trans_y" type="prismatic">
    <parent link="trans_x"/>
    <child link="trans_y"/>
    <axis xyz="0 1 0"/>
    <limit effort="100000" lower="-100000" upper="100000" velocity="100000"/>
  </joint>
  <link name="trans_y"/>
  <joint name="trans_y_to_fixed_z" type="fixed">
    <origin rpy="0.0 0.0 0.0" xyz="0 0 0.13"/>
    <parent link="trans_y"/>
    <child link="trans_z"/>
  </joint>
  <link name="trans_z"/>
  <joint name="trans_z_to_rot_z" type="continuous">
    <parent link="trans_z"/>
    <child link="rot_z"/>
    <axis xyz="0 0 1"/>
  </joint>
  <link name="rot_z"/>
  <joint name="rot_z_to_rot_y" type="continuous">
    <parent link="rot_z"/>
    <child link="rot_y"/>
    <axis xyz="0 1 0"/>
  </joint>
  <link name="rot_y"/>
  <joint name="rot_y_base" type="fixed">
    <origin rpy="0.0 0.0 0.0" xyz="0 0 0"/>
    <parent link="rot_y"/>
    <child link="base"/>
  </joint>
  <!-- <link name="world">
	</link>

	<joint name="world_to_base" type="fixed">
		<origin xyz="0 0 0" rpy="0 0 0" />
		<parent link="world" />
		<child link="base" />
	</joint> -->
  <link name="base">
    <visual>
      <material name="SoftLightBlue"/>
      <geometry>
        <mesh filename="package://alterego_robot/alterego_description/meshes/alterego_v2/visual/body.dae" scale="0.001 0.001 0.001"/>
      </geometry>
      <origin rpy="0 0 0" xyz="0 0 0"/>
    </visual>
    <inertial>
      <origin rpy="0 0 0" xyz="-1.2011052e-5 1.1480563e-3 2.4548879e-1"/>
      <mass value="2.0831010e+1"/>
      <inertia ixx=" 1.6382953" ixy="-4.9516366e-4" ixz="-8.8000450e-3" iyy="1.4399643" iyz="4.3295684e-3" izz="2.5676989e-1"/>
    </inertial>
    <collision>
      <geometry>
        <mesh filename="package://alterego_robot/alterego_description/meshes/alterego_v2/collision/body.stl" scale="0.001 0.001 0.001"/>
      </geometry>
      <origin rpy="0 0 0" xyz="0 0 0"/>
    </collision>
  </link>
  <link name="torso">
	</link>
  <joint name="base_to_torso" type="fixed">
    <origin rpy="0 0 0" xyz="-0.017 0 0.872"/>
    <parent link="base"/>
    <child link="torso"/>
  </joint>
  <gazebo reference="base">
    <material>Gazebo/SkyBlue</material>
    <selfCollide>false</selfCollide>
  </gazebo>
  <!-- JOINT -->
  <joint name="base_to_neck" type="revolute">
    <axis xyz="0 0 1"/>
    <limit effort="1000.0" lower="-3.14" upper="3.14" velocity="0.5"/>
    <origin rpy="0 -1.5707963 1.5707963" xyz="0 0 753.5e-3"/>
    <dynamics damping="0.065" friction="0.025"/>
    <parent link="base"/>
    <child link="neck"/>
  </joint>
  <!-- LINK -->
  <link name="neck">
    <visual>
      <material name="qbmove/flange"/>
      <geometry>
        <mesh filename="package://alterego_robot/alterego_description/meshes/common/visual/la_flg_asm_c_wb_blu.dae" scale="0.001 0.001 0.001"/>
      </geometry>
      <origin rpy="0 0 0" xyz="0 0 0"/>
    </visual>
    <inertial>
      <origin rpy="0 0 0" xyz="-7.3157519e-3 2.3015782e-2 0"/>
      <mass value="8.6640591e-2"/>
      <inertia ixx="7.8695858e-5" ixy="1.8826444e-5" ixz="0" iyy="1.0265668e-4" iyz="0" izz="1.3810438e-4"/>
    </inertial>
    <collision>
      <origin rpy="0 0 0" xyz="0 0 0"/>
      <geometry>
        <mesh filename="package://alterego_robot/alterego_description/meshes/common/collision/la_flg_asm_c_wb_blu.stl" scale="0.001 0.001 0.001"/>
      </geometry>
    </collision>
  </link>
  <!-- GAZEBO REFERENCE -->
  <gazebo reference="neck">
    <material>Gazebo/SkyBlue</material>
    <selfCollide>false</selfCollide>
  </gazebo>
  <!-- JOINT -->
  <joint name="neck_to_neck_cube" type="revolute">
    <axis xyz="0 0 -1"/>
    <limit effort="1000.0" lower="-3.14" upper="3.14" velocity="0.5"/>
    <dynamics damping="0.065" friction="0.025"/>
    <origin rpy="0 0 2.356195 " xyz="0 0 0.5e-3"/>
    <parent link="neck"/>
    <child link="neck_cube"/>
  </joint>
  <!-- LINK -->
  <link name="neck_cube">
    <visual>
      <material name="qbmove/cube"/>
      <geometry>
        <mesh filename="package://alterego_robot/alterego_description/meshes/common/visual/qb_move_advanced_for_mate.dae" scale="0.001 0.001 0.001"/>
      </geometry>
      <origin rpy="0 0 0" xyz="0 0 0"/>
    </visual>
    <inertial>
      <origin rpy="0 0 0" xyz="-9.5664949e-5 -1.6749134e-5  1.3880927e-3"/>
      <mass value="4.5418805e-1"/>
      <inertia ixx="1.7978900e-4" ixy="0" ixz="0" iyy="1.7806823e-4" iyz="0" izz="1.6882624e-4"/>
    </inertial>
    <collision>
      <origin rpy="0.0 0.0 0.0" xyz="0.0 0.0 0.0"/>
      <geometry>
        <box size="0.07 0.07 0.07"/>
      </geometry>
    </collision>
  </link>
  <!-- GAZEBO REFERENCE -->
  <gazebo reference="neck_cube">
    <material>Gazebo/Grey</material>
    <selfCollide>false</selfCollide>
  </gazebo>
  <joint name="neck_cube_to_head" type="fixed">
    <origin rpy="0.0 0.0 0.0" xyz="0 0 0.0"/>
    <parent link="neck_cube"/>
    <child link="head"/>
  </joint>
  <link name="head">
    <visual>
      <material name="qbmove/cube"/>
      <geometry>
        <mesh filename="package://alterego_robot/alterego_description/meshes/alterego_v2/visual/mteg102_head.dae" scale="0.001 0.001 0.001"/>
      </geometry>
      <origin rpy="0 0 0" xyz="0 0 0"/>
    </visual>
    <inertial>
      <origin rpy="0 0 0" xyz="-5.7289026e-2 -2.2846699e-2  -2.3567538e-3"/>
      <mass value="3.1797228e-1"/>
      <inertia ixx="8.0284197e-4" ixy="0" ixz="0" iyy="6.0074469e-4" iyz="1.7864454e-5" izz="5.6711386e-4"/>
    </inertial>
    <collision>
      <origin rpy="0.0 0.0 0.0" xyz="0.0 0.0 0.0"/>
      <geometry>
        <mesh filename="package://alterego_robot/alterego_description/meshes/alterego_v2/collision/mteg102_head.stl" scale="0.001 0.001 0.001"/>
      </geometry>
    </collision>
  </link>
  <gazebo reference="head">
    <material>Gazebo/Grey</material>
    <selfCollide>false</selfCollide>
  </gazebo>
  <!-- JOINT -->
  <joint name="base_to_left_shoulder_flange" type="revolute">
    <axis xyz="0 0 1"/>
    <limit effort="1000.0" lower="-3.14" upper="3.14" velocity="0.5"/>
    <origin rpy="-0.1745345 -1.3962633 -1.5707948" xyz="16.9617e-3 154.989e-3 669.737e-3"/>
    <dynamics damping="0.065" friction="0.025"/>
    <parent link="base"/>
    <child link="left_shoulder_flange"/>
  </joint>
  <!-- LINK -->
  <link name="left_shoulder_flange">
    <visual>
      <material name="qbmove/flange"/>
      <geometry>
        <mesh filename="package://alterego_robot/alterego_description/meshes/common/visual/la_flg_asm_flat_blu.dae" scale="0.001 0.001 0.001"/>
      </geometry>
      <origin rpy="0 0 0" xyz="0 0 0"/>
    </visual>
    <inertial>
      <origin rpy="0 0 0" xyz="-8.0511890e-5 0 6.1371397e-4"/>
      <mass value="4.1898263e-02"/>
      <inertia ixx="1.5773084e-5" ixy="0" ixz="0" iyy="2.1026644e-5" iyz="0" izz="3.6312308e-5"/>
    </inertial>
    <collision>
      <origin rpy="0 0 0" xyz="0 0 0"/>
      <geometry>
        <mesh filename="package://alterego_robot/alterego_description/meshes/common/collision/la_flg_asm_flat_blu.stl" scale="0.001 0.001 0.001"/>
      </geometry>
    </collision>
  </link>
  <!-- GAZEBO REFERENCE -->
  <gazebo reference="left_shoulder_flange">
    <material>Gazebo/SkyBlue</material>
    <selfCollide>false</selfCollide>
  </gazebo>
  <!-- JOINT -->
  <joint name="left_shoulder_flange_to_left_shoulder_cube" type="fixed">
    <origin rpy="1.5707963 0 3.1415927" xyz="0 0 37e-3"/>
    <parent link="left_shoulder_flange"/>
    <child link="left_shoulder_cube"/>
  </joint>
  <!-- LINK -->
  <link name="left_shoulder_cube">
    <visual>
      <material name="qbmove/cube"/>
      <geometry>
        <mesh filename="package://alterego_robot/alterego_description/meshes/common/visual/qb_move_advanced_for_mate.dae" scale="0.001 0.001 0.001"/>
      </geometry>
      <origin rpy="0 0 0" xyz="0 0 0"/>
    </visual>
    <inertial>
      <origin rpy="0 0 0" xyz="-9.5664949e-5 -1.6749134e-5  1.3880927e-3"/>
      <mass value="4.5418805e-1"/>
      <inertia ixx="1.7978900e-4" ixy="0" ixz="0" iyy="1.7806823e-4" iyz="0" izz="1.6882624e-4"/>
    </inertial>
    <collision>
      <origin rpy="0.0 0.0 0.0" xyz="0.0 0.0 0.0"/>
      <geometry>
        <box size="0.07 0.07 0.07"/>
      </geometry>
    </collision>
  </link>
  <!-- GAZEBO REFERENCE -->
  <gazebo reference="left_shoulder_cube">
    <material>Gazebo/Grey</material>
    <selfCollide>false</selfCollide>
  </gazebo>
  <!-- JOINT -->
  <joint name="left_shoulder_cube_to_left_arm_flange" type="revolute">
    <axis xyz="0 0 1"/>
    <limit effort="1000.0" lower="-3.14" upper="3.14" velocity="0.5"/>
    <origin rpy="0 0 3.1415927" xyz="0 0 -0.5e-3"/>
    <dynamics damping="0.065" friction="0.025"/>
    <parent link="left_shoulder_cube"/>
    <child link="left_arm_flange"/>
  </joint>
  <!-- LINK -->
  <link name="left_arm_flange">
    <visual>
      <material name="qbmove/flange"/>
      <geometry>
        <mesh filename="package://alterego_robot/alterego_description/meshes/common/visual/la_flg_asm_c_wb_blu.dae" scale="0.001 0.001 0.001"/>
      </geometry>
      <origin rpy="0 0 0" xyz="0 0 0"/>
    </visual>
    <inertial>
      <origin rpy="0 0 0" xyz="-7.3157519e-3 2.3015782e-2 0"/>
      <mass value="8.6640591e-2"/>
      <inertia ixx="7.8695858e-5" ixy="1.8826444e-5" ixz="0" iyy="1.0265668e-4" iyz="0" izz="1.3810438e-4"/>
    </inertial>
    <collision>
      <origin rpy="0 0 0" xyz="0 0 0"/>
      <geometry>
        <mesh filename="package://alterego_robot/alterego_description/meshes/common/collision/la_flg_asm_c_wb_blu.stl" scale="0.001 0.001 0.001"/>
      </geometry>
    </collision>
  </link>
  <!-- GAZEBO REFERENCE -->
  <gazebo reference="left_arm_flange">
    <material>Gazebo/SkyBlue</material>
    <selfCollide>false</selfCollide>
  </gazebo>
  <!-- JOINT -->
  <joint name="left_arm_flange_to_left_arm_cube" type="fixed">
    <origin rpy="0 1.5707963 3.1415927" xyz="-90e-3 0 0"/>
    <parent link="left_arm_flange"/>
    <child link="left_arm_cube"/>
  </joint>
  <!-- LINK -->
  <link name="left_arm_cube">
    <visual>
      <material name="qbmove/cube"/>
      <geometry>
        <mesh filename="package://alterego_robot/alterego_description/meshes/common/visual/qb_move_advanced_for_mate.dae" scale="0.001 0.001 0.001"/>
      </geometry>
      <origin rpy="0 0 0" xyz="0 0 0"/>
    </visual>
    <inertial>
      <origin rpy="0 0 0" xyz="-9.5664949e-5 -1.6749134e-5  1.3880927e-3"/>
      <mass value="4.5418805e-1"/>
      <inertia ixx="1.7978900e-4" ixy="0" ixz="0" iyy="1.7806823e-4" iyz="0" izz="1.6882624e-4"/>
    </inertial>
    <collision>
      <origin rpy="0.0 0.0 0.0" xyz="0.0 0.0 0.0"/>
      <geometry>
        <box size="0.07 0.07 0.07"/>
      </geometry>
    </collision>
  </link>
  <!-- GAZEBO REFERENCE -->
  <gazebo reference="left_arm_cube">
    <material>Gazebo/Grey</material>
    <selfCollide>false</selfCollide>
  </gazebo>
  <!-- JOINT -->
  <joint name="left_arm_cube_to_left_elbow_flange" type="revolute">
    <axis xyz="0 0 1"/>
    <limit effort="1000.0" lower="-3.14" upper="3.14" velocity="0.5"/>
    <origin rpy="0 0 1.5707963" xyz="0 0 40.5e-3"/>
    <dynamics damping="0.065" friction="0.025"/>
    <parent link="left_arm_cube"/>
    <child link="left_elbow_flange"/>
  </joint>
  <!-- LINK -->
  <link name="left_elbow_flange">
    <visual>
      <material name="qbmove/flange"/>
      <geometry>
        <mesh filename="package://alterego_robot/alterego_description/meshes/common/visual/la_flg_asm_flat_blu.dae" scale="0.001 0.001 0.001"/>
      </geometry>
      <origin rpy="0 0 0" xyz="0 0 0"/>
    </visual>
    <inertial>
      <origin rpy="0 0 0" xyz="-8.0511890e-5 0 6.1371397e-4"/>
      <mass value="4.1898263e-02"/>
      <inertia ixx="1.5773084e-5" ixy="0" ixz="0" iyy="2.1026644e-5" iyz="0" izz="3.6312308e-5"/>
    </inertial>
    <collision>
      <origin rpy="0 0 0" xyz="0 0 0"/>
      <geometry>
        <mesh filename="package://alterego_robot/alterego_description/meshes/common/collision/la_flg_asm_flat_blu.stl" scale="0.001 0.001 0.001"/>
      </geometry>
    </collision>
  </link>
  <!-- GAZEBO REFERENCE -->
  <gazebo reference="left_elbow_flange">
    <material>Gazebo/SkyBlue</material>
    <selfCollide>false</selfCollide>
  </gazebo>
  <!-- JOINT -->
  <joint name="left_elbow_flange_to_left_elbow_cube" type="fixed">
    <origin rpy="-1.5707963 0 -1.5707963" xyz="0 0 37.0e-3"/>
    <parent link="left_elbow_flange"/>
    <child link="left_elbow_cube"/>
  </joint>
  <!-- LINK -->
  <link name="left_elbow_cube">
    <visual>
      <material name="qbmove/cube"/>
      <geometry>
        <mesh filename="package://alterego_robot/alterego_description/meshes/common/visual/qb_move_advanced_for_mate.dae" scale="0.001 0.001 0.001"/>
      </geometry>
      <origin rpy="0 0 0" xyz="0 0 0"/>
    </visual>
    <inertial>
      <origin rpy="0 0 0" xyz="-9.5664949e-5 -1.6749134e-5  1.3880927e-3"/>
      <mass value="4.5418805e-1"/>
      <inertia ixx="1.7978900e-4" ixy="0" ixz="0" iyy="1.7806823e-4" iyz="0" izz="1.6882624e-4"/>
    </inertial>
    <collision>
      <origin rpy="0.0 0.0 0.0" xyz="0.0 0.0 0.0"/>
      <geometry>
        <box size="0.07 0.07 0.07"/>
      </geometry>
    </collision>
  </link>
  <!-- GAZEBO REFERENCE -->
  <gazebo reference="left_elbow_cube">
    <material>Gazebo/Grey</material>
    <selfCollide>false</selfCollide>
  </gazebo>
  <!-- JOINT -->
  <joint name="left_elbow_cube_to_left_forearm_flange" type="revolute">
    <axis xyz="0 0 1"/>
    <limit effort="1000.0" lower="-3.14" upper="3.14" velocity="0.5"/>
    <origin rpy="0 0 1.5707963" xyz="0 0 -0.5e-3"/>
    <dynamics damping="0.065" friction="0.025"/>
    <parent link="left_elbow_cube"/>
    <child link="left_forearm_flange"/>
  </joint>
  <!-- LINK -->
  <link name="left_forearm_flange">
    <visual>
      <material name="qbmove/flange"/>
      <geometry>
        <mesh filename="package://alterego_robot/alterego_description/meshes/common/visual/la_flg_asm_c_wb_blu.dae" scale="0.001 0.001 0.001"/>
      </geometry>
      <origin rpy="0 0 0" xyz="0 0 0"/>
    </visual>
    <inertial>
      <origin rpy="0 0 0" xyz="-7.3157519e-3 2.3015782e-2 0"/>
      <mass value="8.6640591e-2"/>
      <inertia ixx="7.8695858e-5" ixy="1.8826444e-5" ixz="0" iyy="1.0265668e-4" iyz="0" izz="1.3810438e-4"/>
    </inertial>
    <collision>
      <origin rpy="0 0 0" xyz="0 0 0"/>
      <geometry>
        <mesh filename="package://alterego_robot/alterego_description/meshes/common/collision/la_flg_asm_c_wb_blu.stl" scale="0.001 0.001 0.001"/>
      </geometry>
    </collision>
  </link>
  <!-- GAZEBO REFERENCE -->
  <gazebo reference="left_forearm_flange">
    <material>Gazebo/SkyBlue</material>
    <selfCollide>false</selfCollide>
  </gazebo>
  <!-- JOINT -->
  <joint name="left_forearm_flange_to_left_forearm_cube" type="fixed">
    <origin rpy="1.5707963 0 -1.5707963" xyz="-90.0e-3 0 0"/>
    <parent link="left_forearm_flange"/>
    <child link="left_forearm_cube"/>
  </joint>
  <!-- LINK -->
  <link name="left_forearm_cube">
    <visual>
      <material name="qbmove/cube"/>
      <geometry>
        <mesh filename="package://alterego_robot/alterego_description/meshes/common/visual/qb_move_advanced_for_mate.dae" scale="0.001 0.001 0.001"/>
      </geometry>
      <origin rpy="0 0 0" xyz="0 0 0"/>
    </visual>
    <inertial>
      <origin rpy="0 0 0" xyz="-9.5664949e-5 -1.6749134e-5  1.3880927e-3"/>
      <mass value="4.5418805e-1"/>
      <inertia ixx="1.7978900e-4" ixy="0" ixz="0" iyy="1.7806823e-4" iyz="0" izz="1.6882624e-4"/>
    </inertial>
    <collision>
      <origin rpy="0.0 0.0 0.0" xyz="0.0 0.0 0.0"/>
      <geometry>
        <box size="0.07 0.07 0.07"/>
      </geometry>
    </collision>
  </link>
  <!-- GAZEBO REFERENCE -->
  <gazebo reference="left_forearm_cube">
    <material>Gazebo/Grey</material>
    <selfCollide>false</selfCollide>
  </gazebo>
  <!-- JOINT -->
  <joint name="left_forearm_cube_to_left_wrist_flange" type="revolute">
    <axis xyz="0 0 1"/>
    <limit effort="1000.0" lower="-3.14" upper="3.14" velocity="0.5"/>
    <origin rpy="0 0 -1.5707963" xyz="0 0 40.5e-3"/>
    <dynamics damping="0.065" friction="0.025"/>
    <parent link="left_forearm_cube"/>
    <child link="left_wrist_flange"/>
  </joint>
  <!-- LINK -->
  <link name="left_wrist_flange">
    <visual>
      <material name="qbmove/flange"/>
      <geometry>
        <mesh filename="package://alterego_robot/alterego_description/meshes/common/visual/la_flg_asm_flat_blu.dae" scale="0.001 0.001 0.001"/>
      </geometry>
      <origin rpy="0 0 0" xyz="0 0 0"/>
    </visual>
    <inertial>
      <origin rpy="0 0 0" xyz="-8.0511890e-5 0 6.1371397e-4"/>
      <mass value="4.1898263e-02"/>
      <inertia ixx="1.5773084e-5" ixy="0" ixz="0" iyy="2.1026644e-5" iyz="0" izz="3.6312308e-5"/>
    </inertial>
    <collision>
      <origin rpy="0 0 0" xyz="0 0 0"/>
      <geometry>
        <mesh filename="package://alterego_robot/alterego_description/meshes/common/collision/la_flg_asm_flat_blu.stl" scale="0.001 0.001 0.001"/>
      </geometry>
    </collision>
  </link>
  <!-- GAZEBO REFERENCE -->
  <gazebo reference="left_wrist_flange">
    <material>Gazebo/SkyBlue</material>
    <selfCollide>false</selfCollide>
  </gazebo>
  <!-- JOINT -->
  <joint name="left_wrist_flange_to_left_forearm_hand_flange" type="fixed">
    <origin rpy="0 0 0" xyz="0 0 4e-3"/>
    <parent link="left_wrist_flange"/>
    <child link="left_forearm_hand_flange"/>
  </joint>
  <!-- LINK -->
  <link name="left_forearm_hand_flange">
    <visual>
      <material name="qbmove/flange"/>
      <geometry>
        <mesh filename="package://alterego_robot/alterego_description/meshes/alterego_v2/visual/mc_wr_abs_qb_adv_301.dae" scale="0.001 0.001 0.001"/>
      </geometry>
      <origin rpy="0 0 0" xyz="0 0 0"/>
    </visual>
    <inertial>
      <origin rpy="0 0 0" xyz="3.0876986e-4 7.1294237e-5 6.7729239e-3"/>
      <mass value="3.4805486e-2"/>
      <inertia ixx="1.5814995e-5" ixy="0" ixz="0" iyy="1.1610747e-5" iyz="0" izz="2.5935426e-5"/>
    </inertial>
    <collision>
      <origin rpy="0 0 0" xyz="0 0 0"/>
      <geometry>
        <mesh filename="package://alterego_robot/alterego_description/meshes/alterego_v2/collision/mc_wr_abs_qb_adv_301.stl" scale="0.001 0.001 0.001"/>
      </geometry>
    </collision>
  </link>
  <!-- GAZEBO REFERENCE -->
  <gazebo reference="left_forearm_hand_flange">
    <material>Gazebo/Grey</material>
    <selfCollide>false</selfCollide>
  </gazebo>
  <!-- JOINT -->
  <joint name="left_forearm_hand_flange_to_left_hand" type="fixed">
    <axis xyz="0 0 1"/>
    <limit effort="1000.0" lower="-3.14" upper="3.14" velocity="0.5"/>
    <origin rpy="1.571355 0 0" xyz="3.3e-3 1.01693e-3 2.80899e-3"/>
    <parent link="left_forearm_hand_flange"/>
    <child link="left_hand"/>
  </joint>
  <!-- LINK -->
  <link name="left_hand">
    <visual>
      <material name="qbmove/cube"/>
      <geometry>
        <mesh filename="package://alterego_robot/alterego_description/meshes/common/visual/softhand_3_sx_urdf.dae" scale="0.001 0.001 0.001"/>
      </geometry>
      <origin rpy="0 0 0" xyz="0 0 0"/>
    </visual>
    <inertial>
      <origin rpy="0 0 0" xyz="4.1728393e-3  6.3287667e-2 6.0659797e-3"/>
      <mass value="2.9013125e-1"/>
      <inertia ixx="5.6377846e-4" ixy="-2.5891425e-5" ixz="-1.0142109e-5" iyy="1.4989796e-4" iyz="5.9361645e-6" izz="4.4769789e-4"/>
    </inertial>
    <collision>
      <material name="qbmove/cube"/>
      <geometry>
        <mesh filename="package://alterego_robot/alterego_description/meshes/common/collision/softhand_3_sx_urdf.stl" scale="0.001 0.001 0.001"/>
      </geometry>
      <origin rpy="0 0 0" xyz="0 0 0"/>
    </collision>
  </link>
  m
		
  <joint name="left_hand_to_left_hand__ik" type="fixed">
    <origin rpy="0 0 -1.57" xyz="0 0.088 0.032"/>
    <parent link="left_hand"/>
    <child link="left_hand_ik"/>
  </joint>
  <link name="left_hand_ik">
		</link>
  <!-- GAZEBO REFERENCE -->
  <gazebo reference="left_hand">
    <material>Gazebo/Grey</material>
    <selfCollide>false</selfCollide>
  </gazebo>
  <!-- JOINT -->
  <joint name="base_to_right_shoulder_flange" type="revolute">
    <axis xyz="0 0 1"/>
    <limit effort="1000.0" lower="-3.14" upper="3.14" velocity="0.5"/>
    <origin rpy="0.1745345 -1.3962633 1.5707948" xyz="16.9617e-3 -154.989e-3 669.737e-3"/>
    <dynamics damping="0.065" friction="0.025"/>
    <parent link="base"/>
    <child link="right_shoulder_flange"/>
  </joint>
  <!-- LINK -->
  <link name="right_shoulder_flange">
    <visual>
      <material name="qbmove/flange"/>
      <geometry>
        <mesh filename="package://alterego_robot/alterego_description/meshes/common/visual/la_flg_asm_flat_blu.dae" scale="0.001 0.001 0.001"/>
      </geometry>
      <origin rpy="0 0 0" xyz="0 0 0"/>
    </visual>
    <inertial>
      <origin rpy="0 0 0" xyz="-8.0511890e-5 0 6.1371397e-4"/>
      <mass value="4.1898263e-02"/>
      <inertia ixx="1.5773084e-5" ixy="0" ixz="0" iyy="2.1026644e-5" iyz="0" izz="3.6312308e-5"/>
    </inertial>
    <collision>
      <origin rpy="0 0 0" xyz="0 0 0"/>
      <geometry>
        <mesh filename="package://alterego_robot/alterego_description/meshes/common/collision/la_flg_asm_flat_blu.stl" scale="0.001 0.001 0.001"/>
      </geometry>
    </collision>
  </link>
  <!-- GAZEBO REFERENCE -->
  <gazebo reference="right_shoulder_flange">
    <material>Gazebo/SkyBlue</material>
    <selfCollide>false</selfCollide>
  </gazebo>
  <!-- JOINT -->
  <joint name="right_shoulder_flange_to_right_shoulder_cube" type="fixed">
    <origin rpy="-1.5707963 0 3.1415927" xyz="0 0 37.0e-3"/>
    <parent link="right_shoulder_flange"/>
    <child link="right_shoulder_cube"/>
  </joint>
  <!-- LINK -->
  <link name="right_shoulder_cube">
    <visual>
      <material name="qbmove/cube"/>
      <geometry>
        <mesh filename="package://alterego_robot/alterego_description/meshes/common/visual/qb_move_advanced_for_mate.dae" scale="0.001 0.001 0.001"/>
      </geometry>
      <origin rpy="0 0 0" xyz="0 0 0"/>
    </visual>
    <inertial>
      <origin rpy="0 0 0" xyz="-9.5664949e-5 -1.6749134e-5  1.3880927e-3"/>
      <mass value="4.5418805e-1"/>
      <inertia ixx="1.7978900e-4" ixy="0" ixz="0" iyy="1.7806823e-4" iyz="0" izz="1.6882624e-4"/>
    </inertial>
    <collision>
      <origin rpy="0.0 0.0 0.0" xyz="0.0 0.0 0.0"/>
      <geometry>
        <box size="0.07 0.07 0.07"/>
      </geometry>
    </collision>
  </link>
  <!-- GAZEBO REFERENCE -->
  <gazebo reference="right_shoulder_cube">
    <material>Gazebo/Grey</material>
    <selfCollide>false</selfCollide>
  </gazebo>
  <!-- JOINT -->
  <joint name="right_shoulder_cube_to_right_arm_flange" type="revolute">
    <axis xyz="0 0 1"/>
    <limit effort="1000.0" lower="-3.14" upper="3.14" velocity="0.5"/>
    <origin rpy="0 0 3.1415927" xyz="0 0 -0.5e-3"/>
    <dynamics damping="0.065" friction="0.025"/>
    <parent link="right_shoulder_cube"/>
    <child link="right_arm_flange"/>
  </joint>
  <!-- LINK -->
  <link name="right_arm_flange">
    <visual>
      <material name="qbmove/flange"/>
      <geometry>
        <mesh filename="package://alterego_robot/alterego_description/meshes/common/visual/la_flg_asm_c_wb_blu.dae" scale="0.001 0.001 0.001"/>
      </geometry>
      <origin rpy="0 0 0" xyz="0 0 0"/>
    </visual>
    <inertial>
      <origin rpy="0 0 0" xyz="-7.3157519e-3 2.3015782e-2 0"/>
      <mass value="8.6640591e-2"/>
      <inertia ixx="7.8695858e-5" ixy="1.8826444e-5" ixz="0" iyy="1.0265668e-4" iyz="0" izz="1.3810438e-4"/>
    </inertial>
    <collision>
      <origin rpy="0 0 0" xyz="0 0 0"/>
      <geometry>
        <mesh filename="package://alterego_robot/alterego_description/meshes/common/collision/la_flg_asm_c_wb_blu.stl" scale="0.001 0.001 0.001"/>
      </geometry>
    </collision>
  </link>
  <!-- GAZEBO REFERENCE -->
  <gazebo reference="right_arm_flange">
    <material>Gazebo/SkyBlue</material>
    <selfCollide>false</selfCollide>
  </gazebo>
  <!-- JOINT -->
  <joint name="right_arm_flange_to_right_arm_cube" type="fixed">
    <origin rpy="0 1.5707963 3.1415927" xyz="-90e-3 0 -0.5e-3"/>
    <parent link="right_arm_flange"/>
    <child link="right_arm_cube"/>
  </joint>
  <!-- LINK -->
  <link name="right_arm_cube">
    <visual>
      <material name="qbmove/cube"/>
      <geometry>
        <mesh filename="package://alterego_robot/alterego_description/meshes/common/visual/qb_move_advanced_for_mate.dae" scale="0.001 0.001 0.001"/>
      </geometry>
      <origin rpy="0 0 0" xyz="0 0 0"/>
    </visual>
    <inertial>
      <origin rpy="0 0 0" xyz="-9.5664949e-5 -1.6749134e-5  1.3880927e-3"/>
      <mass value="4.5418805e-1"/>
      <inertia ixx="1.7978900e-4" ixy="0" ixz="0" iyy="1.7806823e-4" iyz="0" izz="1.6882624e-4"/>
    </inertial>
    <collision>
      <origin rpy="0.0 0.0 0.0" xyz="0.0 0.0 0.0"/>
      <geometry>
        <box size="0.07 0.07 0.07"/>
      </geometry>
    </collision>
  </link>
  <!-- GAZEBO REFERENCE -->
  <gazebo reference="right_arm_cube">
    <material>Gazebo/Grey</material>
    <selfCollide>false</selfCollide>
  </gazebo>
  <!-- JOINT -->
  <joint name="right_arm_cube_to_right_elbow_flange" type="revolute">
    <axis xyz="0 0 1"/>
    <limit effort="1000.0" lower="-3.14" upper="3.14" velocity="0.5"/>
    <origin rpy="0 0 1.5707963" xyz="0 0 40.5e-3"/>
    <dynamics damping="0.065" friction="0.025"/>
    <parent link="right_arm_cube"/>
    <child link="right_elbow_flange"/>
  </joint>
  <!-- LINK -->
  <link name="right_elbow_flange">
    <visual>
      <material name="qbmove/flange"/>
      <geometry>
        <mesh filename="package://alterego_robot/alterego_description/meshes/common/visual/la_flg_asm_flat_blu.dae" scale="0.001 0.001 0.001"/>
      </geometry>
      <origin rpy="0 0 0" xyz="0 0 0"/>
    </visual>
    <inertial>
      <origin rpy="0 0 0" xyz="-8.0511890e-5 0 6.1371397e-4"/>
      <mass value="4.1898263e-02"/>
      <inertia ixx="1.5773084e-5" ixy="0" ixz="0" iyy="2.1026644e-5" iyz="0" izz="3.6312308e-5"/>
    </inertial>
    <collision>
      <origin rpy="0 0 0" xyz="0 0 0"/>
      <geometry>
        <mesh filename="package://alterego_robot/alterego_description/meshes/common/collision/la_flg_asm_flat_blu.stl" scale="0.001 0.001 0.001"/>
      </geometry>
    </collision>
  </link>
  <!-- GAZEBO REFERENCE -->
  <gazebo reference="right_elbow_flange">
    <material>Gazebo/SkyBlue</material>
    <selfCollide>false</selfCollide>
  </gazebo>
  <!-- JOINT -->
  <joint name="right_elbow_flange_to_right_elbow_cube" type="fixed">
    <origin rpy="1.5707963 0 -1.5707963" xyz="0 0 37e-3"/>
    <parent link="right_elbow_flange"/>
    <child link="right_elbow_cube"/>
  </joint>
  <!-- LINK -->
  <link name="right_elbow_cube">
    <visual>
      <material name="qbmove/cube"/>
      <geometry>
        <mesh filename="package://alterego_robot/alterego_description/meshes/common/visual/qb_move_advanced_for_mate.dae" scale="0.001 0.001 0.001"/>
      </geometry>
      <origin rpy="0 0 0" xyz="0 0 0"/>
    </visual>
    <inertial>
      <origin rpy="0 0 0" xyz="-9.5664949e-5 -1.6749134e-5  1.3880927e-3"/>
      <mass value="4.5418805e-1"/>
      <inertia ixx="1.7978900e-4" ixy="0" ixz="0" iyy="1.7806823e-4" iyz="0" izz="1.6882624e-4"/>
    </inertial>
    <collision>
      <origin rpy="0.0 0.0 0.0" xyz="0.0 0.0 0.0"/>
      <geometry>
        <box size="0.07 0.07 0.07"/>
      </geometry>
    </collision>
  </link>
  <!-- GAZEBO REFERENCE -->
  <gazebo reference="right_elbow_cube">
    <material>Gazebo/Grey</material>
    <selfCollide>false</selfCollide>
  </gazebo>
  <!-- JOINT -->
  <joint name="right_elbow_cube_to_right_forearm_flange" type="revolute">
    <axis xyz="0 0 1"/>
    <limit effort="1000.0" lower="-3.14" upper="3.14" velocity="0.5"/>
    <origin rpy="0 0 -1.5707963" xyz="0 0 -0.5e-3"/>
    <dynamics damping="0.065" friction="0.025"/>
    <parent link="right_elbow_cube"/>
    <child link="right_forearm_flange"/>
  </joint>
  <!-- LINK -->
  <link name="right_forearm_flange">
    <visual>
      <material name="qbmove/flange"/>
      <geometry>
        <mesh filename="package://alterego_robot/alterego_description/meshes/common/visual/la_flg_asm_c_wb_blu.dae" scale="0.001 0.001 0.001"/>
      </geometry>
      <origin rpy="0 0 0" xyz="0 0 0"/>
    </visual>
    <inertial>
      <origin rpy="0 0 0" xyz="-7.3157519e-3 2.3015782e-2 0"/>
      <mass value="8.6640591e-2"/>
      <inertia ixx="7.8695858e-5" ixy="1.8826444e-5" ixz="0" iyy="1.0265668e-4" iyz="0" izz="1.3810438e-4"/>
    </inertial>
    <collision>
      <origin rpy="0 0 0" xyz="0 0 0"/>
      <geometry>
        <mesh filename="package://alterego_robot/alterego_description/meshes/common/collision/la_flg_asm_c_wb_blu.stl" scale="0.001 0.001 0.001"/>
      </geometry>
    </collision>
  </link>
  <!-- GAZEBO REFERENCE -->
  <gazebo reference="right_forearm_flange">
    <material>Gazebo/SkyBlue</material>
    <selfCollide>false</selfCollide>
  </gazebo>
  <!-- JOINT -->
  <joint name="right_forearm_flange_to_right_forearm_cube" type="fixed">
    <origin rpy="-1.5707963 0 1.5707963" xyz="-90e-3 0 0"/>
    <parent link="right_forearm_flange"/>
    <child link="right_forearm_cube"/>
  </joint>
  <!-- LINK -->
  <link name="right_forearm_cube">
    <visual>
      <material name="qbmove/cube"/>
      <geometry>
        <mesh filename="package://alterego_robot/alterego_description/meshes/common/visual/qb_move_advanced_for_mate.dae" scale="0.001 0.001 0.001"/>
      </geometry>
      <origin rpy="0 0 0" xyz="0 0 0"/>
    </visual>
    <inertial>
      <origin rpy="0 0 0" xyz="-9.5664949e-5 -1.6749134e-5  1.3880927e-3"/>
      <mass value="4.5418805e-1"/>
      <inertia ixx="1.7978900e-4" ixy="0" ixz="0" iyy="1.7806823e-4" iyz="0" izz="1.6882624e-4"/>
    </inertial>
    <collision>
      <origin rpy="0.0 0.0 0.0" xyz="0.0 0.0 0.0"/>
      <geometry>
        <box size="0.07 0.07 0.07"/>
      </geometry>
    </collision>
  </link>
  <!-- GAZEBO REFERENCE -->
  <gazebo reference="right_forearm_cube">
    <material>Gazebo/Grey</material>
    <selfCollide>false</selfCollide>
  </gazebo>
  <!-- JOINT -->
  <joint name="right_forearm_cube_to_right_wrist_flange" type="revolute">
    <axis xyz="0 0 1"/>
    <limit effort="1000.0" lower="-3.14" upper="3.14" velocity="0.5"/>
    <origin rpy="0 0 -1.5707963" xyz="0 0 40.5e-3"/>
    <dynamics damping="0.065" friction="0.025"/>
    <parent link="right_forearm_cube"/>
    <child link="right_wrist_flange"/>
  </joint>
  <!-- LINK -->
  <link name="right_wrist_flange">
    <visual>
      <material name="qbmove/flange"/>
      <geometry>
        <mesh filename="package://alterego_robot/alterego_description/meshes/common/visual/la_flg_asm_flat_blu.dae" scale="0.001 0.001 0.001"/>
      </geometry>
      <origin rpy="0 0 0" xyz="0 0 0"/>
    </visual>
    <inertial>
      <origin rpy="0 0 0" xyz="-8.0511890e-5 0 6.1371397e-4"/>
      <mass value="4.1898263e-02"/>
      <inertia ixx="1.5773084e-5" ixy="0" ixz="0" iyy="2.1026644e-5" iyz="0" izz="3.6312308e-5"/>
    </inertial>
    <collision>
      <origin rpy="0 0 0" xyz="0 0 0"/>
      <geometry>
        <mesh filename="package://alterego_robot/alterego_description/meshes/common/collision/la_flg_asm_flat_blu.stl" scale="0.001 0.001 0.001"/>
      </geometry>
    </collision>
  </link>
  <!-- GAZEBO REFERENCE -->
  <gazebo reference="right_wrist_flange">
    <material>Gazebo/SkyBlue</material>
    <selfCollide>false</selfCollide>
  </gazebo>
  <!-- JOINT -->
  <joint name="right_wrist_flange_to_right_forearm_hand_flange" type="fixed">
    <origin rpy="0 0 3.1415927" xyz="0 0 4e-3"/>
    <parent link="right_wrist_flange"/>
    <child link="right_forearm_hand_flange"/>
  </joint>
  <!-- LINK -->
  <link name="right_forearm_hand_flange">
    <visual>
      <material name="qbmove/flange"/>
      <geometry>
        <mesh filename="package://alterego_robot/alterego_description/meshes/alterego_v2/visual/mc_wr_abs_qb_adv_301.dae" scale="0.001 0.001 0.001"/>
      </geometry>
      <origin rpy="0 0 0" xyz="0 0 0"/>
    </visual>
    <inertial>
      <origin rpy="0 0 0" xyz="3.0876986e-4 7.1294237e-5 6.7729239e-3"/>
      <mass value="3.4805486e-2"/>
      <inertia ixx="1.5814995e-5" ixy="0" ixz="0" iyy="1.1610747e-5" iyz="0" izz="2.5935426e-5"/>
    </inertial>
    <collision>
      <origin rpy="0 0 0" xyz="0 0 0"/>
      <geometry>
        <mesh filename="package://alterego_robot/alterego_description/meshes/alterego_v2/collision/mc_wr_abs_qb_adv_301.stl" scale="0.001 0.001 0.001"/>
      </geometry>
    </collision>
  </link>
  <!-- GAZEBO REFERENCE -->
  <gazebo reference="right_forearm_hand_flange">
    <material>Gazebo/Grey</material>
    <selfCollide>false</selfCollide>
  </gazebo>
  <!-- JOINT -->
  <joint name="right_forearm_hand_flange_to_right_hand" type="fixed">
    <axis xyz="0 0 1"/>
    <limit effort="1000.0" lower="-1.57" upper="1.57" velocity="0.5"/>
    <origin rpy="-1.5707963 0 0" xyz="3.3e-3 -1.99457e-3 2.80422e-3"/>
    <parent link="right_forearm_hand_flange"/>
    <child link="right_hand"/>
  </joint>
  <!-- LINK -->
  <link name="right_hand">
    <visual>
      <material name="qbmove/cube"/>
      <geometry>
        <mesh filename="package://alterego_robot/alterego_description/meshes/common/visual/softhand_3_dx_urdf.dae" scale="0.001 0.001 0.001"/>
      </geometry>
      <origin rpy="0 0 0" xyz="0 0 0"/>
    </visual>
    <inertial>
      <origin rpy="0 0 0" xyz="4.1739778e-3  -6.3138073e-2 6.1007501e-3"/>
      <mass value="2.9013125e-1"/>
      <inertia ixx="5.6377846e-4" ixy="-2.5891425e-5" ixz="-1.0142109e-5" iyy="1.4989796e-4" iyz="5.9361645e-6" izz="4.4769789e-4"/>
    </inertial>
    <collision>
      <material name="qbmove/cube"/>
      <geometry>
        <mesh filename="package://alterego_robot/alterego_description/meshes/common/collision/softhand_3_dx_urdf.stl" scale="0.001 0.001 0.001"/>
      </geometry>
      <origin rpy="0 0 0" xyz="0 0 0"/>
    </collision>
  </link>
  <joint name="right_hand_to_right_hand__ik" type="fixed">
    <origin rpy="0 0 -1.57" xyz="0 -0.088 0.032"/>
    <parent link="right_hand"/>
    <child link="right_hand_ik"/>
  </joint>
  <link name="right_hand_ik">
		</link>
  <!-- GAZEBO REFERENCE -->
  <gazebo reference="right_hand">
    <material>Gazebo/Grey</material>
    <selfCollide>false</selfCollide>
  </gazebo>
</robot>
